<mujoco model="lingyue_urdf_1.0">
  <compiler angle="radian" meshdir="../../meshes/Bessica_D_v1_1/SkeletonOnly/"/>

  <asset>
    <mesh name="base_link" file="base_link.STL"/>
    <mesh name="head" file="head.STL"/>
    <mesh name="right_arm_base_link" file="right_arm_base_link.STL"/>
    <mesh name="right_arm_link1" file="right_arm_link1.STL"/>
    <mesh name="right_arm_link2" file="right_arm_link2.STL"/>
    <mesh name="right_arm_link3" file="right_arm_link3.STL"/>
    <mesh name="right_arm_link4" file="right_arm_link4.STL"/>
    <mesh name="right_arm_link5" file="right_arm_link5.STL"/>
    <mesh name="right_arm_link6" file="right_arm_link6.STL"/>
    <mesh name="right_arm_link7" file="right_arm_link7.STL"/>
    <mesh name="right_arm_gripper_left_finger" file="right_arm_gripper_left_finger.STL"/>
    <mesh name="right_arm_gripper_right_finger" file="right_arm_gripper_right_finger.STL"/>
    <mesh name="left_arm_base_link" file="left_arm_base_link.STL"/>
    <mesh name="left_arm_link1" file="left_arm_link1.STL"/>
    <mesh name="left_arm_link2" file="left_arm_link2.STL"/>
    <mesh name="left_arm_link3" file="left_arm_link3.STL"/>
    <mesh name="left_arm_link4" file="left_arm_link4.STL"/>
    <mesh name="left_arm_link5" file="left_arm_link5.STL"/>
    <mesh name="left_arm_link6" file="left_arm_link6.STL"/>
    <mesh name="left_arm_link7" file="left_arm_link7.STL"/>
    <mesh name="left_arm_gripper_right_finger" file="left_arm_gripper_right_finger.STL"/>
    <mesh name="left_arm_gripper_left_finger" file="left_arm_gripper_left_finger.STL"/>
    <texture builtin="gradient" height="100" rgb1=".4 .5 .6" rgb2="0 0 0" type="skybox" width="100" />
    <texture builtin="checker" height="100" name="texplane" rgb1="1 1 1" rgb2=".8 .9 1" type="2d" width="100" />
    <material name="MatPlane" reflectance="0.5" texrepeat="1 1" texture="texplane" texuniform="true" />
    <material name="white" rgba="1 1 1 1" shininess="0.5" specular="0.1" />
    <material name="black" rgba="0.25 0.25 0.25 1" shininess="0.2" specular="0.05" />
    <material name="invisible" rgba="1 1 1 0" shininess="0" specular="0" />
  </asset>

  <worldbody>
    <geom conaffinity="1" condim="3" contype="1" friction="1 .1 .1" group="2" material="MatPlane" name="floor" pos="0 0 0" rgba="0.8 0.9 0.8 1" size="10 10 0.125" type="plane" />
    <light castshadow="false" cutoff="100" diffuse="1 1 1" dir="-0 0 -1.3" directional="true" exponent="1" pos="0 0 1.3" specular=".1 .1 .1" />
    <body name="base_link" pos="0 0 0">
      <geom type="mesh" contype="0" conaffinity="0" group="1" density="0" rgba="0.807843 0.843137 0.905882 1" mesh="base_link"/>
      <geom type="mesh" rgba="0.807843 0.843137 0.905882 1" mesh="base_link"/>
      <geom pos="0.0608245 0.00175926 0.700041" type="mesh" contype="0" conaffinity="0" group="1" density="0" rgba="0.592157 0.666667 0.682353 1" mesh="head"/>
      <geom pos="0.0608245 0.00175926 0.700041" type="mesh" rgba="0.592157 0.666667 0.682353 1" mesh="head"/>
      <geom pos="0 -0.09 0.5145" quat="0 0 0 -1" type="mesh" contype="0" conaffinity="0" group="1" density="0" rgba="0.807843 0.843137 0.905882 1" mesh="right_arm_base_link"/>
      <geom pos="0 -0.09 0.5145" quat="0 0 0 -1" type="mesh" rgba="0.807843 0.843137 0.905882 1" mesh="right_arm_base_link"/>
      <geom pos="1.06667e-08 0.09 0.5145" quat="0 0 -0.707107 -0.707107" type="mesh" contype="0" conaffinity="0" group="1" density="0" rgba="0.807843 0.843137 0.905882 1" mesh="left_arm_base_link"/>
      <geom pos="1.06667e-08 0.09 0.5145" quat="0 0 -0.707107 -0.707107" type="mesh" rgba="0.807843 0.843137 0.905882 1" mesh="left_arm_base_link"/>
      <body name="right_arm_link1" pos="5e-05 -0.2046 0.5145" quat="0 0 -1 0">
        <inertial pos="0.000110936 -0.00312061 0.000177914" quat="0.503324 0.499404 0.49881 0.498447" mass="0.208266" diaginertia="0.00034002 0.000262863 0.000150646"/>
        <joint name="right_arm_joint1" pos="0 0 0" axis="0 1 0" range="-2.14 2.14" actuatorfrcrange="-5 5"/>
        <geom type="mesh" contype="0" conaffinity="0" group="1" density="0" rgba="0.807843 0.843137 0.905882 1" mesh="right_arm_link1"/>
        <geom type="mesh" rgba="0.807843 0.843137 0.905882 1" mesh="right_arm_link1"/>
        <body name="right_arm_link2" pos="0 -0.04286 0" quat="0 0.707107 0 -0.707107">
          <inertial pos="-0.0297081 0.000293735 0.000469869" quat="0.512721 0.46754 0.480696 0.536148" mass="0.0472691" diaginertia="1.62077e-05 1.58746e-05 7.75482e-06"/>
          <joint name="right_arm_joint2" pos="0 0 0" axis="0 0 -1" range="-2.14 2.14" actuatorfrcrange="-5 5"/>
          <geom type="mesh" contype="0" conaffinity="0" group="1" density="0" rgba="0.592157 0.666667 0.682353 1" mesh="right_arm_link2"/>
          <geom type="mesh" rgba="0.592157 0.666667 0.682353 1" mesh="right_arm_link2"/>
          <body name="right_arm_link3" pos="-0.06455 0 0.0003" quat="0.5 0.5 -0.5 -0.5">
            <inertial pos="-0.00359313 -0.000221914 0.094469" quat="0.709839 0.0300787 0.0347342 0.702864" mass="0.140452" diaginertia="8.80484e-05 7.8681e-05 5.52303e-05"/>
            <joint name="right_arm_joint3" pos="0 0 0" axis="0 0 -1" range="-2.14 2.14" actuatorfrcrange="-5 5"/>
            <geom type="mesh" contype="0" conaffinity="0" group="1" density="0" rgba="0.807843 0.843137 0.905882 1" mesh="right_arm_link3"/>
            <geom type="mesh" rgba="0.807843 0.843137 0.905882 1" mesh="right_arm_link3"/>
            <body name="right_arm_link4" pos="-1.89942e-05 -5e-05 0.1816" quat="0.707107 -0.707107 0 0">
              <inertial pos="-2.80211e-05 -0.0241583 -4.84137e-05" quat="1 0 0 0.000169429" mass="0.0427207" diaginertia="1.04868e-05 8.49768e-06 8.00565e-06"/>
              <joint name="right_arm_joint4" pos="0 0 0" axis="0 0 1" range="-2.14 2.14" actuatorfrcrange="-5 5"/>
              <geom type="mesh" contype="0" conaffinity="0" group="1" density="0" rgba="0.592157 0.666667 0.682353 1" mesh="right_arm_link4"/>
              <geom type="mesh" rgba="0.592157 0.666667 0.682353 1" mesh="right_arm_link4"/>
              <body name="right_arm_link5" pos="0 -0.0488 -0.0001" quat="0.707107 -0.707107 0 0">
                <inertial pos="-0.00180911 0.000196787 -0.0430793" quat="0.96714 0.0368465 -0.108778 -0.226827" mass="0.110397" diaginertia="8.7423e-05 8.69117e-05 4.35431e-05"/>
                <joint name="right_arm_joint5" pos="0 0 0" axis="0 0 1" range="-2.14 2.14" actuatorfrcrange="-5 5"/>
                <geom type="mesh" contype="0" conaffinity="0" group="1" density="0" rgba="0.807843 0.843137 0.905882 1" mesh="right_arm_link5"/>
                <geom type="mesh" rgba="0.807843 0.843137 0.905882 1" mesh="right_arm_link5"/>
                <body name="right_arm_link6" pos="0.00289 0.00207607 -0.10801" quat="0.707107 0.707107 0 0">
                  <inertial pos="0.000365898 -0.0257376 -4.10017e-05" quat="0.999601 0.00397576 0.00062209 -0.0279465" mass="0.0345707" diaginertia="1.56449e-05 1.27188e-05 9.19996e-06"/>
                  <joint name="right_arm_joint6" pos="0 0 0" axis="0 0 1" range="-2.14 2.14" actuatorfrcrange="-5 5"/>
                  <geom type="mesh" contype="0" conaffinity="0" group="1" density="0" rgba="0.807843 0.843137 0.905882 1" mesh="right_arm_link6"/>
                  <geom type="mesh" rgba="0.807843 0.843137 0.905882 1" mesh="right_arm_link6"/>
                  <body name="right_arm_link7" pos="-0.0015 -0.05561 0" quat="0.5 -0.5 0.5 -0.5">
                    <inertial pos="0.0415076 0.000152835 -0.0262967" quat="0.698357 0.698702 0.109714 -0.109886" mass="0.134443" diaginertia="9.59304e-05 8.33778e-05 4.31456e-05"/>
                    <joint name="right_arm_joint7" pos="0 0 0" axis="0 0 -1" range="-2.14 2.14" actuatorfrcrange="-5 5"/>
                    <geom type="mesh" contype="0" conaffinity="0" group="1" density="0" rgba="0.807843 0.843137 0.905882 1" mesh="right_arm_link7"/>
                    <geom type="mesh" rgba="0.807843 0.843137 0.905882 1" mesh="right_arm_link7"/>
                    <geom size="0.005" pos="0.14128 0 -0.00015" quat="-3.67321e-06 -1 0 0" contype="0" conaffinity="0" group="1" density="0" rgba="0 1 0 1"/>
                    <body name="right_arm_gripper_left_finger" pos="0.14128 0.0505 -0.00015" quat="0.707105 0.707108 0 0">
                      <inertial pos="-0.0434087 -1.55043e-08 -0.0106596" quat="1.78481e-06 0.569751 -6.4369e-06 0.821818" mass="0.0256463" diaginertia="8.50963e-06 6.46826e-06 4.6607e-06"/>
                      <joint name="right_arm_gripper_joint1" pos="0 0 0" axis="0 0.054375 -0.998521" type="slide" range="-0.05 0" actuatorfrcrange="-5 5"/>
                      <geom type="mesh" contype="0" conaffinity="0" group="1" density="0" rgba="0.592157 0.666667 0.682353 1" mesh="right_arm_gripper_left_finger"/>
                      <geom type="mesh" rgba="0.592157 0.666667 0.682353 1" mesh="right_arm_gripper_left_finger"/>
                    </body>
                    <body name="right_arm_gripper_right_finger" pos="0.14128 -0.0505 -0.00015" quat="0.707105 -0.707108 0 0">
                      <inertial pos="-0.0434087 -1.55043e-08 -0.0106596" quat="1.78481e-06 0.569751 -6.4369e-06 0.821818" mass="0.0256463" diaginertia="8.50963e-06 6.46826e-06 4.6607e-06"/>
                      <joint name="right_arm_gripper_joint2" pos="0 0 0" axis="0 -0.054375 0.998521" type="slide" range="0 0.05" actuatorfrcrange="-5 5"/>
                      <geom type="mesh" contype="0" conaffinity="0" group="1" density="0" rgba="0.592157 0.666667 0.682353 1" mesh="right_arm_gripper_right_finger"/>
                      <geom type="mesh" rgba="0.592157 0.666667 0.682353 1" mesh="right_arm_gripper_right_finger"/>
                    </body>
                  </body>
                </body>
              </body>
            </body>
          </body>
        </body>
      </body>
      <body name="left_arm_link1" pos="-4.99893e-05 0.2046 0.5145" quat="0 0 -0.707107 -0.707107">
        <inertial pos="-0.000114066 -0.000187362 0.00370369" quat="-0.00280195 0.709053 -0.000282862 0.70515" mass="0.197841" diaginertia="0.000335797 0.000260031 0.000148034"/>
        <joint name="left_arm_joint1" pos="0 0 0" axis="0 0 1" range="-2.14 2.14" actuatorfrcrange="-5 5"/>
        <geom type="mesh" contype="0" conaffinity="0" group="1" density="0" rgba="0.807843 0.843137 0.905882 1" mesh="left_arm_link1"/>
        <geom type="mesh" rgba="0.807843 0.843137 0.905882 1" mesh="left_arm_link1"/>
        <body name="left_arm_link2" pos="0 0 0.04286" quat="0.5 0.5 0.5 0.5">
          <inertial pos="-0.0297081 0.000293735 0.000469869" quat="0.512721 0.46754 0.480696 0.536148" mass="0.0472691" diaginertia="1.62077e-05 1.58746e-05 7.75482e-06"/>
          <joint name="left_arm_joint2" pos="0 0 0" axis="0 0 1" range="-2.14 2.14" actuatorfrcrange="-5 5"/>
          <geom type="mesh" contype="0" conaffinity="0" group="1" density="0" rgba="0.592157 0.666667 0.682353 1" mesh="left_arm_link2"/>
          <geom type="mesh" rgba="0.592157 0.666667 0.682353 1" mesh="left_arm_link2"/>
          <body name="left_arm_link3" pos="-0.06455 0 0.0003" quat="0.5 0.5 -0.5 -0.5">
            <inertial pos="-0.00359313 -0.000221914 0.094469" quat="0.709839 0.0300787 0.0347342 0.702864" mass="0.140452" diaginertia="8.80484e-05 7.8681e-05 5.52303e-05"/>
            <joint name="left_arm_joint3" pos="0 0 0" axis="0 0 -1" range="-2.14 2.14" actuatorfrcrange="-5 5"/>
            <geom type="mesh" contype="0" conaffinity="0" group="1" density="0" rgba="0.807843 0.843137 0.905882 1" mesh="left_arm_link3"/>
            <geom type="mesh" rgba="0.807843 0.843137 0.905882 1" mesh="left_arm_link3"/>
            <body name="left_arm_link4" pos="-1.89942e-05 -5e-05 0.1816" quat="0.707107 -0.707107 0 0">
              <inertial pos="-2.80211e-05 -0.0241583 -4.84137e-05" quat="1 0 0 0.000169429" mass="0.0427207" diaginertia="1.04868e-05 8.49768e-06 8.00565e-06"/>
              <joint name="left_arm_joint4" pos="0 0 0" axis="0 0 -1" range="-2.14 2.14" actuatorfrcrange="-5 5"/>
              <geom type="mesh" contype="0" conaffinity="0" group="1" density="0" rgba="0.592157 0.666667 0.682353 1" mesh="left_arm_link4"/>
              <geom type="mesh" rgba="0.592157 0.666667 0.682353 1" mesh="left_arm_link4"/>
              <body name="left_arm_link5" pos="0 -0.0488 -0.0001" quat="0.707107 -0.707107 0 0">
                <inertial pos="-0.00180911 0.000196787 -0.0430793" quat="0.96714 0.0368465 -0.108778 -0.226827" mass="0.110397" diaginertia="8.7423e-05 8.69117e-05 4.35431e-05"/>
                <joint name="left_arm_joint5" pos="0 0 0" axis="0 0 1" range="-2.14 2.14" actuatorfrcrange="-5 5"/>
                <geom type="mesh" contype="0" conaffinity="0" group="1" density="0" rgba="0.807843 0.843137 0.905882 1" mesh="left_arm_link5"/>
                <geom type="mesh" rgba="0.807843 0.843137 0.905882 1" mesh="left_arm_link5"/>
                <body name="left_arm_link6" pos="0.00289 0.00207607 -0.10801" quat="0.707107 0.707107 0 0">
                  <inertial pos="0.000365898 -0.0257376 -4.10017e-05" quat="0.999601 0.00397576 0.000622093 -0.0279465" mass="0.0345707" diaginertia="1.56449e-05 1.27188e-05 9.19996e-06"/>
                  <joint name="left_arm_joint6" pos="0 0 0" axis="0 0 -1" range="-2.14 2.14" actuatorfrcrange="-5 5"/>
                  <geom type="mesh" contype="0" conaffinity="0" group="1" density="0" rgba="0.807843 0.843137 0.905882 1" mesh="left_arm_link6"/>
                  <geom type="mesh" rgba="0.807843 0.843137 0.905882 1" mesh="left_arm_link6"/>
                  <body name="left_arm_link7" pos="-0.0015 -0.05561 0.00375195" quat="0.5 -0.5 0.5 -0.5">
                    <inertial pos="0.0417512 0.00390925 -0.0266716" quat="0.697385 0.697718 0.115769 -0.115941" mass="0.130828" diaginertia="9.49108e-05 8.29883e-05 4.23029e-05"/>
                    <joint name="left_arm_joint7" pos="0 0 0" axis="0 0 -1" range="-2.14 2.14" actuatorfrcrange="-5 5"/>
                    <geom type="mesh" contype="0" conaffinity="0" group="1" density="0" rgba="0.807843 0.843137 0.905882 1" mesh="left_arm_link7"/>
                    <geom type="mesh" rgba="0.807843 0.843137 0.905882 1" mesh="left_arm_link7"/>
                    <geom size="0.005" pos="0.14128 0.0037519 -0.00015" quat="-3.67321e-06 1 0 0" contype="0" conaffinity="0" group="1" density="0" rgba="0 1 0 1"/>
                    <body name="left_arm_gripper_right_finger" pos="0.14128 -0.046748 -0.00015" quat="0.707105 -0.707108 0 0">
                      <inertial pos="-0.0434087 1.55043e-08 0.11166" quat="-6.4369e-06 0.821818 1.78481e-06 0.569751" mass="0.0256463" diaginertia="8.50963e-06 6.46826e-06 4.6607e-06"/>
                      <joint name="left_arm_gripper_joint1" pos="0 0 0" axis="0 0 1" type="slide" range="-0.05 0" actuatorfrcrange="-5 5"/>
                      <geom type="mesh" contype="0" conaffinity="0" group="1" density="0" rgba="0.592157 0.666667 0.682353 1" mesh="left_arm_gripper_right_finger"/>
                      <geom type="mesh" rgba="0.592157 0.666667 0.682353 1" mesh="left_arm_gripper_right_finger"/>
                    </body>
                    <body name="left_arm_gripper_left_finger" pos="0.14128 0.054252 -0.00015" quat="0.707105 0.707108 0 0">
                      <inertial pos="-0.0434087 1.55043e-08 0.11166" quat="-6.4369e-06 0.821818 1.78481e-06 0.569751" mass="0.0256463" diaginertia="8.50963e-06 6.46826e-06 4.6607e-06"/>
                      <joint name="left_arm_gripper_joint2" pos="0 0 0" axis="0 0 -1" type="slide" range="0 0.05" actuatorfrcrange="-5 5"/>
                      <geom type="mesh" contype="0" conaffinity="0" group="1" density="0" rgba="0.592157 0.666667 0.682353 1" mesh="left_arm_gripper_left_finger"/>
                      <geom type="mesh" rgba="0.592157 0.666667 0.682353 1" mesh="left_arm_gripper_left_finger"/>
                    </body>
                  </body>
                </body>
              </body>
            </body>
          </body>
        </body>
      </body>
    </body>
  </worldbody>


  <contact>
    <exclude body1="base_link" body2="left_arm_link1" />
    <exclude body1="left_arm_link1" body2="left_arm_link2" />
    <exclude body1="left_arm_link1" body2="left_arm_link3" />
    <exclude body1="left_arm_link2" body2="left_arm_link3" />
    <exclude body1="left_arm_link3" body2="left_arm_link4" />
    <exclude body1="left_arm_link4" body2="left_arm_link5" />
    <exclude body1="left_arm_link5" body2="left_arm_link6" />
    <exclude body1="left_arm_link6" body2="left_arm_link7" />
    <exclude body1="base_link" body2="right_arm_link1" />
    <exclude body1="right_arm_link1" body2="right_arm_link2" />
    <exclude body1="right_arm_link1" body2="right_arm_link3" />
    <exclude body1="right_arm_link2" body2="right_arm_link3" />
    <exclude body1="right_arm_link3" body2="right_arm_link4" />
    <exclude body1="right_arm_link4" body2="right_arm_link5" />
    <exclude body1="right_arm_link5" body2="right_arm_link6" />
    <exclude body1="right_arm_link6" body2="right_arm_link7" />
  </contact>

</mujoco>
