<?xml version="1.0"?>
<robot  name="MoveAI" >
 <link  name="BASE" >
  <inertial >
   <origin  xyz="0 0 0"  rpy="0 0 0" />
   <mass  value="0.000001" />
   <inertia  ixy="0"  iyy="0.000001"  ixz="0"  ixx="0.000001"  izz="0.000001"  iyz="0" />
  </inertial>
 </link>
 <link  name="BODY" >
  <visual >
   <origin  xyz="0.0 0.0 0.1056481591092321"  rpy="0 0 0" />
   <geometry >
    <box  size="0.18 0.1 0.13" />
   </geometry>
   <material  name="Cyan" >
    <color  rgba="0 1 1 1" />
   </material>
  </visual>
  <inertial >
   <origin  xyz="0.0 0.0 0.1056481591092321"  rpy="0 0 0" />
   <mass  value="14.4" />
   <inertia  ixy="0"  iyy="0.05915999999999999"  ixz="0"  ixx="0.05088"  izz="0.03228"  iyz="0" />
  </inertial>
 </link>
 <link  name="Spine1" >
  <inertial >
   <origin  xyz="0 0 0"  rpy="0 0 0" />
   <mass  value="0.000001" />
   <inertia  ixy="0"  iyy="0.000001"  ixz="0"  ixx="0.000001"  izz="0.000001"  iyz="0" />
  </inertial>
 </link>
 <link  name="Spine2" >
  <inertial >
   <origin  xyz="0 0 0"  rpy="0 0 0" />
   <mass  value="0.000001" />
   <inertia  ixy="0"  iyy="0.000001"  ixz="0"  ixx="0.000001"  izz="0.000001"  iyz="0" />
  </inertial>
 </link>
 <link  name="Spine3" >
  <visual >
   <origin  xyz="0.0 0.0 0.18143922977455068"  rpy="0 0 0" />
   <geometry >
    <box  size="0.28 0.12 0.36287845954910136" />
   </geometry>
   <material  name="Cyan" >
    <color  rgba="0 1 1 1" />
   </material>
  </visual>
  <inertial >
   <origin  xyz="0.0 0.0 0.18143922977455068"  rpy="0 0 0" />
   <mass  value="21.599999999999998" />
   <inertia  ixy="0"  iyy="0.37814539752851184"  ixz="0"  ixx="0.16704"  izz="0.2629453975285118"  iyz="0" />
  </inertial>
 </link>
 <link  name="Neck1" >
  <inertial >
   <origin  xyz="0 0 0"  rpy="0 0 0" />
   <mass  value="0.000001" />
   <inertia  ixy="0"  iyy="0.000001"  ixz="0"  ixx="0.000001"  izz="0.000001"  iyz="0" />
  </inertial>
 </link>
 <link  name="Neck2" >
  <inertial >
   <origin  xyz="0 0 0"  rpy="0 0 0" />
   <mass  value="0.000001" />
   <inertia  ixy="0"  iyy="0.000001"  ixz="0"  ixx="0.000001"  izz="0.000001"  iyz="0" />
  </inertial>
 </link>
 <link  name="Neck3" >
  <inertial >
   <origin  xyz="0 0 0"  rpy="0 0 0" />
   <mass  value="0.000001" />
   <inertia  ixy="0"  iyy="0.000001"  ixz="0"  ixx="0.000001"  izz="0.000001"  iyz="0" />
  </inertial>
 </link>
 <link  name="L_sblade" >
  <inertial >
   <origin  xyz="0 0 0"  rpy="0 0 0" />
   <mass  value="0.000001" />
   <inertia  ixy="0"  iyy="0.000001"  ixz="0"  ixx="0.000001"  izz="0.000001"  iyz="0" />
  </inertial>
 </link>
 <link  name="L_Arm1" >
  <visual >
   <origin  xyz="0.0 0.0 -0.1455422634146082"  rpy="0 0 0" />
   <geometry >
    <box  size="0.075 0.075 0.2910845268292164" />
   </geometry>
   <material  name="Cyan" >
    <color  rgba="0 1 1 1" />
   </material>
  </visual>
  <inertial >
   <origin  xyz="0.0 0.0 -0.1455422634146082"  rpy="0 0 0" />
   <mass  value="1.78125" />
   <inertia  ixy="0"  iyy="0.013412100261159274"  ixz="0"  ixx="0.013412100261159274"  izz="0.001669921875"  iyz="0" />
  </inertial>
 </link>
 <link  name="L_Arm2" >
  <visual >
   <origin  xyz="0.0 0.0 -0.14383198304776762"  rpy="0 0 0" />
   <geometry >
    <box  size="0.06 0.06 0.28766396609553524" />
   </geometry>
   <material  name="Cyan" >
    <color  rgba="0 1 1 1" />
   </material>
  </visual>
  <inertial >
   <origin  xyz="0.0 0.0 -0.14383198304776762"  rpy="0 0 0" />
   <mass  value="1.78125" />
   <inertia  ixy="0"  iyy="0.012817660862550406"  ixz="0"  ixx="0.012817660862550406"  izz="0.00106875"  iyz="0" />
  </inertial>
 </link>
 <link  name="L_Wrist1" >
  <inertial >
   <origin  xyz="0 0 0"  rpy="0 0 0" />
   <mass  value="0.000001" />
   <inertia  ixy="0"  iyy="0.000001"  ixz="0"  ixx="0.000001"  izz="0.000001"  iyz="0" />
  </inertial>
 </link>
 <link  name="L_Wrist2" >
  <inertial >
   <origin  xyz="0 0 0"  rpy="0 0 0" />
   <mass  value="0.000001" />
   <inertia  ixy="0"  iyy="0.000001"  ixz="0"  ixx="0.000001"  izz="0.000001"  iyz="0" />
  </inertial>
 </link>
 <link  name="L_Wrist3" >
  <visual >
   <origin  xyz="0.0 0.0 -0.04"  rpy="0 0 0" />
   <geometry >
    <box  size="0.025 0.08 0.05" />
   </geometry>
   <material  name="Cyan" >
    <color  rgba="0 1 1 1" />
   </material>
  </visual>
  <inertial >
   <origin  xyz="0.0 0.0 -0.04"  rpy="0 0 0" />
   <mass  value="0.0" />
   <inertia  ixy="0"  iyy="0.0"  ixz="0"  ixx="0.0"  izz="0.0"  iyz="0" />
  </inertial>
 </link>
 <link  name="L_Leg1" >
  <visual >
   <origin  xyz="0.0 0.0 -0.2220102739121942"  rpy="0 0 0" />
   <geometry >
    <box  size="0.11 0.11 0.4440205478243884" />
   </geometry>
   <material  name="Cyan" >
    <color  rgba="0 1 1 1" />
   </material>
  </visual>
  <inertial >
   <origin  xyz="0.0 0.0 -0.2220102739121942"  rpy="0 0 0" />
   <mass  value="8.0625" />
   <inertia  ixy="0"  iyy="0.14059269712940015"  ixz="0"  ixx="0.14059269712940015"  izz="0.016259375"  iyz="0" />
  </inertial>
 </link>
 <link  name="L_Leg2" >
  <visual >
   <origin  xyz="0.0 0.0 -0.22748332056359288"  rpy="0 0 0" />
   <geometry >
    <box  size="0.085 0.085 0.45496664112718577" />
   </geometry>
   <material  name="Cyan" >
    <color  rgba="0 1 1 1" />
   </material>
  </visual>
  <inertial >
   <origin  xyz="0.0 0.0 -0.22748332056359288"  rpy="0 0 0" />
   <mass  value="5.250000000000001" />
   <inertia  ixy="0"  iyy="0.09372109448561713"  ixz="0"  ixx="0.09372109448561713"  izz="0.006321875000000002"  iyz="0" />
  </inertial>
 </link>
 <link  name="L_Leg3" >
  <inertial >
   <origin  xyz="0 0 0"  rpy="0 0 0" />
   <mass  value="0.000001" />
   <inertia  ixy="0"  iyy="0.000001"  ixz="0"  ixx="0.000001"  izz="0.000001"  iyz="0" />
  </inertial>
 </link>
 <link  name="L_Leg4" >
  <inertial >
   <origin  xyz="0 0 0"  rpy="0 0 0" />
   <mass  value="0.000001" />
   <inertia  ixy="0"  iyy="0.000001"  ixz="0"  ixx="0.000001"  izz="0.000001"  iyz="0" />
  </inertial>
 </link>
 <link  name="L_Ankle" >
  <visual >
   <origin  xyz="0.0 -0.06 -0.05362312483331108"  rpy="0 0 0" />
   <geometry >
    <box  size="0.08 0.16086937449993324 0.025" />
   </geometry>
   <material  name="Cyan" >
    <color  rgba="0 1 1 1" />
   </material>
  </visual>
  <inertial >
   <origin  xyz="0.0 -0.06 -0.05362312483331108"  rpy="0 0 0" />
   <mass  value="0.0" />
   <inertia  ixy="0"  iyy="0.0"  ixz="0"  ixx="0.0"  izz="0.0"  iyz="0" />
  </inertial>
 </link>
 <link  name="L_Foot" >
  <visual >
   <origin  xyz="-0.0625 0.0 -0.00625"  rpy="0 0 0" />
   <geometry >
    <box  size="0.08 0.05362312483331108 0.0125" />
   </geometry>
   <material  name="Cyan" >
    <color  rgba="0 1 1 1" />
   </material>
  </visual>
  <inertial >
   <origin  xyz="-0.0625 0.0 -0.00625"  rpy="0 0 0" />
   <mass  value="0.0" />
   <inertia  ixy="0"  iyy="0.0"  ixz="0"  ixx="0.0"  izz="0.0"  iyz="0" />
  </inertial>
 </link>
 <link  name="R_sblade" >
  <inertial >
   <origin  xyz="0 0 0"  rpy="0 0 0" />
   <mass  value="0.000001" />
   <inertia  ixy="0"  iyy="0.000001"  ixz="0"  ixx="0.000001"  izz="0.000001"  iyz="0" />
  </inertial>
 </link>
 <link  name="R_Arm1" >
  <visual >
   <origin  xyz="0.0 0.0 -0.1455422634146082"  rpy="0 0 0" />
   <geometry >
    <box  size="0.075 0.075 0.2910845268292164" />
   </geometry>
   <material  name="Cyan" >
    <color  rgba="0 1 1 1" />
   </material>
  </visual>
  <inertial >
   <origin  xyz="0.0 0.0 -0.1455422634146082"  rpy="0 0 0" />
   <mass  value="1.78125" />
   <inertia  ixy="0"  iyy="0.013412100261159274"  ixz="0"  ixx="0.013412100261159274"  izz="0.001669921875"  iyz="0" />
  </inertial>
 </link>
 <link  name="R_Arm2" >
  <visual >
   <origin  xyz="0.0 0.0 -0.14383198304776762"  rpy="0 0 0" />
   <geometry >
    <box  size="0.06 0.06 0.28766396609553524" />
   </geometry>
   <material  name="Cyan" >
    <color  rgba="0 1 1 1" />
   </material>
  </visual>
  <inertial >
   <origin  xyz="0.0 0.0 -0.14383198304776762"  rpy="0 0 0" />
   <mass  value="1.78125" />
   <inertia  ixy="0"  iyy="0.012817660862550406"  ixz="0"  ixx="0.012817660862550406"  izz="0.00106875"  iyz="0" />
  </inertial>
 </link>
 <link  name="R_Wrist1" >
  <inertial >
   <origin  xyz="0 0 0"  rpy="0 0 0" />
   <mass  value="0.000001" />
   <inertia  ixy="0"  iyy="0.000001"  ixz="0"  ixx="0.000001"  izz="0.000001"  iyz="0" />
  </inertial>
 </link>
 <link  name="R_Wrist2" >
  <inertial >
   <origin  xyz="0 0 0"  rpy="0 0 0" />
   <mass  value="0.000001" />
   <inertia  ixy="0"  iyy="0.000001"  ixz="0"  ixx="0.000001"  izz="0.000001"  iyz="0" />
  </inertial>
 </link>
 <link  name="R_Wrist3" >
  <visual >
   <origin  xyz="0.0 0.0 -0.04"  rpy="0 0 0" />
   <geometry >
    <box  size="0.025 0.08 0.05" />
   </geometry>
   <material  name="Cyan" >
    <color  rgba="0 1 1 1" />
   </material>
  </visual>
  <inertial >
   <origin  xyz="0.0 0.0 -0.04"  rpy="0 0 0" />
   <mass  value="0.0" />
   <inertia  ixy="0"  iyy="0.0"  ixz="0"  ixx="0.0"  izz="0.0"  iyz="0" />
  </inertial>
 </link>
 <link  name="R_Leg1" >
  <visual >
   <origin  xyz="0.0 0.0 -0.2220102739121942"  rpy="0 0 0" />
   <geometry >
    <box  size="0.11 0.11 0.4440205478243884" />
   </geometry>
   <material  name="Cyan" >
    <color  rgba="0 1 1 1" />
   </material>
  </visual>
  <inertial >
   <origin  xyz="0.0 0.0 -0.2220102739121942"  rpy="0 0 0" />
   <mass  value="8.0625" />
   <inertia  ixy="0"  iyy="0.14059269712940015"  ixz="0"  ixx="0.14059269712940015"  izz="0.016259375"  iyz="0" />
  </inertial>
 </link>
 <link  name="R_Leg2" >
  <visual >
   <origin  xyz="0.0 0.0 -0.22748332056359288"  rpy="0 0 0" />
   <geometry >
    <box  size="0.085 0.085 0.45496664112718577" />
   </geometry>
   <material  name="Cyan" >
    <color  rgba="0 1 1 1" />
   </material>
  </visual>
  <inertial >
   <origin  xyz="0.0 0.0 -0.22748332056359288"  rpy="0 0 0" />
   <mass  value="5.250000000000001" />
   <inertia  ixy="0"  iyy="0.09372109448561713"  ixz="0"  ixx="0.09372109448561713"  izz="0.006321875000000002"  iyz="0" />
  </inertial>
 </link>
 <link  name="R_Leg3" >
  <inertial >
   <origin  xyz="0 0 0"  rpy="0 0 0" />
   <mass  value="0.000001" />
   <inertia  ixy="0"  iyy="0.000001"  ixz="0"  ixx="0.000001"  izz="0.000001"  iyz="0" />
  </inertial>
 </link>
 <link  name="R_Leg4" >
  <inertial >
   <origin  xyz="0 0 0"  rpy="0 0 0" />
   <mass  value="0.000001" />
   <inertia  ixy="0"  iyy="0.000001"  ixz="0"  ixx="0.000001"  izz="0.000001"  iyz="0" />
  </inertial>
 </link>
 <link  name="R_Ankle" >
  <visual >
   <origin  xyz="0.0 -0.06 -0.05362312483331108"  rpy="0 0 0" />
   <geometry >
    <box  size="0.08 0.16086937449993324 0.025" />
   </geometry>
   <material  name="Cyan" >
    <color  rgba="0 1 1 1" />
   </material>
  </visual>
  <inertial >
   <origin  xyz="0.0 -0.06 -0.05362312483331108"  rpy="0 0 0" />
   <mass  value="0.0" />
   <inertia  ixy="0"  iyy="0.0"  ixz="0"  ixx="0.0"  izz="0.0"  iyz="0" />
  </inertial>
 </link>
 <link  name="R_Foot" >
  <visual >
   <origin  xyz="0.0625 0.0 -0.00625"  rpy="0 0 0" />
   <geometry >
    <box  size="0.08 0.05362312483331108 0.0125" />
   </geometry>
   <material  name="Cyan" >
    <color  rgba="0 1 1 1" />
   </material>
  </visual>
  <inertial >
   <origin  xyz="0.0625 0.0 -0.00625"  rpy="0 0 0" />
   <mass  value="0.0" />
   <inertia  ixy="0"  iyy="0.0"  ixz="0"  ixx="0.0"  izz="0.0"  iyz="0" />
  </inertial>
 </link>
 <joint  type="floating"  name="R" >
  <parent  link="BASE" />
  <child  link="BODY" />
  <origin  xyz="0 0 0"  rpy="0 0 0" />
 </joint>
 <joint  type="revolute"  name="Spine_P" >
  <parent  link="BODY" />
  <child  link="Spine1" />
  <origin  xyz="0.0 0.0 0.2112963182184642"  rpy="0 0.0 0" />
  <axis  xyz="1 0 0" />
  <limit  effort="100"  upper="0.8"  lower="0.0"  velocity="1000" />
 </joint>
 <joint  type="revolute"  name="Spine_R" >
  <parent  link="Spine1" />
  <child  link="Spine2" />
  <origin  xyz="0.0 0.0 0.0"  rpy="0 0.0 0" />
  <axis  xyz="0 1 0" />
  <limit  effort="100"  upper="0.52"  lower="-0.52"  velocity="1000" />
 </joint>
 <joint  type="revolute"  name="Spine_Y" >
  <parent  link="Spine2" />
  <child  link="Spine3" />
  <origin  xyz="0.0 0.0 0.0"  rpy="0 0.0 0" />
  <axis  xyz="0 0 1" />
  <limit  effort="100"  upper="0.26"  lower="-0.26"  velocity="1000" />
 </joint>
 <joint  type="revolute"  name="Neck_Y" >
  <parent  link="Spine3" />
  <child  link="Neck1" />
  <origin  xyz="0.0 0.0 0.4579"  rpy="0 0.0 0" />
  <axis  xyz="0 0 1" />
  <limit  effort="100"  upper="1.2"  lower="-1.2"  velocity="1000" />
 </joint>
 <joint  type="revolute"  name="Neck_P" >
  <parent  link="Neck1" />
  <child  link="Neck2" />
  <origin  xyz="0.0 0.0 0.0"  rpy="0 0.0 0" />
  <axis  xyz="1 0 0" />
  <limit  effort="100"  upper="1.2"  lower="-1.2"  velocity="1000" />
 </joint>
 <joint  type="revolute"  name="Neck_R" >
  <parent  link="Neck2" />
  <child  link="Neck3" />
  <origin  xyz="0.0 0.0 0.0"  rpy="0 0.0 0" />
  <axis  xyz="0 1 0" />
  <limit  effort="100"  upper="1.2"  lower="-1.2"  velocity="1000" />
 </joint>
 <joint  type="prismatic"  name="L_Shoulder_Prism" >
  <parent  link="Spine3" />
  <child  link="L_sblade" />
  <origin  xyz="0.20185373398483272 0.0 0.362878"  rpy="0 0.0 0" />
  <axis  xyz="0 0 1" />
  <limit  effort="1"  upper="1"  lower="-1"  velocity="1000" />
 </joint>
 <joint  type="spherical"  name="L_Shoulder" >
  <parent  link="L_sblade" />
  <child  link="L_Arm1" />
  <origin  xyz="0.0 0.0 0.0"  rpy="0 0 0" />
 </joint>
 <joint  type="revolute"  name="L_Elbow" >
  <parent  link="L_Arm1" />
  <child  link="L_Arm2" />
  <origin  xyz="0.2910845268292164 0.0 0.0"  rpy="0 0.0 0" />
  <axis  xyz="1 0 0" />
  <limit  effort="100"  upper="0.01"  lower="-3.14"  velocity="1000" />
 </joint>
 <joint  type="revolute"  name="L_Wrist_P" >
  <parent  link="L_Arm2" />
  <child  link="L_Wrist1" />
  <origin  xyz="0.28766396609553524 0.0 0.0"  rpy="0 0.0 0" />
  <axis  xyz="1 0 0" />
  <limit  effort="100"  upper="0.5"  lower="-0.5"  velocity="1000" />
 </joint>
 <joint  type="revolute"  name="L_Wrist_R" >
  <parent  link="L_Wrist1" />
  <child  link="L_Wrist2" />
  <origin  xyz="0.0 0.0 0.0"  rpy="0 0.0 0" />
  <axis  xyz="0 1 0" />
  <limit  effort="100"  upper="0.5"  lower="-0.5"  velocity="1000" />
 </joint>
 <joint  type="revolute"  name="L_Wrist_Y" >
  <parent  link="L_Wrist2" />
  <child  link="L_Wrist3" />
  <origin  xyz="0.0 0.0 0.0"  rpy="0 0.0 0" />
  <axis  xyz="0 0 1" />
  <limit  effort="100"  upper="0.3"  lower="-0.3"  velocity="1000" />
 </joint>
 <joint  type="prismatic"  name="R_Shoulder_Prism" >
  <parent  link="Spine3" />
  <child  link="R_sblade" />
  <origin  xyz="-0.20185373398483272 0.0 0.362878"  rpy="0 0.0 0" />
  <axis  xyz="0 0 1" />
  <limit  effort="1"  upper="1"  lower="-1"  velocity="1000" />
 </joint>
 <joint  type="spherical"  name="R_Shoulder" >
  <parent  link="R_sblade" />
  <child  link="R_Arm1" />
  <origin  xyz="0.0 0.0 0.0"  rpy="0 0 0" />
 </joint>
 <joint  type="revolute"  name="R_Elbow" >
  <parent  link="R_Arm1" />
  <child  link="R_Arm2" />
  <origin  xyz="-0.2910845268292164 0.0 0.0"  rpy="0 0.0 0" />
  <axis  xyz="1 0 0" />
  <limit  effort="100"  upper="0.01"  lower="-3.14"  velocity="1000" />
 </joint>
 <joint  type="revolute"  name="R_Wrist_P" >
  <parent  link="R_Arm2" />
  <child  link="R_Wrist1" />
  <origin  xyz="-0.28766396609553524 0.0 0.0"  rpy="0 0.0 0" />
  <axis  xyz="1 0 0" />
  <limit  effort="100"  upper="0.5"  lower="-0.5"  velocity="1000" />
 </joint>
 <joint  type="revolute"  name="R_Wrist_R" >
  <parent  link="R_Wrist1" />
  <child  link="R_Wrist2" />
  <origin  xyz="0.0 0.0 0.0"  rpy="0 0.0 0" />
  <axis  xyz="0 1 0" />
  <limit  effort="100"  upper="0.5"  lower="-0.5"  velocity="1000" />
 </joint>
 <joint  type="revolute"  name="R_Wrist_Y" >
  <parent  link="R_Wrist2" />
  <child  link="R_Wrist3" />
  <origin  xyz="0.0 0.0 0.0"  rpy="0 0.0 0" />
  <axis  xyz="0 0 1" />
  <limit  effort="100"  upper="0.3"  lower="-0.3"  velocity="1000" />
 </joint>
 <joint  type="spherical"  name="L_Hip" >
  <parent  link="BODY" />
  <child  link="L_Leg1" />
  <origin  xyz="0.1118922968527683 0.0 0.0"  rpy="0 0.0 0" />
 </joint>
 <joint  type="revolute"  name="L_Knee" >
  <parent  link="L_Leg1" />
  <child  link="L_Leg2" />
  <origin  xyz="0.0 0.0 -0.4440205478243884"  rpy="0 0 0" />
  <axis  xyz="1 0 0" />
  <limit  effort="100"  upper="3.14"  lower="0.01"  velocity="1000" />
 </joint>
 <joint  type="revolute"  name="L_Ankle_Y" >
  <parent  link="L_Leg2" />
  <child  link="L_Leg3" />
  <origin  xyz="0.0 0.0 -0.45496664112718577"  rpy="0 0.0 0" />
  <axis  xyz="0 0 -1" />
  <limit  effort="100"  upper="0.7"  lower="-0.7"  velocity="1000" />
 </joint>
 <joint  type="revolute"  name="L_Ankle_R" >
  <parent  link="L_Leg3" />
  <child  link="L_Leg4" />
  <origin  xyz="0.0 0.0 0.0"  rpy="0 0.0 0" />
  <axis  xyz="0 1 0" />
  <limit  effort="100"  upper="0.4"  lower="-0.4"  velocity="1000" />
 </joint>
 <joint  type="revolute"  name="L_Ankle_P" >
  <parent  link="L_Leg4" />
  <child  link="L_Ankle" />
  <origin  xyz="0.0 0.0 0.0"  rpy="0 0.0 0" />
  <axis  xyz="1 0 0" />
  <limit  effort="100"  upper="0.4"  lower="-0.4"  velocity="1000" />
 </joint>
 <joint  type="revolute"  name="L_Foot_Pinky_P" >
  <parent  link="L_Ankle" />
  <child  link="L_Foot" />
  <origin  xyz="0.04289849986664887 -0.13942012456660882 -0.05362312483331108"  rpy="0 0.0 0" />
  <axis  xyz="1 0 0" />
  <limit  effort="100"  upper="0.001"  lower="-0.5"  velocity="1000" />
 </joint>
 <joint  type="spherical"  name="R_Hip" >
  <parent  link="BODY" />
  <child  link="R_Leg1" />
  <origin  xyz="-0.1118922968527683 0.0 0.0"  rpy="0 0.0 0" />
 </joint>
 <joint  type="revolute"  name="R_Knee" >
  <parent  link="R_Leg1" />
  <child  link="R_Leg2" />
  <origin  xyz="0.0 0.0 -0.4440205478243884"  rpy="0 0.0 0" />
  <axis  xyz="1 0 0" />
  <limit  effort="100"  upper="3.14"  lower="0.01"  velocity="1000" />
 </joint>
 <joint  type="revolute"  name="R_Ankle_Y" >
  <parent  link="R_Leg2" />
  <child  link="R_Leg3" />
  <origin  xyz="0.0 0.0 -0.45496664112718577"  rpy="0 0.0 0" />
  <axis  xyz="0 0 1" />
  <limit  effort="100"  upper="0.7"  lower="-0.7"  velocity="1000" />
 </joint>
 <joint  type="revolute"  name="R_Ankle_R" >
  <parent  link="R_Leg3" />
  <child  link="R_Leg4" />
  <origin  xyz="0.0 0.0 0.0"  rpy="0 0.0 0" />
  <axis  xyz="0 1 0" />
  <limit  effort="100"  upper="0.4"  lower="-0.4"  velocity="1000" />
 </joint>
 <joint  type="revolute"  name="R_Ankle_P" >
  <parent  link="R_Leg4" />
  <child  link="R_Ankle" />
  <origin  xyz="0.0 0.0 0.0"  rpy="0 0.0 0" />
  <axis  xyz="1 0 0" />
  <limit  effort="100"  upper="0.4"  lower="-0.4"  velocity="1000" />
 </joint>
 <joint  type="revolute"  name="R_Foot_Pinky_P" >
  <parent  link="R_Ankle" />
  <child  link="R_Foot" />
  <origin  xyz="-0.04289849986664887 -0.13942012456660882 -0.05362312483331108"  rpy="0 0.0 0" />
  <axis  xyz="1 0 0" />
  <limit  effort="100"  upper="0.001"  lower="-0.5"  velocity="1000" />
 </joint>
</robot>