<?xml version="1.0" ?>
<robot name="core_skeleton_joints__1_:AITrajectory">
  <link name="BASE">
    <inertial>
      <mass value="0.000001"/>
      <inertia ixx="0.000001" iyy="0.000001" izz="0.000001" ixy="0" ixz="0" iyz="0"/>
      <origin xyz="0 0 0" rpy="0 0 0"/>
    </inertial>
  </link>
  <link name="core_skeleton_joints__1_:Hips"/>
  <joint name="core_skeleton_joints__1_:Hips_fixed_joint" type="fixed">
    <parent link="BASE"/>
    <child link="core_skeleton_joints__1_:Hips"/>
    <axis xyz="0 1 0"/>
    <origin xyz="0.0 -0.02759992890059948 0.9337000250816345" rpy="-3.141592502593994 -1.570796251296997 0.0"/>
  </joint>
  <joint name="core_skeleton_joints__1_:Hips_floating_joint" type="floating">
    <parent link="core_skeleton_joints__1_:Hips"/>
    <child link="core_skeleton_joints__1_:Hips_floating_link"/>
    <origin xyz="0 0 0" rpy="0 0 0"/>
    <axis xyz="100.00000762939453 7.549791462224675e-06 -4.942146952097159e-13"/>
  </joint>
  <link name="core_skeleton_joints__1_:Hips_floating_link"/>
  <link name="core_skeleton_joints__1_:Spine"/>
  <joint name="core_skeleton_joints__1_:Spine_fixed_joint" type="fixed">
    <parent link="core_skeleton_joints__1_:Hips_floating_link"/>
    <child link="core_skeleton_joints__1_:Spine"/>
    <axis xyz="0 1 0"/>
    <origin xyz="0.09300003200769424 -0.016600007191300392 -4.0651588761875246e-09" rpy="4.166775369185416e-09 -4.139046883011588e-09 0.09546942263841629"/>
  </joint>
  <link name="core_skeleton_joints__1_:Spine1"/>
  <joint name="core_skeleton_joints__1_:Spine1_fixed_joint" type="fixed">
    <parent link="core_skeleton_joints__1_:Spine"/>
    <child link="core_skeleton_joints__1_:Spine1"/>
    <axis xyz="0 1 0"/>
    <origin xyz="0.0638999491930008 1.0728835597717534e-08 -3.0449232024665207e-09" rpy="-8.928984662759376e-09 8.497487158365402e-09 -0.18849532306194305"/>
  </joint>
  <joint name="core_skeleton_joints__1_:Spine1_custom_joint_0" type="revolute">
    <parent link="core_skeleton_joints__1_:Spine1"/>
    <child link="core_skeleton_joints__1_:Spine1_custom_link_0"/>
    <origin xyz="0 0 0" rpy="0 0 0"/>
    <axis xyz="-9.27295332076028e-07 3.946196102333488e-06 100.00000762939453"/>
    <limit velocity="1000.0" effort="100.0" upper="0.6000000238418579" lower="-0.20000000298023224"/>
  </joint>
  <link name="core_skeleton_joints__1_:Spine1_custom_link_0">
    <inertial>
      <mass value="0.000001"/>
      <inertia ixx="0.000001" iyy="0.000001" izz="0.000001" ixy="0" ixz="0" iyz="0"/>
      <origin xyz="0 0 0" rpy="0 0 0"/>
    </inertial>
  </link>
  <joint name="core_skeleton_joints__1_:Spine1_custom_joint_1" type="revolute">
    <parent link="core_skeleton_joints__1_:Spine1_custom_link_0"/>
    <child link="core_skeleton_joints__1_:Spine1_custom_link_1"/>
    <origin xyz="0 0 0" rpy="0 0 0"/>
    <axis xyz="9.289183616638184 -99.56761932373047 4.015270860691089e-06"/>
    <limit velocity="1000.0" effort="100.0" upper="0.5199999809265137" lower="-0.5199999809265137"/>
  </joint>
  <link name="core_skeleton_joints__1_:Spine1_custom_link_1">
    <inertial>
      <mass value="0.000001"/>
      <inertia ixx="0.000001" iyy="0.000001" izz="0.000001" ixy="0" ixz="0" iyz="0"/>
      <origin xyz="0 0 0" rpy="0 0 0"/>
    </inertial>
  </link>
  <joint name="core_skeleton_joints__1_:Spine1_custom_joint_2" type="revolute">
    <parent link="core_skeleton_joints__1_:Spine1_custom_link_1"/>
    <child link="core_skeleton_joints__1_:Spine1_custom_link_2"/>
    <origin xyz="0 0 0" rpy="0 0 0"/>
    <axis xyz="99.56761932373047 9.289183616638184 5.567166567743698e-07"/>
    <limit velocity="1000.0" effort="100.0" upper="0.25999999046325684" lower="-0.25999999046325684"/>
  </joint>
  <link name="core_skeleton_joints__1_:Spine1_custom_link_2">
    <inertial>
      <mass value="0.000001"/>
      <inertia ixx="0.000001" iyy="0.000001" izz="0.000001" ixy="0" ixz="0" iyz="0"/>
      <origin xyz="0 0 0" rpy="0 0 0"/>
    </inertial>
  </link>
  <link name="core_skeleton_joints__1_:Spine2"/>
  <joint name="core_skeleton_joints__1_:Spine2_fixed_joint" type="fixed">
    <parent link="core_skeleton_joints__1_:Spine1_custom_link_2"/>
    <child link="core_skeleton_joints__1_:Spine2"/>
    <axis xyz="0 1 0"/>
    <origin xyz="0.08619993925094604 -1.7881397473828997e-09 -3.302311313291284e-09" rpy="-2.9390938571793868e-09 1.895530177264959e-09 -0.07679444551467896"/>
  </joint>
  <link name="core_skeleton_joints__1_:Spine3"/>
  <joint name="core_skeleton_joints__1_:Spine3_fixed_joint" type="fixed">
    <parent link="core_skeleton_joints__1_:Spine2"/>
    <child link="core_skeleton_joints__1_:Spine3"/>
    <axis xyz="0 1 0"/>
    <origin xyz="0.1446000188589096 -2.384185648907078e-08 -5.249183310240824e-09" rpy="1.1866496230084067e-08 -1.7185811884701252e-08 0.33300891518592834"/>
  </joint>
  <joint name="core_skeleton_joints__1_:Spine3_custom_joint_0" type="revolute">
    <parent link="core_skeleton_joints__1_:Spine3"/>
    <child link="core_skeleton_joints__1_:Spine3_custom_link_0"/>
    <origin xyz="0 0 0" rpy="0 0 0"/>
    <axis xyz="1.5463878071386716e-06 5.023221547162393e-06 100.0"/>
    <limit velocity="1000.0" effort="100.0" upper="0.3400000035762787" lower="-0.20000000298023224"/>
  </joint>
  <link name="core_skeleton_joints__1_:Spine3_custom_link_0">
    <inertial>
      <mass value="0.000001"/>
      <inertia ixx="0.000001" iyy="0.000001" izz="0.000001" ixy="0" ixz="0" iyz="0"/>
      <origin xyz="0 0 0" rpy="0 0 0"/>
    </inertial>
  </link>
  <joint name="core_skeleton_joints__1_:Spine3_custom_joint_1" type="revolute">
    <parent link="core_skeleton_joints__1_:Spine3_custom_link_0"/>
    <child link="core_skeleton_joints__1_:Spine3_custom_link_1"/>
    <origin xyz="0 0 0" rpy="0 0 0"/>
    <axis xyz="-16.246517181396484 -98.67142486572266 5.207718004385242e-06"/>
    <limit velocity="1000.0" effort="100.0" upper="0.5199999809265137" lower="-0.5199999809265137"/>
  </joint>
  <link name="core_skeleton_joints__1_:Spine3_custom_link_1">
    <inertial>
      <mass value="0.000001"/>
      <inertia ixx="0.000001" iyy="0.000001" izz="0.000001" ixy="0" ixz="0" iyz="0"/>
      <origin xyz="0 0 0" rpy="0 0 0"/>
    </inertial>
  </link>
  <joint name="core_skeleton_joints__1_:Spine3_custom_joint_2" type="revolute">
    <parent link="core_skeleton_joints__1_:Spine3_custom_link_1"/>
    <child link="core_skeleton_joints__1_:Spine3_custom_link_2"/>
    <origin xyz="0 0 0" rpy="0 0 0"/>
    <axis xyz="98.67144012451172 -16.24652099609375 -7.097441425685247e-07"/>
    <limit velocity="1000.0" effort="100.0" upper="0.8199999928474426" lower="-0.8199999928474426"/>
  </joint>
  <link name="core_skeleton_joints__1_:Spine3_custom_link_2">
    <inertial>
      <mass value="0.000001"/>
      <inertia ixx="0.000001" iyy="0.000001" izz="0.000001" ixy="0" ixz="0" iyz="0"/>
      <origin xyz="0 0 0" rpy="0 0 0"/>
    </inertial>
  </link>
  <link name="core_skeleton_joints__1_:Neck"/>
  <joint name="core_skeleton_joints__1_:Neck_fixed_joint" type="fixed">
    <parent link="core_skeleton_joints__1_:Spine3_custom_link_2"/>
    <child link="core_skeleton_joints__1_:Neck"/>
    <axis xyz="0 1 0"/>
    <origin xyz="0.17689992487430573 -4.5299529460862686e-08 -9.109099252668784e-09" rpy="3.654730518221072e-09 -1.080447051271527e-10 0.07103399932384491"/>
  </joint>
  <link name="core_skeleton_joints__1_:Neck1"/>
  <joint name="core_skeleton_joints__1_:Neck1_fixed_joint" type="fixed">
    <parent link="core_skeleton_joints__1_:Neck"/>
    <child link="core_skeleton_joints__1_:Neck1"/>
    <axis xyz="0 1 0"/>
    <origin xyz="0.06460007280111313 -1.4305115314527939e-08 -3.3250335818024723e-09" rpy="-1.163101970291791e-08 6.1480283086723375e-09 -0.22793996334075928"/>
  </joint>
  <joint name="core_skeleton_joints__1_:Neck1_custom_joint_0" type="revolute">
    <parent link="core_skeleton_joints__1_:Neck1"/>
    <child link="core_skeleton_joints__1_:Neck1_custom_link_0"/>
    <origin xyz="0 0 0" rpy="0 0 0"/>
    <axis xyz="99.998046875 -0.6282539367675781 -2.794860520793918e-08"/>
    <limit velocity="1000.0" effort="100.0" upper="1.4800000190734863" lower="-1.4800000190734863"/>
  </joint>
  <link name="core_skeleton_joints__1_:Neck1_custom_link_0">
    <inertial>
      <mass value="0.000001"/>
      <inertia ixx="0.000001" iyy="0.000001" izz="0.000001" ixy="0" ixz="0" iyz="0"/>
      <origin xyz="0 0 0" rpy="0 0 0"/>
    </inertial>
  </link>
  <joint name="core_skeleton_joints__1_:Neck1_custom_joint_1" type="revolute">
    <parent link="core_skeleton_joints__1_:Neck1_custom_link_0"/>
    <child link="core_skeleton_joints__1_:Neck1_custom_link_1"/>
    <origin xyz="0 0 0" rpy="0 0 0"/>
    <axis xyz="5.558343829648038e-08 4.398517376102973e-06 100.0"/>
    <limit velocity="1000.0" effort="100.0" upper="1.1100000143051147" lower="-1.090000033378601"/>
  </joint>
  <link name="core_skeleton_joints__1_:Neck1_custom_link_1">
    <inertial>
      <mass value="0.000001"/>
      <inertia ixx="0.000001" iyy="0.000001" izz="0.000001" ixy="0" ixz="0" iyz="0"/>
      <origin xyz="0 0 0" rpy="0 0 0"/>
    </inertial>
  </link>
  <joint name="core_skeleton_joints__1_:Neck1_custom_joint_2" type="revolute">
    <parent link="core_skeleton_joints__1_:Neck1_custom_link_1"/>
    <child link="core_skeleton_joints__1_:Neck1_custom_link_2"/>
    <origin xyz="0 0 0" rpy="0 0 0"/>
    <axis xyz="-0.6282493472099304 -99.998046875 4.398779310577083e-06"/>
    <limit velocity="1000.0" effort="100.0" upper="0.8500000238418579" lower="-0.8500000238418579"/>
  </joint>
  <link name="core_skeleton_joints__1_:Neck1_custom_link_2">
    <inertial>
      <mass value="0.000001"/>
      <inertia ixx="0.000001" iyy="0.000001" izz="0.000001" ixy="0" ixz="0" iyz="0"/>
      <origin xyz="0 0 0" rpy="0 0 0"/>
    </inertial>
  </link>
  <link name="core_skeleton_joints__1_:Head"/>
  <joint name="core_skeleton_joints__1_:Head_fixed_joint" type="fixed">
    <parent link="core_skeleton_joints__1_:Neck1_custom_link_2"/>
    <child link="core_skeleton_joints__1_:Head"/>
    <axis xyz="0 1 0"/>
    <origin xyz="0.08610011637210846 4.768371297814156e-08 -3.787685276535058e-09" rpy="7.524147416226867e-10 -6.513919958983649e-10 0.017105156555771828"/>
  </joint>
  <link name="core_skeleton_joints__1_:HeadEnd"/>
  <joint name="core_skeleton_joints__1_:HeadEnd_fixed_joint" type="fixed">
    <parent link="core_skeleton_joints__1_:Head"/>
    <child link="core_skeleton_joints__1_:HeadEnd"/>
    <axis xyz="0 1 0"/>
    <origin xyz="0.15859994292259216 -6.437301180994837e-08 -7.079376640461987e-09" rpy="-4.197163450125885e-15 -4.89832063799156e-11 1.7347169619294832e-18"/>
  </joint>
  <link name="core_skeleton_joints__1_:LeftShoulder"/>
  <joint name="core_skeleton_joints__1_:LeftShoulder_fixed_joint" type="fixed">
    <parent link="core_skeleton_joints__1_:Spine3_custom_link_2"/>
    <child link="core_skeleton_joints__1_:LeftShoulder"/>
    <axis xyz="0 1 0"/>
    <origin xyz="0.1456000655889511 0.0606999434530735 0.025199992582201958" rpy="-1.4039427042007446 -2.0315632820129395 1.2219047546386719"/>
  </joint>
  <joint name="core_skeleton_joints__1_:LeftShoulder_custom_joint_0" type="revolute">
    <parent link="core_skeleton_joints__1_:LeftShoulder"/>
    <child link="core_skeleton_joints__1_:LeftShoulder_custom_link_0"/>
    <origin xyz="0 0 0" rpy="0 0 0"/>
    <axis xyz="43.69903564453125 -89.8750228881836 -3.5870776176452637"/>
    <limit velocity="1000.0" effort="100.0" upper="0.4300000071525574" lower="-0.25999999046325684"/>
  </joint>
  <link name="core_skeleton_joints__1_:LeftShoulder_custom_link_0">
    <inertial>
      <mass value="0.000001"/>
      <inertia ixx="0.000001" iyy="0.000001" izz="0.000001" ixy="0" ixz="0" iyz="0"/>
      <origin xyz="0 0 0" rpy="0 0 0"/>
    </inertial>
  </link>
  <joint name="core_skeleton_joints__1_:LeftShoulder_custom_joint_1" type="revolute">
    <parent link="core_skeleton_joints__1_:LeftShoulder_custom_link_0"/>
    <child link="core_skeleton_joints__1_:LeftShoulder_custom_link_1"/>
    <origin xyz="0 0 0" rpy="0 0 0"/>
    <axis xyz="-8.209627151489258 -0.013975515030324459 -99.66242980957031"/>
    <limit velocity="1000.0" effort="100.0" upper="0.4300000071525574" lower="-0.4300000071525574"/>
  </joint>
  <link name="core_skeleton_joints__1_:LeftShoulder_custom_link_1">
    <inertial>
      <mass value="0.000001"/>
      <inertia ixx="0.000001" iyy="0.000001" izz="0.000001" ixy="0" ixz="0" iyz="0"/>
      <origin xyz="0 0 0" rpy="0 0 0"/>
    </inertial>
  </link>
  <link name="core_skeleton_joints__1_:LeftArm"/>
  <joint name="core_skeleton_joints__1_:LeftArm_fixed_joint" type="fixed">
    <parent link="core_skeleton_joints__1_:LeftShoulder_custom_link_1"/>
    <child link="core_skeleton_joints__1_:LeftArm"/>
    <axis xyz="0 1 0"/>
    <origin xyz="0.1800999790430069 8.385628547102897e-08 4.835426636873308e-08" rpy="-0.017802132293581963 -0.8185592293739319 0.42202049493789673"/>
  </joint>
  <joint name="core_skeleton_joints__1_:LeftArm_custom_joint_0" type="spherical">
    <parent link="core_skeleton_joints__1_:LeftArm"/>
    <child link="core_skeleton_joints__1_:LeftArm_custom_link_0"/>
    <origin xyz="0 0 0" rpy="0 0 0"/>
    <axis xyz="-4.910170173388906e-05 6.711842060089111 -99.7750244140625"/>
    <limit velocity="0" effort="0" upper="0" lower="0"/>
  </joint>
  <link name="core_skeleton_joints__1_:LeftArm_custom_link_0">
    <inertial>
      <mass value="0.000001"/>
      <inertia ixx="0.000001" iyy="0.000001" izz="0.000001" ixy="0" ixz="0" iyz="0"/>
      <origin xyz="0 0 0" rpy="0 0 0"/>
    </inertial>
  </link>
  <link name="core_skeleton_joints__1_:LeftForeArm"/>
  <joint name="core_skeleton_joints__1_:LeftForeArm_fixed_joint" type="fixed">
    <parent link="core_skeleton_joints__1_:LeftArm_custom_link_0"/>
    <child link="core_skeleton_joints__1_:LeftForeArm"/>
    <axis xyz="0 1 0"/>
    <origin xyz="0.3005000948905945 1.3709067658851382e-08 -1.192092824453539e-08" rpy="-3.609058012443711e-07 -5.8024152593816325e-08 0.3612836003303528"/>
  </joint>
  <joint name="core_skeleton_joints__1_:LeftForeArm_custom_joint_0" type="revolute">
    <parent link="core_skeleton_joints__1_:LeftForeArm"/>
    <child link="core_skeleton_joints__1_:LeftForeArm_custom_link_0"/>
    <origin xyz="0 0 0" rpy="0 0 0"/>
    <axis xyz="-1.1258940503466874e-05 6.711885929107666 -99.77527618408203"/>
    <limit velocity="1000.0" effort="100.0" upper="0.009999999776482582" lower="-3.140000104904175"/>
  </joint>
  <link name="core_skeleton_joints__1_:LeftForeArm_custom_link_0">
    <inertial>
      <mass value="0.000001"/>
      <inertia ixx="0.000001" iyy="0.000001" izz="0.000001" ixy="0" ixz="0" iyz="0"/>
      <origin xyz="0 0 0" rpy="0 0 0"/>
    </inertial>
  </link>
  <link name="core_skeleton_joints__1_:LeftHand"/>
  <joint name="core_skeleton_joints__1_:LeftHand_fixed_joint" type="fixed">
    <parent link="core_skeleton_joints__1_:LeftForeArm_custom_link_0"/>
    <child link="core_skeleton_joints__1_:LeftHand"/>
    <axis xyz="0 1 0"/>
    <origin xyz="0.2600000202655792 -1.1920928955078125e-07 -6.794929419129403e-08" rpy="-2.7567148208618164e-07 1.3597309589385986e-07 -7.450599248670642e-09"/>
  </joint>
  <joint name="core_skeleton_joints__1_:LeftHand_custom_joint_0" type="revolute">
    <parent link="core_skeleton_joints__1_:LeftHand"/>
    <child link="core_skeleton_joints__1_:LeftHand_custom_link_0"/>
    <origin xyz="0 0 0" rpy="0 0 0"/>
    <axis xyz="1.7502702576166485e-06 6.711913585662842 -99.77527618408203"/>
    <limit velocity="1000.0" effort="100.0" upper="1.5700000524520874" lower="-1.5700000524520874"/>
  </joint>
  <link name="core_skeleton_joints__1_:LeftHand_custom_link_0">
    <inertial>
      <mass value="0.000001"/>
      <inertia ixx="0.000001" iyy="0.000001" izz="0.000001" ixy="0" ixz="0" iyz="0"/>
      <origin xyz="0 0 0" rpy="0 0 0"/>
    </inertial>
  </link>
  <joint name="core_skeleton_joints__1_:LeftHand_custom_joint_1" type="revolute">
    <parent link="core_skeleton_joints__1_:LeftHand_custom_link_0"/>
    <child link="core_skeleton_joints__1_:LeftHand_custom_link_1"/>
    <origin xyz="0 0 0" rpy="0 0 0"/>
    <axis xyz="-0.00017910185852088034 -99.77500915527344 -6.711928844451904"/>
    <limit velocity="1000.0" effort="100.0" upper="1.5700000524520874" lower="-1.5700000524520874"/>
  </joint>
  <link name="core_skeleton_joints__1_:LeftHand_custom_link_1">
    <inertial>
      <mass value="0.000001"/>
      <inertia ixx="0.000001" iyy="0.000001" izz="0.000001" ixy="0" ixz="0" iyz="0"/>
      <origin xyz="0 0 0" rpy="0 0 0"/>
    </inertial>
  </link>
  <joint name="core_skeleton_joints__1_:LeftHand_custom_joint_2" type="revolute">
    <parent link="core_skeleton_joints__1_:LeftHand_custom_link_1"/>
    <child link="core_skeleton_joints__1_:LeftHand_custom_link_2"/>
    <origin xyz="0 0 0" rpy="0 0 0"/>
    <axis xyz="-100.00035095214844 0.00019648911256808788 -1.8959269709739601e-06"/>
    <limit velocity="1000.0" effort="100.0" upper="0.5" lower="-0.5"/>
  </joint>
  <link name="core_skeleton_joints__1_:LeftHand_custom_link_2">
    <inertial>
      <mass value="0.000001"/>
      <inertia ixx="0.000001" iyy="0.000001" izz="0.000001" ixy="0" ixz="0" iyz="0"/>
      <origin xyz="0 0 0" rpy="0 0 0"/>
    </inertial>
  </link>
  <link name="core_skeleton_joints__1_:LeftHandThumb1"/>
  <joint name="core_skeleton_joints__1_:LeftHandThumb1_fixed_joint" type="fixed">
    <parent link="core_skeleton_joints__1_:LeftHand_custom_link_2"/>
    <child link="core_skeleton_joints__1_:LeftHandThumb1"/>
    <axis xyz="0 1 0"/>
    <origin xyz="0.006499972194433212 0.021099986508488655 0.016400009393692017" rpy="2.8806660175323486 -0.5633924007415771 0.5799727439880371"/>
  </joint>
  <link name="core_skeleton_joints__1_:LeftHandThumb2"/>
  <joint name="core_skeleton_joints__1_:LeftHandThumb2_fixed_joint" type="fixed">
    <parent link="core_skeleton_joints__1_:LeftHandThumb1"/>
    <child link="core_skeleton_joints__1_:LeftHandThumb2"/>
    <axis xyz="0 1 0"/>
    <origin xyz="0.050700053572654724 1.23977656585339e-07 -5.960464477539063e-08" rpy="-7.399081169978672e-08 -3.999080604444316e-07 0.16336330771446228"/>
  </joint>
  <link name="core_skeleton_joints__1_:LeftHandThumb3"/>
  <joint name="core_skeleton_joints__1_:LeftHandThumb3_fixed_joint" type="fixed">
    <parent link="core_skeleton_joints__1_:LeftHandThumb2"/>
    <child link="core_skeleton_joints__1_:LeftHandThumb3"/>
    <axis xyz="0 1 0"/>
    <origin xyz="0.03420000523328781 -3.814697180359872e-08 -7.390976008991856e-08" rpy="5.130705744704755e-07 8.062836514000082e-07 0.3415604531764984"/>
  </joint>
  <link name="core_skeleton_joints__1_:LeftHandThumbEnd"/>
  <joint name="core_skeleton_joints__1_:LeftHandThumbEnd_fixed_joint" type="fixed">
    <parent link="core_skeleton_joints__1_:LeftHandThumb3"/>
    <child link="core_skeleton_joints__1_:LeftHandThumbEnd"/>
    <axis xyz="0 1 0"/>
    <origin xyz="0.030699942260980606 -1.907348590179936e-08 -3.33786012163273e-08" rpy="5.401671643312511e-08 9.313225746154785e-09 -4.6566106526313433e-10"/>
  </joint>
  <link name="core_skeleton_joints__1_:LeftInHandIndex"/>
  <joint name="core_skeleton_joints__1_:LeftInHandIndex_fixed_joint" type="fixed">
    <parent link="core_skeleton_joints__1_:LeftHand_custom_link_2"/>
    <child link="core_skeleton_joints__1_:LeftInHandIndex"/>
    <axis xyz="0 1 0"/>
    <origin xyz="0.015200014226138592 0.014699983410537243 0.004100013058632612" rpy="1.6678370237350464 -0.14102289080619812 0.17784900963306427"/>
  </joint>
  <link name="core_skeleton_joints__1_:LeftHandIndex1"/>
  <joint name="core_skeleton_joints__1_:LeftHandIndex1_fixed_joint" type="fixed">
    <parent link="core_skeleton_joints__1_:LeftInHandIndex"/>
    <child link="core_skeleton_joints__1_:LeftHandIndex1"/>
    <axis xyz="0 1 0"/>
    <origin xyz="0.07500004768371582 5.960464477539063e-08 9.53674295089968e-09" rpy="0.16057075560092926 0.06929004937410355 0.29705432057380676"/>
  </joint>
  <link name="core_skeleton_joints__1_:LeftHandIndex2"/>
  <joint name="core_skeleton_joints__1_:LeftHandIndex2_fixed_joint" type="fixed">
    <parent link="core_skeleton_joints__1_:LeftHandIndex1"/>
    <child link="core_skeleton_joints__1_:LeftHandIndex2"/>
    <axis xyz="0 1 0"/>
    <origin xyz="0.048199985176324844 4.291534239087014e-08 6.67572024326546e-08" rpy="-9.759097565620323e-07 -5.552682296183775e-07 0.3454006314277649"/>
  </joint>
  <link name="core_skeleton_joints__1_:LeftHandIndex3"/>
  <joint name="core_skeleton_joints__1_:LeftHandIndex3_fixed_joint" type="fixed">
    <parent link="core_skeleton_joints__1_:LeftHandIndex2"/>
    <child link="core_skeleton_joints__1_:LeftHandIndex3"/>
    <axis xyz="0 1 0"/>
    <origin xyz="0.023500045761466026 3.814697180359872e-08 3.814697180359872e-08" rpy="3.7188695500844915e-07 3.487921844680386e-07 0.2359689325094223"/>
  </joint>
  <link name="core_skeleton_joints__1_:LeftHandIndexEnd"/>
  <joint name="core_skeleton_joints__1_:LeftHandIndexEnd_fixed_joint" type="fixed">
    <parent link="core_skeleton_joints__1_:LeftHandIndex3"/>
    <child link="core_skeleton_joints__1_:LeftHandIndexEnd"/>
    <axis xyz="0 1 0"/>
    <origin xyz="0.0221999678760767 -2.8610228852699038e-08 -2.8610228852699038e-08" rpy="1.8626450382086546e-09 -1.4901162970204496e-08 7.450581485102248e-09"/>
  </joint>
  <link name="core_skeleton_joints__1_:LeftInHandMiddle"/>
  <joint name="core_skeleton_joints__1_:LeftInHandMiddle_fixed_joint" type="fixed">
    <parent link="core_skeleton_joints__1_:LeftHand_custom_link_2"/>
    <child link="core_skeleton_joints__1_:LeftInHandMiddle"/>
    <axis xyz="0 1 0"/>
    <origin xyz="0.018800003454089165 0.0007999801309779286 -0.003100025001913309" rpy="1.6838939189910889 -0.1774996668100357 0.0804593563079834"/>
  </joint>
  <link name="core_skeleton_joints__1_:LeftHandMiddle1"/>
  <joint name="core_skeleton_joints__1_:LeftHandMiddle1_fixed_joint" type="fixed">
    <parent link="core_skeleton_joints__1_:LeftInHandMiddle"/>
    <child link="core_skeleton_joints__1_:LeftHandMiddle1"/>
    <axis xyz="0 1 0"/>
    <origin xyz="0.07789991796016693 1.5616416249031317e-07 3.814697180359872e-08" rpy="-0.11484270542860031 -0.005585158243775368 0.30962127447128296"/>
  </joint>
  <link name="core_skeleton_joints__1_:LeftHandMiddle2"/>
  <joint name="core_skeleton_joints__1_:LeftHandMiddle2_fixed_joint" type="fixed">
    <parent link="core_skeleton_joints__1_:LeftHandMiddle1"/>
    <child link="core_skeleton_joints__1_:LeftHandMiddle2"/>
    <axis xyz="0 1 0"/>
    <origin xyz="0.04879995062947273 8.583068478174027e-08 1.907348590179936e-08" rpy="-5.219489480623452e-07 -2.2243153807721683e-07 0.4262101650238037"/>
  </joint>
  <link name="core_skeleton_joints__1_:LeftHandMiddle3"/>
  <joint name="core_skeleton_joints__1_:LeftHandMiddle3_fixed_joint" type="fixed">
    <parent link="core_skeleton_joints__1_:LeftHandMiddle2"/>
    <child link="core_skeleton_joints__1_:LeftHandMiddle3"/>
    <axis xyz="0 1 0"/>
    <origin xyz="0.02899996191263199 9.53674295089968e-09 1.907348590179936e-08" rpy="3.4802934578692657e-07 5.6344443777334163e-08 0.22828860580921173"/>
  </joint>
  <link name="core_skeleton_joints__1_:LeftHandMiddleEnd"/>
  <joint name="core_skeleton_joints__1_:LeftHandMiddleEnd_fixed_joint" type="fixed">
    <parent link="core_skeleton_joints__1_:LeftHandMiddle3"/>
    <child link="core_skeleton_joints__1_:LeftHandMiddleEnd"/>
    <axis xyz="0 1 0"/>
    <origin xyz="0.023800019174814224 -4.291534239087014e-08 -1.907348590179936e-08" rpy="7.450581485102248e-09 2.2351741790771484e-08 4.842877388000488e-08"/>
  </joint>
  <link name="core_skeleton_joints__1_:LeftInHandRing"/>
  <joint name="core_skeleton_joints__1_:LeftInHandRing_fixed_joint" type="fixed">
    <parent link="core_skeleton_joints__1_:LeftHand_custom_link_2"/>
    <child link="core_skeleton_joints__1_:LeftInHandRing"/>
    <axis xyz="0 1 0"/>
    <origin xyz="0.018999958410859108 -0.012499989941716194 -0.003500076476484537" rpy="1.6704550981521606 -0.20472681522369385 0.008377378806471825"/>
  </joint>
  <link name="core_skeleton_joints__1_:LeftHandRing1"/>
  <joint name="core_skeleton_joints__1_:LeftHandRing1_fixed_joint" type="fixed">
    <parent link="core_skeleton_joints__1_:LeftInHandRing"/>
    <child link="core_skeleton_joints__1_:LeftHandRing1"/>
    <axis xyz="0 1 0"/>
    <origin xyz="0.07429999858140945 8.225440950582197e-08 1.907348590179936e-08" rpy="-0.1804673969745636 -0.058817602694034576 0.3459249436855316"/>
  </joint>
  <link name="core_skeleton_joints__1_:LeftHandRing2"/>
  <joint name="core_skeleton_joints__1_:LeftHandRing2_fixed_joint" type="fixed">
    <parent link="core_skeleton_joints__1_:LeftHandRing1"/>
    <child link="core_skeleton_joints__1_:LeftHandRing2"/>
    <axis xyz="0 1 0"/>
    <origin xyz="0.04550012946128845 -3.993510944155787e-08 9.53674295089968e-09" rpy="3.7369886740634684e-07 8.237117299358943e-08 0.38466981053352356"/>
  </joint>
  <link name="core_skeleton_joints__1_:LeftHandRing3"/>
  <joint name="core_skeleton_joints__1_:LeftHandRing3_fixed_joint" type="fixed">
    <parent link="core_skeleton_joints__1_:LeftHandRing2"/>
    <child link="core_skeleton_joints__1_:LeftHandRing3"/>
    <axis xyz="0 1 0"/>
    <origin xyz="0.02670004963874817 6.19888282926695e-08 2.8610228852699038e-08" rpy="-7.490390885322995e-07 -1.909377829178993e-07 0.15271812677383423"/>
  </joint>
  <link name="core_skeleton_joints__1_:LeftHandRingEnd"/>
  <joint name="core_skeleton_joints__1_:LeftHandRingEnd_fixed_joint" type="fixed">
    <parent link="core_skeleton_joints__1_:LeftHandRing3"/>
    <child link="core_skeleton_joints__1_:LeftHandRingEnd"/>
    <axis xyz="0 1 0"/>
    <origin xyz="0.02439991943538189 -1.4305114426349519e-08 -1.4305114426349519e-08" rpy="-4.470348713425665e-08 -9.313231075225303e-09 -1.7695128917694092e-07"/>
  </joint>
  <link name="core_skeleton_joints__1_:LeftInHandPinky"/>
  <joint name="core_skeleton_joints__1_:LeftInHandPinky_fixed_joint" type="fixed">
    <parent link="core_skeleton_joints__1_:LeftHand_custom_link_2"/>
    <child link="core_skeleton_joints__1_:LeftInHandPinky"/>
    <axis xyz="0 1 0"/>
    <origin xyz="0.017199985682964325 -0.0252000093460083 0.0005999899003654718" rpy="1.6612046957015991 -0.15952321887016296 -0.13508881628513336"/>
  </joint>
  <link name="core_skeleton_joints__1_:LeftHandPinky1"/>
  <joint name="core_skeleton_joints__1_:LeftHandPinky1_fixed_joint" type="fixed">
    <parent link="core_skeleton_joints__1_:LeftInHandPinky"/>
    <child link="core_skeleton_joints__1_:LeftHandPinky1"/>
    <axis xyz="0 1 0"/>
    <origin xyz="0.06689995527267456 5.781650358471779e-08 9.53674295089968e-09" rpy="-0.2427753508090973 0.010646341368556023 0.44645437598228455"/>
  </joint>
  <link name="core_skeleton_joints__1_:LeftHandPinky2"/>
  <joint name="core_skeleton_joints__1_:LeftHandPinky2_fixed_joint" type="fixed">
    <parent link="core_skeleton_joints__1_:LeftHandPinky1"/>
    <child link="core_skeleton_joints__1_:LeftHandPinky2"/>
    <axis xyz="0 1 0"/>
    <origin xyz="0.039000004529953 4.1127204752910984e-08 9.53674295089968e-09" rpy="-2.894211661441659e-07 -1.4117084390363743e-07 0.2951366901397705"/>
  </joint>
  <link name="core_skeleton_joints__1_:LeftHandPinky3"/>
  <joint name="core_skeleton_joints__1_:LeftHandPinky3_fixed_joint" type="fixed">
    <parent link="core_skeleton_joints__1_:LeftHandPinky2"/>
    <child link="core_skeleton_joints__1_:LeftHandPinky3"/>
    <axis xyz="0 1 0"/>
    <origin xyz="0.021499985828995705 -1.87754629621395e-08 -2.8610228852699038e-08" rpy="2.023136573825468e-07 2.6728136504061695e-07 0.17243866622447968"/>
  </joint>
  <link name="core_skeleton_joints__1_:LeftHandPinkyEnd"/>
  <joint name="core_skeleton_joints__1_:LeftHandPinkyEnd_fixed_joint" type="fixed">
    <parent link="core_skeleton_joints__1_:LeftHandPinky3"/>
    <child link="core_skeleton_joints__1_:LeftHandPinkyEnd"/>
    <axis xyz="0 1 0"/>
    <origin xyz="0.020199932157993317 2.9802320611338473e-09 -4.76837147544984e-09" rpy="2.7939686120248552e-09 -3.725291186640334e-09 -1.2305100938192481e-07"/>
  </joint>
  <link name="core_skeleton_joints__1_:Left_sb_foreArmTwist_001"/>
  <joint name="core_skeleton_joints__1_:Left_sb_foreArmTwist_001_fixed_joint" type="fixed">
    <parent link="core_skeleton_joints__1_:LeftForeArm_custom_link_0"/>
    <child link="core_skeleton_joints__1_:Left_sb_foreArmTwist_001"/>
    <axis xyz="0 1 0"/>
    <origin xyz="6.020069065471034e-08 4.17232506322307e-08 -5.237757960685485e-08" rpy="-3.166496753692627e-08 6.146729703004894e-08 -1.862645504502325e-08"/>
  </joint>
  <link name="core_skeleton_joints__1_:Left_sb_foreArmTwist_002"/>
  <joint name="core_skeleton_joints__1_:Left_sb_foreArmTwist_002_fixed_joint" type="fixed">
    <parent link="core_skeleton_joints__1_:LeftForeArm_custom_link_0"/>
    <child link="core_skeleton_joints__1_:Left_sb_foreArmTwist_002"/>
    <axis xyz="0 1 0"/>
    <origin xyz="0.08670000731945038 2.8610228852699038e-08 -7.539987478821786e-08" rpy="2.0675365419720038e-07 9.313151361212135e-10 6.33299421792799e-08"/>
  </joint>
  <link name="core_skeleton_joints__1_:Left_sb_foreArmTwist_003"/>
  <joint name="core_skeleton_joints__1_:Left_sb_foreArmTwist_003_fixed_joint" type="fixed">
    <parent link="core_skeleton_joints__1_:LeftForeArm_custom_link_0"/>
    <child link="core_skeleton_joints__1_:Left_sb_foreArmTwist_003"/>
    <axis xyz="0 1 0"/>
    <origin xyz="0.17329998314380646 -5.7220457705398076e-08 -4.440546064188311e-08" rpy="2.2165481539104803e-07 -1.3010428187408421e-15 3.7252920748187535e-09"/>
  </joint>
  <link name="core_skeleton_joints__1_:Left_sb_armTwist_001"/>
  <joint name="core_skeleton_joints__1_:Left_sb_armTwist_001_fixed_joint" type="fixed">
    <parent link="core_skeleton_joints__1_:LeftArm_custom_link_0"/>
    <child link="core_skeleton_joints__1_:Left_sb_armTwist_001"/>
    <axis xyz="0 1 0"/>
    <origin xyz="3.929715575168302e-08 -1.7285346487483366e-08 -1.2218952072373668e-08" rpy="-2.9802320611338473e-08 -1.2206146493554115e-07 -1.88592803596066e-08"/>
  </joint>
  <link name="core_skeleton_joints__1_:Left_sb_armTwist_002"/>
  <joint name="core_skeleton_joints__1_:Left_sb_armTwist_002_fixed_joint" type="fixed">
    <parent link="core_skeleton_joints__1_:LeftArm_custom_link_0"/>
    <child link="core_skeleton_joints__1_:Left_sb_armTwist_002"/>
    <axis xyz="0 1 0"/>
    <origin xyz="0.10020004957914352 -3.5762786065873797e-09 -5.9604643443123e-10" rpy="-5.4016705774984075e-08 -1.2051896192133427e-07 -6.309710443019867e-08"/>
  </joint>
  <link name="core_skeleton_joints__1_:Left_sb_armTwist_003"/>
  <joint name="core_skeleton_joints__1_:Left_sb_armTwist_003_fixed_joint" type="fixed">
    <parent link="core_skeleton_joints__1_:LeftArm_custom_link_0"/>
    <child link="core_skeleton_joints__1_:Left_sb_armTwist_003"/>
    <axis xyz="0 1 0"/>
    <origin xyz="0.20030000805854797 1.2516975012033527e-08 -1.3634561923936417e-08" rpy="-1.6763806343078613e-08 -1.226580934599042e-07 1.0281082625865356e-15"/>
  </joint>
  <link name="core_skeleton_joints__1_:RightShoulder"/>
  <joint name="core_skeleton_joints__1_:RightShoulder_fixed_joint" type="fixed">
    <parent link="core_skeleton_joints__1_:Spine3_custom_link_2"/>
    <child link="core_skeleton_joints__1_:RightShoulder"/>
    <axis xyz="0 1 0"/>
    <origin xyz="0.1456000655889511 0.0606999397277832 -0.025200005620718002" rpy="1.4039427042007446 2.0315632820129395 1.2219047546386719"/>
  </joint>
  <joint name="core_skeleton_joints__1_:RightShoulder_custom_joint_0" type="revolute">
    <parent link="core_skeleton_joints__1_:RightShoulder"/>
    <child link="core_skeleton_joints__1_:RightShoulder_custom_link_0"/>
    <origin xyz="0 0 0" rpy="0 0 0"/>
    <axis xyz="43.69902801513672 -89.87503051757812 3.587085247039795"/>
    <limit velocity="1000.0" effort="100.0" upper="0.4300000071525574" lower="-0.25999999046325684"/>
  </joint>
  <link name="core_skeleton_joints__1_:RightShoulder_custom_link_0">
    <inertial>
      <mass value="0.000001"/>
      <inertia ixx="0.000001" iyy="0.000001" izz="0.000001" ixy="0" ixz="0" iyz="0"/>
      <origin xyz="0 0 0" rpy="0 0 0"/>
    </inertial>
  </link>
  <joint name="core_skeleton_joints__1_:RightShoulder_custom_joint_1" type="revolute">
    <parent link="core_skeleton_joints__1_:RightShoulder_custom_link_0"/>
    <child link="core_skeleton_joints__1_:RightShoulder_custom_link_1"/>
    <origin xyz="0 0 0" rpy="0 0 0"/>
    <axis xyz="-8.209635734558105 -0.01397892739623785 99.66242980957031"/>
    <limit velocity="1000.0" effort="100.0" upper="0.4300000071525574" lower="-0.4300000071525574"/>
  </joint>
  <link name="core_skeleton_joints__1_:RightShoulder_custom_link_1">
    <inertial>
      <mass value="0.000001"/>
      <inertia ixx="0.000001" iyy="0.000001" izz="0.000001" ixy="0" ixz="0" iyz="0"/>
      <origin xyz="0 0 0" rpy="0 0 0"/>
    </inertial>
  </link>
  <link name="core_skeleton_joints__1_:RightArm"/>
  <joint name="core_skeleton_joints__1_:RightArm_fixed_joint" type="fixed">
    <parent link="core_skeleton_joints__1_:RightShoulder_custom_link_1"/>
    <child link="core_skeleton_joints__1_:RightArm"/>
    <axis xyz="0 1 0"/>
    <origin xyz="0.18010003864765167 3.738328757663112e-08 -2.5704501638301736e-08" rpy="0.017802022397518158 0.8185591697692871 0.42202046513557434"/>
  </joint>
  <joint name="core_skeleton_joints__1_:RightArm_custom_joint_0" type="spherical">
    <parent link="core_skeleton_joints__1_:RightArm"/>
    <child link="core_skeleton_joints__1_:RightArm_custom_link_0"/>
    <origin xyz="0 0 0" rpy="0 0 0"/>
    <axis xyz="6.636777106905356e-05 6.711808681488037 99.77449798583984"/>
    <limit velocity="0" effort="0" upper="0" lower="0"/>
  </joint>
  <link name="core_skeleton_joints__1_:RightArm_custom_link_0">
    <inertial>
      <mass value="0.000001"/>
      <inertia ixx="0.000001" iyy="0.000001" izz="0.000001" ixy="0" ixz="0" iyz="0"/>
      <origin xyz="0 0 0" rpy="0 0 0"/>
    </inertial>
  </link>
  <link name="core_skeleton_joints__1_:RightForeArm"/>
  <joint name="core_skeleton_joints__1_:RightForeArm_fixed_joint" type="fixed">
    <parent link="core_skeleton_joints__1_:RightArm_custom_link_0"/>
    <child link="core_skeleton_joints__1_:RightForeArm"/>
    <axis xyz="0 1 0"/>
    <origin xyz="0.30049994587898254 2.2649764730431343e-08 -1.212954430229729e-07" rpy="4.4431183710003097e-07 4.5723812291953436e-08 0.36128342151641846"/>
  </joint>
  <joint name="core_skeleton_joints__1_:RightForeArm_custom_joint_0" type="revolute">
    <parent link="core_skeleton_joints__1_:RightForeArm"/>
    <child link="core_skeleton_joints__1_:RightForeArm_custom_link_0"/>
    <origin xyz="0 0 0" rpy="0 0 0"/>
    <axis xyz="1.2518107723735739e-05 -6.711868762969971 -99.77445983886719"/>
    <limit velocity="1000.0" effort="100.0" upper="0.009999999776482582" lower="-3.140000104904175"/>
  </joint>
  <link name="core_skeleton_joints__1_:RightForeArm_custom_link_0">
    <inertial>
      <mass value="0.000001"/>
      <inertia ixx="0.000001" iyy="0.000001" izz="0.000001" ixy="0" ixz="0" iyz="0"/>
      <origin xyz="0 0 0" rpy="0 0 0"/>
    </inertial>
  </link>
  <link name="core_skeleton_joints__1_:RightHand"/>
  <joint name="core_skeleton_joints__1_:RightHand_fixed_joint" type="fixed">
    <parent link="core_skeleton_joints__1_:RightForeArm_custom_link_0"/>
    <child link="core_skeleton_joints__1_:RightHand"/>
    <axis xyz="0 1 0"/>
    <origin xyz="0.2600000202655792 -5.7220457705398076e-08 -1.6093254373572563e-07" rpy="2.8684732455985795e-07 -1.4714908047608333e-07 8.009374710127304e-07"/>
  </joint>
  <joint name="core_skeleton_joints__1_:RightHand_custom_joint_0" type="revolute">
    <parent link="core_skeleton_joints__1_:RightHand"/>
    <child link="core_skeleton_joints__1_:RightHand_custom_link_0"/>
    <origin xyz="0 0 0" rpy="0 0 0"/>
    <axis xyz="-4.8239876377920154e-06 -6.711896896362305 -99.77444458007812"/>
    <limit velocity="1000.0" effort="100.0" upper="1.5700000524520874" lower="-1.5700000524520874"/>
  </joint>
  <link name="core_skeleton_joints__1_:RightHand_custom_link_0">
    <inertial>
      <mass value="0.000001"/>
      <inertia ixx="0.000001" iyy="0.000001" izz="0.000001" ixy="0" ixz="0" iyz="0"/>
      <origin xyz="0 0 0" rpy="0 0 0"/>
    </inertial>
  </link>
  <joint name="core_skeleton_joints__1_:RightHand_custom_joint_1" type="revolute">
    <parent link="core_skeleton_joints__1_:RightHand_custom_link_0"/>
    <child link="core_skeleton_joints__1_:RightHand_custom_link_1"/>
    <origin xyz="0 0 0" rpy="0 0 0"/>
    <axis xyz="-3.3449519833084196e-05 -99.77545166015625 6.711834907531738"/>
    <limit velocity="1000.0" effort="100.0" upper="1.5700000524520874" lower="-1.5700000524520874"/>
  </joint>
  <link name="core_skeleton_joints__1_:RightHand_custom_link_1">
    <inertial>
      <mass value="0.000001"/>
      <inertia ixx="0.000001" iyy="0.000001" izz="0.000001" ixy="0" ixz="0" iyz="0"/>
      <origin xyz="0 0 0" rpy="0 0 0"/>
    </inertial>
  </link>
  <joint name="core_skeleton_joints__1_:RightHand_custom_joint_2" type="revolute">
    <parent link="core_skeleton_joints__1_:RightHand_custom_link_1"/>
    <child link="core_skeleton_joints__1_:RightHand_custom_link_2"/>
    <origin xyz="0 0 0" rpy="0 0 0"/>
    <axis xyz="-100.00080108642578 5.832659007865004e-05 1.837685522332322e-05"/>
    <limit velocity="1000.0" effort="100.0" upper="0.5" lower="-0.5"/>
  </joint>
  <link name="core_skeleton_joints__1_:RightHand_custom_link_2">
    <inertial>
      <mass value="0.000001"/>
      <inertia ixx="0.000001" iyy="0.000001" izz="0.000001" ixy="0" ixz="0" iyz="0"/>
      <origin xyz="0 0 0" rpy="0 0 0"/>
    </inertial>
  </link>
  <link name="core_skeleton_joints__1_:RightHandThumb1"/>
  <joint name="core_skeleton_joints__1_:RightHandThumb1_fixed_joint" type="fixed">
    <parent link="core_skeleton_joints__1_:RightHand_custom_link_2"/>
    <child link="core_skeleton_joints__1_:RightHandThumb1"/>
    <axis xyz="0 1 0"/>
    <origin xyz="0.006500141695141792 0.021099958568811417 -0.016400162130594254" rpy="-2.8806660175323486 0.5633928179740906 0.5799716711044312"/>
  </joint>
  <link name="core_skeleton_joints__1_:RightHandThumb2"/>
  <joint name="core_skeleton_joints__1_:RightHandThumb2_fixed_joint" type="fixed">
    <parent link="core_skeleton_joints__1_:RightHandThumb1"/>
    <child link="core_skeleton_joints__1_:RightHandThumb2"/>
    <axis xyz="0 1 0"/>
    <origin xyz="0.050700102001428604 -1.5258788721439487e-07 -2.384185648907078e-08" rpy="1.8678527169413428e-07 2.659782296632329e-07 0.16336335241794586"/>
  </joint>
  <link name="core_skeleton_joints__1_:RightHandThumb3"/>
  <joint name="core_skeleton_joints__1_:RightHandThumb3_fixed_joint" type="fixed">
    <parent link="core_skeleton_joints__1_:RightHandThumb2"/>
    <child link="core_skeleton_joints__1_:RightHandThumb3"/>
    <axis xyz="0 1 0"/>
    <origin xyz="0.034199923276901245 -8.583068478174027e-08 4.5299529460862686e-08" rpy="-1.2510734848092397e-07 -4.4738590077031404e-07 0.34156039357185364"/>
  </joint>
  <link name="core_skeleton_joints__1_:RightHandThumbEnd"/>
  <joint name="core_skeleton_joints__1_:RightHandThumbEnd_fixed_joint" type="fixed">
    <parent link="core_skeleton_joints__1_:RightHandThumb3"/>
    <child link="core_skeleton_joints__1_:RightHandThumbEnd"/>
    <axis xyz="0 1 0"/>
    <origin xyz="0.030699945986270905 9.53674295089968e-09 -4.5299529460862686e-08" rpy="1.6763806343078613e-08 9.313227522511625e-09 -1.7695130338779563e-07"/>
  </joint>
  <link name="core_skeleton_joints__1_:RightInHandIndex"/>
  <joint name="core_skeleton_joints__1_:RightInHandIndex_fixed_joint" type="fixed">
    <parent link="core_skeleton_joints__1_:RightHand_custom_link_2"/>
    <child link="core_skeleton_joints__1_:RightInHandIndex"/>
    <axis xyz="0 1 0"/>
    <origin xyz="0.015200118534266949 0.014699945226311684 -0.004100127145648003" rpy="-1.6678370237350464 0.14102286100387573 0.17784826457500458"/>
  </joint>
  <link name="core_skeleton_joints__1_:RightHandIndex1"/>
  <joint name="core_skeleton_joints__1_:RightHandIndex1_fixed_joint" type="fixed">
    <parent link="core_skeleton_joints__1_:RightInHandIndex"/>
    <child link="core_skeleton_joints__1_:RightHandIndex1"/>
    <axis xyz="0 1 0"/>
    <origin xyz="0.07499995082616806 -3.218650590497418e-08 4.768371297814156e-08" rpy="-0.16057026386260986 -0.06928928941488266 0.2970541715621948"/>
  </joint>
  <link name="core_skeleton_joints__1_:RightHandIndex2"/>
  <joint name="core_skeleton_joints__1_:RightHandIndex2_fixed_joint" type="fixed">
    <parent link="core_skeleton_joints__1_:RightHandIndex1"/>
    <child link="core_skeleton_joints__1_:RightHandIndex2"/>
    <axis xyz="0 1 0"/>
    <origin xyz="0.04819996654987335 -1.907348590179936e-08 3.814697180359872e-08" rpy="1.0149631890499222e-07 1.8574340288068925e-07 0.3454005718231201"/>
  </joint>
  <link name="core_skeleton_joints__1_:RightHandIndex3"/>
  <joint name="core_skeleton_joints__1_:RightHandIndex3_fixed_joint" type="fixed">
    <parent link="core_skeleton_joints__1_:RightHandIndex2"/>
    <child link="core_skeleton_joints__1_:RightHandIndex3"/>
    <axis xyz="0 1 0"/>
    <origin xyz="0.02350008860230446 -2.8610228852699038e-08 0.0" rpy="-1.7944034880201798e-07 -3.1871695682639256e-07 0.23596897721290588"/>
  </joint>
  <link name="core_skeleton_joints__1_:RightHandIndexEnd"/>
  <joint name="core_skeleton_joints__1_:RightHandIndexEnd_fixed_joint" type="fixed">
    <parent link="core_skeleton_joints__1_:RightHandIndex3"/>
    <child link="core_skeleton_joints__1_:RightHandIndexEnd"/>
    <axis xyz="0 1 0"/>
    <origin xyz="0.022199882194399834 6.67572024326546e-08 -4.768371297814156e-08" rpy="-5.587935003603661e-09 -2.9802322387695312e-08 -2.2351741790771484e-08"/>
  </joint>
  <link name="core_skeleton_joints__1_:RightInHandMiddle"/>
  <joint name="core_skeleton_joints__1_:RightInHandMiddle_fixed_joint" type="fixed">
    <parent link="core_skeleton_joints__1_:RightHand_custom_link_2"/>
    <child link="core_skeleton_joints__1_:RightInHandMiddle"/>
    <axis xyz="0 1 0"/>
    <origin xyz="0.01880006119608879 0.0007999705849215388 0.003099872963503003" rpy="-1.6838939189910889 0.17750044167041779 0.08045877516269684"/>
  </joint>
  <link name="core_skeleton_joints__1_:RightHandMiddle1"/>
  <joint name="core_skeleton_joints__1_:RightHandMiddle1_fixed_joint" type="fixed">
    <parent link="core_skeleton_joints__1_:RightInHandMiddle"/>
    <child link="core_skeleton_joints__1_:RightHandMiddle1"/>
    <axis xyz="0 1 0"/>
    <origin xyz="0.07789996266365051 7.1525572131747595e-09 2.8610228852699038e-08" rpy="0.11484226584434509 0.005585278384387493 0.30962038040161133"/>
  </joint>
  <link name="core_skeleton_joints__1_:RightHandMiddle2"/>
  <joint name="core_skeleton_joints__1_:RightHandMiddle2_fixed_joint" type="fixed">
    <parent link="core_skeleton_joints__1_:RightHandMiddle1"/>
    <child link="core_skeleton_joints__1_:RightHandMiddle2"/>
    <axis xyz="0 1 0"/>
    <origin xyz="0.04880008101463318 2.1100044023114606e-07 -4.768371297814156e-08" rpy="3.7354269011302677e-07 -3.988409957855765e-08 0.4262104630470276"/>
  </joint>
  <link name="core_skeleton_joints__1_:RightHandMiddle3"/>
  <joint name="core_skeleton_joints__1_:RightHandMiddle3_fixed_joint" type="fixed">
    <parent link="core_skeleton_joints__1_:RightHandMiddle2"/>
    <child link="core_skeleton_joints__1_:RightHandMiddle3"/>
    <axis xyz="0 1 0"/>
    <origin xyz="0.02900022454559803 3.814697180359872e-08 5.7220457705398076e-08" rpy="8.090985659237049e-08 3.4361679013272806e-07 0.22828839719295502"/>
  </joint>
  <link name="core_skeleton_joints__1_:RightHandMiddleEnd"/>
  <joint name="core_skeleton_joints__1_:RightHandMiddleEnd_fixed_joint" type="fixed">
    <parent link="core_skeleton_joints__1_:RightHandMiddle3"/>
    <child link="core_skeleton_joints__1_:RightHandMiddleEnd"/>
    <axis xyz="0 1 0"/>
    <origin xyz="0.023799924179911613 2.384185648907078e-08 9.53674295089968e-09" rpy="3.725290298461914e-08 -1.1175870895385742e-08 7.450580596923828e-09"/>
  </joint>
  <link name="core_skeleton_joints__1_:RightInHandRing"/>
  <joint name="core_skeleton_joints__1_:RightInHandRing_fixed_joint" type="fixed">
    <parent link="core_skeleton_joints__1_:RightHand_custom_link_2"/>
    <child link="core_skeleton_joints__1_:RightInHandRing"/>
    <axis xyz="0 1 0"/>
    <origin xyz="0.01900012232363224 -0.012500032782554626 0.003499924438074231" rpy="-1.670454978942871 0.20472677052021027 0.008376788347959518"/>
  </joint>
  <link name="core_skeleton_joints__1_:RightHandRing1"/>
  <joint name="core_skeleton_joints__1_:RightHandRing1_fixed_joint" type="fixed">
    <parent link="core_skeleton_joints__1_:RightInHandRing"/>
    <child link="core_skeleton_joints__1_:RightHandRing1"/>
    <axis xyz="0 1 0"/>
    <origin xyz="0.07429998368024826 8.583068478174027e-08 9.53674295089968e-09" rpy="0.18046724796295166 0.05881776660680771 0.34592482447624207"/>
  </joint>
  <link name="core_skeleton_joints__1_:RightHandRing2"/>
  <joint name="core_skeleton_joints__1_:RightHandRing2_fixed_joint" type="fixed">
    <parent link="core_skeleton_joints__1_:RightHandRing1"/>
    <child link="core_skeleton_joints__1_:RightHandRing2"/>
    <axis xyz="0 1 0"/>
    <origin xyz="0.04550010710954666 3.7550925924279e-08 -2.384185648907078e-08" rpy="-3.3624468187554157e-07 -1.9100189874166063e-08 0.38466987013816833"/>
  </joint>
  <link name="core_skeleton_joints__1_:RightHandRing3"/>
  <joint name="core_skeleton_joints__1_:RightHandRing3_fixed_joint" type="fixed">
    <parent link="core_skeleton_joints__1_:RightHandRing2"/>
    <child link="core_skeleton_joints__1_:RightHandRing3"/>
    <axis xyz="0 1 0"/>
    <origin xyz="0.026700064539909363 -8.344650304081824e-09 4.76837147544984e-09" rpy="3.7127662722014065e-07 -1.1833585489284815e-07 0.15271808207035065"/>
  </joint>
  <link name="core_skeleton_joints__1_:RightHandRingEnd"/>
  <joint name="core_skeleton_joints__1_:RightHandRingEnd_fixed_joint" type="fixed">
    <parent link="core_skeleton_joints__1_:RightHandRing3"/>
    <child link="core_skeleton_joints__1_:RightHandRingEnd"/>
    <axis xyz="0 1 0"/>
    <origin xyz="0.024399979040026665 -3.099441414633475e-08 -4.76837147544984e-09" rpy="-4.0978196835794733e-08 -4.0978193283081055e-08 1.0617079482244662e-07"/>
  </joint>
  <link name="core_skeleton_joints__1_:RightInHandPinky"/>
  <joint name="core_skeleton_joints__1_:RightInHandPinky_fixed_joint" type="fixed">
    <parent link="core_skeleton_joints__1_:RightHand_custom_link_2"/>
    <child link="core_skeleton_joints__1_:RightInHandPinky"/>
    <axis xyz="0 1 0"/>
    <origin xyz="0.017200062051415443 -0.025200022384524345 -0.0006001031142659485" rpy="-1.66120445728302 0.15952332317829132 -0.13508950173854828"/>
  </joint>
  <link name="core_skeleton_joints__1_:RightHandPinky1"/>
  <joint name="core_skeleton_joints__1_:RightHandPinky1_fixed_joint" type="fixed">
    <parent link="core_skeleton_joints__1_:RightInHandPinky"/>
    <child link="core_skeleton_joints__1_:RightHandPinky1"/>
    <axis xyz="0 1 0"/>
    <origin xyz="0.06689998507499695 -3.9041040622578294e-08 9.53674295089968e-09" rpy="0.24277520179748535 -0.010646010749042034 0.44645434617996216"/>
  </joint>
  <link name="core_skeleton_joints__1_:RightHandPinky2"/>
  <joint name="core_skeleton_joints__1_:RightHandPinky2_fixed_joint" type="fixed">
    <parent link="core_skeleton_joints__1_:RightHandPinky1"/>
    <child link="core_skeleton_joints__1_:RightHandPinky2"/>
    <axis xyz="0 1 0"/>
    <origin xyz="0.039000004529953 9.53674295089968e-09 1.907348590179936e-08" rpy="2.6443899514561053e-07 2.1137187999897833e-08 0.29513663053512573"/>
  </joint>
  <link name="core_skeleton_joints__1_:RightHandPinky3"/>
  <joint name="core_skeleton_joints__1_:RightHandPinky3_fixed_joint" type="fixed">
    <parent link="core_skeleton_joints__1_:RightHandPinky2"/>
    <child link="core_skeleton_joints__1_:RightHandPinky3"/>
    <axis xyz="0 1 0"/>
    <origin xyz="0.02149997651576996 2.9057263262188826e-08 4.291534239087014e-08" rpy="-2.5055030050680216e-07 -8.718454580503021e-08 0.17243865132331848"/>
  </joint>
  <link name="core_skeleton_joints__1_:RightHandPinkyEnd"/>
  <joint name="core_skeleton_joints__1_:RightHandPinkyEnd_fixed_joint" type="fixed">
    <parent link="core_skeleton_joints__1_:RightHandPinky3"/>
    <child link="core_skeleton_joints__1_:RightHandPinkyEnd"/>
    <axis xyz="0 1 0"/>
    <origin xyz="0.020199855789542198 2.7418135317702763e-08 1.192092824453539e-08" rpy="1.0244550097127103e-08 -7.450580152834618e-09 -1.2945383787155151e-07"/>
  </joint>
  <link name="core_skeleton_joints__1_:Right_sb_foreArmTwist_001"/>
  <joint name="core_skeleton_joints__1_:Right_sb_foreArmTwist_001_fixed_joint" type="fixed">
    <parent link="core_skeleton_joints__1_:RightForeArm_custom_link_0"/>
    <child link="core_skeleton_joints__1_:Right_sb_foreArmTwist_001"/>
    <axis xyz="0 1 0"/>
    <origin xyz="9.47713800769634e-08 -2.324581060975106e-08 -1.566857008583611e-07" rpy="1.862645149230957e-08 -4.284084198502569e-08 1.1920930376163597e-07"/>
  </joint>
  <link name="core_skeleton_joints__1_:Right_sb_foreArmTwist_002"/>
  <joint name="core_skeleton_joints__1_:Right_sb_foreArmTwist_002_fixed_joint" type="fixed">
    <parent link="core_skeleton_joints__1_:RightForeArm_custom_link_0"/>
    <child link="core_skeleton_joints__1_:Right_sb_foreArmTwist_002"/>
    <axis xyz="0 1 0"/>
    <origin xyz="0.08670004457235336 -2.145767119543507e-08 -1.1458993043333976e-07" rpy="-2.5145712356788863e-07 -9.033829684312877e-08 7.450582728552035e-08"/>
  </joint>
  <link name="core_skeleton_joints__1_:Right_sb_foreArmTwist_003"/>
  <joint name="core_skeleton_joints__1_:Right_sb_foreArmTwist_003_fixed_joint" type="fixed">
    <parent link="core_skeleton_joints__1_:RightForeArm_custom_link_0"/>
    <child link="core_skeleton_joints__1_:Right_sb_foreArmTwist_003"/>
    <axis xyz="0 1 0"/>
    <origin xyz="0.17329998314380646 -1.907348590179936e-08 -1.8388033140581683e-07" rpy="-2.1606686573250045e-07 -1.9837173681480635e-07 2.607705695822915e-08"/>
  </joint>
  <link name="core_skeleton_joints__1_:Right_sb_armTwist_001"/>
  <joint name="core_skeleton_joints__1_:Right_sb_armTwist_001_fixed_joint" type="fixed">
    <parent link="core_skeleton_joints__1_:RightArm_custom_link_0"/>
    <child link="core_skeleton_joints__1_:Right_sb_armTwist_001"/>
    <axis xyz="0 1 0"/>
    <origin xyz="-9.499955666569804e-08 -5.364417798858767e-09 -9.216368113129647e-08" rpy="2.8870999813079834e-08 4.6900822781026363e-08 2.328307102672511e-09"/>
  </joint>
  <link name="core_skeleton_joints__1_:Right_sb_armTwist_002"/>
  <joint name="core_skeleton_joints__1_:Right_sb_armTwist_002_fixed_joint" type="fixed">
    <parent link="core_skeleton_joints__1_:RightArm_custom_link_0"/>
    <child link="core_skeleton_joints__1_:Right_sb_armTwist_002"/>
    <axis xyz="0 1 0"/>
    <origin xyz="0.10019991546869278 1.1324882365215672e-08 -1.1399387744859268e-07" rpy="5.21540641784668e-08 4.6842615120112896e-08 2.328307768806326e-09"/>
  </joint>
  <link name="core_skeleton_joints__1_:Right_sb_armTwist_003"/>
  <joint name="core_skeleton_joints__1_:Right_sb_armTwist_003_fixed_joint" type="fixed">
    <parent link="core_skeleton_joints__1_:RightArm_custom_link_0"/>
    <child link="core_skeleton_joints__1_:Right_sb_armTwist_003"/>
    <axis xyz="0 1 0"/>
    <origin xyz="0.20030002295970917 1.4901161193847656e-08 -1.7661601248164516e-07" rpy="5.21540641784668e-08 4.6842615120112896e-08 2.328307768806326e-09"/>
  </joint>
  <link name="core_skeleton_joints__1_:LeftUpLeg"/>
  <joint name="core_skeleton_joints__1_:LeftUpLeg_fixed_joint" type="fixed">
    <parent link="core_skeleton_joints__1_:Hips_floating_link"/>
    <child link="core_skeleton_joints__1_:LeftUpLeg"/>
    <axis xyz="0 1 0"/>
    <origin xyz="0.0 -1.9339584156341516e-08 0.10300000011920929" rpy="-0.067195363342762 -0.0684124305844307 -3.095167636871338"/>
  </joint>
  <joint name="core_skeleton_joints__1_:LeftUpLeg_custom_joint_0" type="spherical">
    <parent link="core_skeleton_joints__1_:LeftUpLeg"/>
    <child link="core_skeleton_joints__1_:LeftUpLeg_custom_link_0"/>
    <origin xyz="0 0 0" rpy="0 0 0"/>
    <axis xyz="-100.0002670288086 -7.636251393705606e-05 -0.0009196726605296135"/>
    <limit velocity="0" effort="0" upper="0" lower="0"/>
  </joint>
  <link name="core_skeleton_joints__1_:LeftUpLeg_custom_link_0">
    <inertial>
      <mass value="0.000001"/>
      <inertia ixx="0.000001" iyy="0.000001" izz="0.000001" ixy="0" ixz="0" iyz="0"/>
      <origin xyz="0 0 0" rpy="0 0 0"/>
    </inertial>
  </link>
  <link name="core_skeleton_joints__1_:LeftLeg"/>
  <joint name="core_skeleton_joints__1_:LeftLeg_fixed_joint" type="fixed">
    <parent link="core_skeleton_joints__1_:LeftUpLeg_custom_link_0"/>
    <child link="core_skeleton_joints__1_:LeftLeg"/>
    <axis xyz="0 1 0"/>
    <origin xyz="0.43849867582321167 2.3335218202191754e-07 3.926791123376461e-06" rpy="-1.5941311914957623e-07 -9.663799716008725e-08 0.017453303560614586"/>
  </joint>
  <joint name="core_skeleton_joints__1_:LeftLeg_custom_joint_0" type="revolute">
    <parent link="core_skeleton_joints__1_:LeftLeg"/>
    <child link="core_skeleton_joints__1_:LeftLeg_custom_link_0"/>
    <origin xyz="0 0 0" rpy="0 0 0"/>
    <axis xyz="4.629358954844065e-05 -6.555897235870361 99.7837142944336"/>
    <limit velocity="1000.0" effort="100.0" upper="3.140000104904175" lower="0.009999999776482582"/>
  </joint>
  <link name="core_skeleton_joints__1_:LeftLeg_custom_link_0">
    <inertial>
      <mass value="0.000001"/>
      <inertia ixx="0.000001" iyy="0.000001" izz="0.000001" ixy="0" ixz="0" iyz="0"/>
      <origin xyz="0 0 0" rpy="0 0 0"/>
    </inertial>
  </link>
  <link name="core_skeleton_joints__1_:LeftFoot"/>
  <joint name="core_skeleton_joints__1_:LeftFoot_fixed_joint" type="fixed">
    <parent link="core_skeleton_joints__1_:LeftLeg_custom_link_0"/>
    <child link="core_skeleton_joints__1_:LeftFoot"/>
    <axis xyz="0 1 0"/>
    <origin xyz="0.4279989004135132 2.1100044023114606e-07 3.816932348854607e-06" rpy="-0.05322395637631416 0.019897248595952988 -1.2346442937850952"/>
  </joint>
  <joint name="core_skeleton_joints__1_:LeftFoot_custom_joint_0" type="revolute">
    <parent link="core_skeleton_joints__1_:LeftFoot"/>
    <child link="core_skeleton_joints__1_:LeftFoot_custom_link_0"/>
    <origin xyz="0 0 0" rpy="0 0 0"/>
    <axis xyz="32.97919845581055 94.23486328125 5.678391456604004"/>
    <limit velocity="1000.0" effort="100.0" upper="1.25" lower="-1.25"/>
  </joint>
  <link name="core_skeleton_joints__1_:LeftFoot_custom_link_0">
    <inertial>
      <mass value="0.000001"/>
      <inertia ixx="0.000001" iyy="0.000001" izz="0.000001" ixy="0" ixz="0" iyz="0"/>
      <origin xyz="0 0 0" rpy="0 0 0"/>
    </inertial>
  </link>
  <joint name="core_skeleton_joints__1_:LeftFoot_custom_joint_1" type="revolute">
    <parent link="core_skeleton_joints__1_:LeftFoot_custom_link_0"/>
    <child link="core_skeleton_joints__1_:LeftFoot_custom_link_1"/>
    <origin xyz="0 0 0" rpy="0 0 0"/>
    <axis xyz="-94.31201934814453 32.61914825439453 6.424679756164551"/>
    <limit velocity="1000.0" effort="100.0" upper="0.3499999940395355" lower="-0.3499999940395355"/>
  </joint>
  <link name="core_skeleton_joints__1_:LeftFoot_custom_link_1">
    <inertial>
      <mass value="0.000001"/>
      <inertia ixx="0.000001" iyy="0.000001" izz="0.000001" ixy="0" ixz="0" iyz="0"/>
      <origin xyz="0 0 0" rpy="0 0 0"/>
    </inertial>
  </link>
  <joint name="core_skeleton_joints__1_:LeftFoot_custom_joint_2" type="revolute">
    <parent link="core_skeleton_joints__1_:LeftFoot_custom_link_1"/>
    <child link="core_skeleton_joints__1_:LeftFoot_custom_link_2"/>
    <origin xyz="0 0 0" rpy="0 0 0"/>
    <axis xyz="4.202469825744629 -7.473278045654297 99.63060760498047"/>
    <limit velocity="1000.0" effort="100.0" upper="0.3499999940395355" lower="-0.3499999940395355"/>
  </joint>
  <link name="core_skeleton_joints__1_:LeftFoot_custom_link_2">
    <inertial>
      <mass value="0.000001"/>
      <inertia ixx="0.000001" iyy="0.000001" izz="0.000001" ixy="0" ixz="0" iyz="0"/>
      <origin xyz="0 0 0" rpy="0 0 0"/>
    </inertial>
  </link>
  <link name="core_skeleton_joints__1_:LeftToeBase"/>
  <joint name="core_skeleton_joints__1_:LeftToeBase_fixed_joint" type="fixed">
    <parent link="core_skeleton_joints__1_:LeftFoot_custom_link_2"/>
    <child link="core_skeleton_joints__1_:LeftToeBase"/>
    <axis xyz="0 1 0"/>
    <origin xyz="0.12259992957115173 -3.1247734000316996e-07 4.1183082544193894e-07" rpy="1.0303938324796036e-06 -4.815519332623808e-06 -0.3324863314628601"/>
  </joint>
  <joint name="core_skeleton_joints__1_:LeftToeBase_custom_joint_0" type="revolute">
    <parent link="core_skeleton_joints__1_:LeftToeBase"/>
    <child link="core_skeleton_joints__1_:LeftToeBase_custom_link_0"/>
    <origin xyz="0 0 0" rpy="0 0 0"/>
    <axis xyz="6.412029266357422 -5.692229747772217 99.63058471679688"/>
    <limit velocity="1000.0" effort="100.0" upper="0.0010000000474974513" lower="-0.30000001192092896"/>
  </joint>
  <link name="core_skeleton_joints__1_:LeftToeBase_custom_link_0">
    <inertial>
      <mass value="0.000001"/>
      <inertia ixx="0.000001" iyy="0.000001" izz="0.000001" ixy="0" ixz="0" iyz="0"/>
      <origin xyz="0 0 0" rpy="0 0 0"/>
    </inertial>
  </link>
  <link name="core_skeleton_joints__1_:LeftFootEnd"/>
  <joint name="core_skeleton_joints__1_:LeftFootEnd_fixed_joint" type="fixed">
    <parent link="core_skeleton_joints__1_:LeftToeBase_custom_link_0"/>
    <child link="core_skeleton_joints__1_:LeftFootEnd"/>
    <axis xyz="0 1 0"/>
    <origin xyz="0.0762999951839447 -3.993510944155787e-08 -1.3230368267613812e-07" rpy="1.5366822481155396e-08 -2.6193442970168235e-09 -5.6694261729717255e-08"/>
  </joint>
  <link name="core_skeleton_joints__1_:Left_sb_legTwist_001"/>
  <joint name="core_skeleton_joints__1_:Left_sb_legTwist_001_fixed_joint" type="fixed">
    <parent link="core_skeleton_joints__1_:LeftLeg_custom_link_0"/>
    <child link="core_skeleton_joints__1_:Left_sb_legTwist_001"/>
    <axis xyz="0 1 0"/>
    <origin xyz="-1.3411044497146918e-09 5.9604643443123e-10 2.514570951461792e-08" rpy="-4.8894426285528425e-09 -1.862645371275562e-09 3.702007234096527e-08"/>
  </joint>
  <link name="core_skeleton_joints__1_:Left_sb_legTwist_002"/>
  <joint name="core_skeleton_joints__1_:Left_sb_legTwist_002_fixed_joint" type="fixed">
    <parent link="core_skeleton_joints__1_:LeftLeg_custom_link_0"/>
    <child link="core_skeleton_joints__1_:Left_sb_legTwist_002"/>
    <axis xyz="0 1 0"/>
    <origin xyz="0.14269967377185822 7.480382890889814e-08 1.293420723413874e-06" rpy="1.88592803596066e-08 3.4458935260772705e-08 4.516914131613703e-08"/>
  </joint>
  <link name="core_skeleton_joints__1_:Left_sb_legTwist_003"/>
  <joint name="core_skeleton_joints__1_:Left_sb_legTwist_003_fixed_joint" type="fixed">
    <parent link="core_skeleton_joints__1_:LeftLeg_custom_link_0"/>
    <child link="core_skeleton_joints__1_:Left_sb_legTwist_003"/>
    <axis xyz="0 1 0"/>
    <origin xyz="0.28529927134513855 1.335144048653092e-07 2.5562942482793005e-06" rpy="1.7229465854029513e-08 3.585591912269592e-08 4.656615648634954e-10"/>
  </joint>
  <link name="core_skeleton_joints__1_:Left_sb_upLegTwist_001"/>
  <joint name="core_skeleton_joints__1_:Left_sb_upLegTwist_001_fixed_joint" type="fixed">
    <parent link="core_skeleton_joints__1_:LeftUpLeg_custom_link_0"/>
    <child link="core_skeleton_joints__1_:Left_sb_upLegTwist_001"/>
    <axis xyz="0 1 0"/>
    <origin xyz="-1.0192393773422737e-07 2.2947787670091202e-08 6.407498975846693e-09" rpy="3.026798811589515e-09 -2.5494957256455564e-08 -6.984919309616089e-10"/>
  </joint>
  <link name="core_skeleton_joints__1_:Left_sb_upLegTwist_002"/>
  <joint name="core_skeleton_joints__1_:Left_sb_upLegTwist_002_fixed_joint" type="fixed">
    <parent link="core_skeleton_joints__1_:LeftUpLeg_custom_link_0"/>
    <child link="core_skeleton_joints__1_:Left_sb_upLegTwist_002"/>
    <axis xyz="0 1 0"/>
    <origin xyz="0.14619944989681244 1.0341405953795402e-07 1.3057887144896085e-06" rpy="-1.7811546015877866e-08 -3.3993273973464966e-08 4.6333301639833735e-08"/>
  </joint>
  <link name="core_skeleton_joints__1_:Left_sb_upLegTwist_003"/>
  <joint name="core_skeleton_joints__1_:Left_sb_upLegTwist_003_fixed_joint" type="fixed">
    <parent link="core_skeleton_joints__1_:LeftUpLeg_custom_link_0"/>
    <child link="core_skeleton_joints__1_:Left_sb_upLegTwist_003"/>
    <axis xyz="0 1 0"/>
    <origin xyz="0.2922991216182709 1.5527010077676096e-07 2.617985046526883e-06" rpy="-2.689194467109246e-08 -3.236345946788788e-08 1.862645815364772e-09"/>
  </joint>
  <link name="core_skeleton_joints__1_:RightUpLeg"/>
  <joint name="core_skeleton_joints__1_:RightUpLeg_fixed_joint" type="fixed">
    <parent link="core_skeleton_joints__1_:Hips_floating_link"/>
    <child link="core_skeleton_joints__1_:RightUpLeg"/>
    <axis xyz="0 1 0"/>
    <origin xyz="0.0 -9.270645584535941e-09 -0.10300000011920929" rpy="0.0671953484416008 0.06841256469488144 -3.095167636871338"/>
  </joint>
  <joint name="core_skeleton_joints__1_:RightUpLeg_custom_joint_0" type="spherical">
    <parent link="core_skeleton_joints__1_:RightUpLeg"/>
    <child link="core_skeleton_joints__1_:RightUpLeg_custom_link_0"/>
    <origin xyz="0 0 0" rpy="0 0 0"/>
    <axis xyz="-100.00041961669922 -8.366491238120943e-05 0.0008887969306670129"/>
    <limit velocity="0" effort="0" upper="0" lower="0"/>
  </joint>
  <link name="core_skeleton_joints__1_:RightUpLeg_custom_link_0">
    <inertial>
      <mass value="0.000001"/>
      <inertia ixx="0.000001" iyy="0.000001" izz="0.000001" ixy="0" ixz="0" iyz="0"/>
      <origin xyz="0 0 0" rpy="0 0 0"/>
    </inertial>
  </link>
  <link name="core_skeleton_joints__1_:RightLeg"/>
  <joint name="core_skeleton_joints__1_:RightLeg_fixed_joint" type="fixed">
    <parent link="core_skeleton_joints__1_:RightUpLeg_custom_link_0"/>
    <child link="core_skeleton_joints__1_:RightLeg"/>
    <axis xyz="0 1 0"/>
    <origin xyz="0.43849870562553406 2.6851893153434503e-07 -3.830417881545145e-06" rpy="1.878495510254652e-07 -1.401841274173421e-07 0.017453307285904884"/>
  </joint>
  <joint name="core_skeleton_joints__1_:RightLeg_custom_joint_0" type="revolute">
    <parent link="core_skeleton_joints__1_:RightLeg"/>
    <child link="core_skeleton_joints__1_:RightLeg_custom_link_0"/>
    <origin xyz="0 0 0" rpy="0 0 0"/>
    <axis xyz="-5.707232776330784e-05 6.555886745452881 99.783935546875"/>
    <limit velocity="1000.0" effort="100.0" upper="3.140000104904175" lower="0.009999999776482582"/>
  </joint>
  <link name="core_skeleton_joints__1_:RightLeg_custom_link_0">
    <inertial>
      <mass value="0.000001"/>
      <inertia ixx="0.000001" iyy="0.000001" izz="0.000001" ixy="0" ixz="0" iyz="0"/>
      <origin xyz="0 0 0" rpy="0 0 0"/>
    </inertial>
  </link>
  <link name="core_skeleton_joints__1_:RightFoot"/>
  <joint name="core_skeleton_joints__1_:RightFoot_fixed_joint" type="fixed">
    <parent link="core_skeleton_joints__1_:RightLeg_custom_link_0"/>
    <child link="core_skeleton_joints__1_:RightFoot"/>
    <axis xyz="0 1 0"/>
    <origin xyz="0.427998811006546 2.1040439435182634e-07 -3.795027623709757e-06" rpy="0.05322389677166939 -0.019897574558854103 -1.2346444129943848"/>
  </joint>
  <joint name="core_skeleton_joints__1_:RightFoot_custom_joint_0" type="revolute">
    <parent link="core_skeleton_joints__1_:RightFoot"/>
    <child link="core_skeleton_joints__1_:RightFoot_custom_link_0"/>
    <origin xyz="0 0 0" rpy="0 0 0"/>
    <axis xyz="-32.97920227050781 -94.23494720458984 5.6783881187438965"/>
    <limit velocity="1000.0" effort="100.0" upper="1.25" lower="-1.25"/>
  </joint>
  <link name="core_skeleton_joints__1_:RightFoot_custom_link_0">
    <inertial>
      <mass value="0.000001"/>
      <inertia ixx="0.000001" iyy="0.000001" izz="0.000001" ixy="0" ixz="0" iyz="0"/>
      <origin xyz="0 0 0" rpy="0 0 0"/>
    </inertial>
  </link>
  <joint name="core_skeleton_joints__1_:RightFoot_custom_joint_1" type="revolute">
    <parent link="core_skeleton_joints__1_:RightFoot_custom_link_0"/>
    <child link="core_skeleton_joints__1_:RightFoot_custom_link_1"/>
    <origin xyz="0 0 0" rpy="0 0 0"/>
    <axis xyz="-94.3119888305664 32.61912536621094 -6.424656867980957"/>
    <limit velocity="1000.0" effort="100.0" upper="0.3499999940395355" lower="-0.3499999940395355"/>
  </joint>
  <link name="core_skeleton_joints__1_:RightFoot_custom_link_1">
    <inertial>
      <mass value="0.000001"/>
      <inertia ixx="0.000001" iyy="0.000001" izz="0.000001" ixy="0" ixz="0" iyz="0"/>
      <origin xyz="0 0 0" rpy="0 0 0"/>
    </inertial>
  </link>
  <joint name="core_skeleton_joints__1_:RightFoot_custom_joint_2" type="revolute">
    <parent link="core_skeleton_joints__1_:RightFoot_custom_link_1"/>
    <child link="core_skeleton_joints__1_:RightFoot_custom_link_2"/>
    <origin xyz="0 0 0" rpy="0 0 0"/>
    <axis xyz="-4.202426910400391 7.473270416259766 99.63085174560547"/>
    <limit velocity="1000.0" effort="100.0" upper="0.3499999940395355" lower="-0.3499999940395355"/>
  </joint>
  <link name="core_skeleton_joints__1_:RightFoot_custom_link_2">
    <inertial>
      <mass value="0.000001"/>
      <inertia ixx="0.000001" iyy="0.000001" izz="0.000001" ixy="0" ixz="0" iyz="0"/>
      <origin xyz="0 0 0" rpy="0 0 0"/>
    </inertial>
  </link>
  <link name="core_skeleton_joints__1_:RightToeBase"/>
  <joint name="core_skeleton_joints__1_:RightToeBase_fixed_joint" type="fixed">
    <parent link="core_skeleton_joints__1_:RightFoot_custom_link_2"/>
    <child link="core_skeleton_joints__1_:RightToeBase"/>
    <axis xyz="0 1 0"/>
    <origin xyz="0.12259994447231293 -3.066658962325164e-07 -4.6383587459786213e-07" rpy="-1.202704083880235e-06 2.234365410913597e-06 -0.3324861228466034"/>
  </joint>
  <joint name="core_skeleton_joints__1_:RightToeBase_custom_joint_0" type="revolute">
    <parent link="core_skeleton_joints__1_:RightToeBase"/>
    <child link="core_skeleton_joints__1_:RightToeBase_custom_link_0"/>
    <origin xyz="0 0 0" rpy="0 0 0"/>
    <axis xyz="-6.411728858947754 5.6922197341918945 99.63082122802734"/>
    <limit velocity="1000.0" effort="100.0" upper="0.0010000000474974513" lower="-0.30000001192092896"/>
  </joint>
  <link name="core_skeleton_joints__1_:RightToeBase_custom_link_0">
    <inertial>
      <mass value="0.000001"/>
      <inertia ixx="0.000001" iyy="0.000001" izz="0.000001" ixy="0" ixz="0" iyz="0"/>
      <origin xyz="0 0 0" rpy="0 0 0"/>
    </inertial>
  </link>
  <link name="core_skeleton_joints__1_:RightFootEnd"/>
  <joint name="core_skeleton_joints__1_:RightFootEnd_fixed_joint" type="fixed">
    <parent link="core_skeleton_joints__1_:RightToeBase_custom_link_0"/>
    <child link="core_skeleton_joints__1_:RightFootEnd"/>
    <axis xyz="0 1 0"/>
    <origin xyz="0.0763000100851059 -5.155801829914708e-08 -1.3645738761169923e-07" rpy="2.3515895009040833e-08 3.783498403464591e-09 -5.57629356023881e-08"/>
  </joint>
  <link name="core_skeleton_joints__1_:Right_sb_legTwist_001"/>
  <joint name="core_skeleton_joints__1_:Right_sb_legTwist_001_fixed_joint" type="fixed">
    <parent link="core_skeleton_joints__1_:RightLeg_custom_link_0"/>
    <child link="core_skeleton_joints__1_:Right_sb_legTwist_001"/>
    <axis xyz="0 1 0"/>
    <origin xyz="-1.9036232146163456e-08 -5.9604643443123e-10 -1.4342367293807001e-08" rpy="-6.752089110051429e-09 -4.423782229423523e-09 3.9115551686563776e-08"/>
  </joint>
  <link name="core_skeleton_joints__1_:Right_sb_legTwist_002"/>
  <joint name="core_skeleton_joints__1_:Right_sb_legTwist_002_fixed_joint" type="fixed">
    <parent link="core_skeleton_joints__1_:RightLeg_custom_link_0"/>
    <child link="core_skeleton_joints__1_:Right_sb_legTwist_002"/>
    <axis xyz="0 1 0"/>
    <origin xyz="0.14269961416721344 7.271766833127913e-08 -1.2579932899825508e-06" rpy="-3.795139491558075e-08 -3.306195139884949e-08 4.819595389449205e-08"/>
  </joint>
  <link name="core_skeleton_joints__1_:Right_sb_legTwist_003"/>
  <joint name="core_skeleton_joints__1_:Right_sb_legTwist_003_fixed_joint" type="fixed">
    <parent link="core_skeleton_joints__1_:RightLeg_custom_link_0"/>
    <child link="core_skeleton_joints__1_:Right_sb_legTwist_003"/>
    <axis xyz="0 1 0"/>
    <origin xyz="0.2852992117404938 1.50203703697116e-07 -2.5285035007982515e-06" rpy="-4.0046870708465576e-08 -3.4458935260772705e-08 5.122275492652761e-09"/>
  </joint>
  <link name="core_skeleton_joints__1_:Right_sb_upLegTwist_001"/>
  <joint name="core_skeleton_joints__1_:Right_sb_upLegTwist_001_fixed_joint" type="fixed">
    <parent link="core_skeleton_joints__1_:RightUpLeg_custom_link_0"/>
    <child link="core_skeleton_joints__1_:Right_sb_upLegTwist_001"/>
    <axis xyz="0 1 0"/>
    <origin xyz="-1.2069940602543738e-08 5.871057240369737e-08 -1.0430812658057675e-08" rpy="1.0826626706261777e-08 2.9685908842225217e-08 1.257285564548738e-08"/>
  </joint>
  <link name="core_skeleton_joints__1_:Right_sb_upLegTwist_002"/>
  <joint name="core_skeleton_joints__1_:Right_sb_upLegTwist_002_fixed_joint" type="fixed">
    <parent link="core_skeleton_joints__1_:RightUpLeg_custom_link_0"/>
    <child link="core_skeleton_joints__1_:Right_sb_upLegTwist_002"/>
    <axis xyz="0 1 0"/>
    <origin xyz="0.1461995393037796 1.1473893835045601e-07 -1.27419821183139e-06" rpy="3.410969284800558e-08 4.016328958300619e-08 1.862645815364772e-09"/>
  </joint>
  <link name="core_skeleton_joints__1_:Right_sb_upLegTwist_003"/>
  <joint name="core_skeleton_joints__1_:Right_sb_upLegTwist_003_fixed_joint" type="fixed">
    <parent link="core_skeleton_joints__1_:RightUpLeg_custom_link_0"/>
    <child link="core_skeleton_joints__1_:Right_sb_upLegTwist_003"/>
    <axis xyz="0 1 0"/>
    <origin xyz="0.29229915142059326 2.095103184274194e-07 -2.5546551114530303e-06" rpy="2.6542698705611656e-08 4.0279704904833125e-08 3.4924600988972543e-09"/>
  </joint>
  <link name="core_skeleton_joints__1_:Trajectory"/>
  <joint name="core_skeleton_joints__1_:Trajectory_fixed_joint" type="fixed">
    <parent link="BASE"/>
    <child link="core_skeleton_joints__1_:Trajectory"/>
    <axis xyz="0 1 0"/>
    <origin xyz="0.0 0.0 0.0" rpy="1.570796251296997 -7.549789415861596e-08 -1.5707963705062866"/>
  </joint>
  <link name="core_skeleton_joints__1_:TrajectoryEnd"/>
  <joint name="core_skeleton_joints__1_:TrajectoryEnd_fixed_joint" type="fixed">
    <parent link="core_skeleton_joints__1_:Trajectory"/>
    <child link="core_skeleton_joints__1_:TrajectoryEnd"/>
    <axis xyz="0 1 0"/>
    <origin xyz="0.11999999731779099 -1.907348590179936e-08 0.0" rpy="-0.0 1.570796251296997 0.0"/>
  </joint>
</robot>
