<?xml version="1.0"?>
<robot name="MoveAI">
    <link name="BASE">
        <inertial>
            <origin xyz="0 0 0" rpy="0 0 0" />
            <mass value="0.000001" />
            <inertia iyz="0" ixy="0" izz="0.000001" ixz="0" ixx="0.000001" iyy="0.000001" />
        </inertial>
    </link>
    <link name="BODY">
        <visual>
            <origin xyz="0.0 0.0 0.0" rpy="0.0 0.0 0.0" />
            <geometry>
                <mesh scale="1.0 1.0 0.7149502246986716" filename="visual_0_BODY.obj" />
            </geometry>
            <material name="fMoveBotMaterial" />
        </visual>
        <inertial>
            <origin xyz="0.0 0.0 0.07392692565917969" rpy="0 0 0" />
            <mass value="14.4" />
            <inertia iyz="0" ixy="0" izz="0.046656" ixz="0" ixx="0.046656" iyy="0.046656" />
        </inertial>
    </link>
    <link name="Spine1_1">
        <inertial>
            <origin xyz="0 0 0" rpy="0 0 0" />
            <mass value="0.000001" />
            <inertia iyz="0" ixy="0" izz="0.000001" ixz="0" ixx="0.000001" iyy="0.000001" />
        </inertial>
    </link>
    <link name="Spine1_2">
        <inertial>
            <origin xyz="0 0 0" rpy="0 0 0" />
            <mass value="0.000001" />
            <inertia iyz="0" ixy="0" izz="0.000001" ixz="0" ixx="0.000001" iyy="0.000001" />
        </inertial>
    </link>
    <link name="Spine1_3">
        <visual>
            <origin xyz="0.0 0.0 0.0" rpy="0.0 0.0 0.0" />
            <geometry>
                <mesh scale="1.0 1.0 1.3527673180621629" filename="visual_0_Spine1_3.obj" />
            </geometry>
            <material name="fMoveBotMaterial" />
        </visual>
        <inertial>
            <origin xyz="0.0 0.0 0.09381576627492905" rpy="0 0 0" />
            <mass value="21.599999999999998" />
            <inertia iyz="0" ixy="0" izz="0.11426399999999999" ixz="0" ixx="0.11426399999999999"
                iyy="0.11426399999999999" />
        </inertial>
    </link>
    <link name="Spine2_1">
        <inertial>
            <origin xyz="0 0 0" rpy="0 0 0" />
            <mass value="0.000001" />
            <inertia iyz="0" ixy="0" izz="0.000001" ixz="0" ixx="0.000001" iyy="0.000001" />
        </inertial>
    </link>
    <link name="Spine2_2">
        <inertial>
            <origin xyz="0 0 0" rpy="0 0 0" />
            <mass value="0.000001" />
            <inertia iyz="0" ixy="0" izz="0.000001" ixz="0" ixx="0.000001" iyy="0.000001" />
        </inertial>
    </link>
    <link name="Spine2_3">
        <visual>
            <origin xyz="0.0 0.0 0.0" rpy="0.0 0.0 0.0" />
            <geometry>
                <mesh scale="1.0 1.0 1.3527770711808718" filename="visual_0_Spine2_3.obj" />
            </geometry>
            <material name="fMoveBotMaterial" />
        </visual>
        <inertial>
            <origin xyz="0.0 0.0 0.09381576627492905" rpy="0 0 0" />
            <mass value="21.599999999999998" />
            <inertia iyz="0" ixy="0" izz="0.11426399999999999" ixz="0" ixx="0.11426399999999999"
                iyy="0.11426399999999999" />
        </inertial>
    </link>
    <link name="Neck1">
        <inertial>
            <origin xyz="0 0 0" rpy="0 0 0" />
            <mass value="0.000001" />
            <inertia iyz="0" ixy="0" izz="0.000001" ixz="0" ixx="0.000001" iyy="0.000001" />
        </inertial>
    </link>
    <link name="Neck2">
        <inertial>
            <origin xyz="0 0 0" rpy="0 0 0" />
            <mass value="0.000001" />
            <inertia iyz="0" ixy="0" izz="0.000001" ixz="0" ixx="0.000001" iyy="0.000001" />
        </inertial>
    </link>
    <link name="Neck3">
        <visual>
            <origin xyz="0.0 0.0 0.0" rpy="0.0 0.0 0.0" />
            <geometry>
                <mesh scale="1.0 1.0 1.0" filename="visual_0_Neck3.obj" />
            </geometry>
            <material name="fMoveBotMaterial" />
        </visual>
        <inertial>
            <origin xyz="0.0 0.0 0.0" rpy="0 0 0" />
            <mass value="0.0" />
            <inertia iyz="0" ixy="0" izz="0.0" ixz="0" ixx="0.0" iyy="0.0" />
        </inertial>
    </link>
    <link name="Torso">
        <visual>
            <origin xyz="0.0 0.0 0.0" rpy="0.0 0.0 0.0" />
            <geometry>
                <mesh scale="1.0 1.0 1.1022682791206122" filename="visual_0_Torso.obj" />
            </geometry>
            <material name="fMoveBotMaterial" />
        </visual>
        <inertial>
            <origin xyz="0.0 0.0 0.0" rpy="0 0 0" />
            <mass value="0.0" />
            <inertia iyz="0" ixy="0" izz="0.0" ixz="0" ixx="0.0" iyy="0.0" />
        </inertial>
    </link>
    <link name="L_sblade">
        <visual>
            <origin xyz="0.0 0.0 0.0" rpy="0.0 0.0 0.0" />
            <geometry>
                <mesh scale="1.0 1.0 1.0" filename="visual_0_L_sblade.obj" />
            </geometry>
            <material name="fMoveBotMaterial" />
        </visual>
        <inertial>
            <origin xyz="0.0 0.0 0.0" rpy="0 0 0" />
            <mass value="0.0" />
            <inertia iyz="0" ixy="0" izz="0.0" ixz="0" ixx="0.0" iyy="0.0" />
        </inertial>
    </link>
    <link name="L_Arm1">
        <visual>
            <origin xyz="0.0 0.0 0.0" rpy="0.0 0.0 0.0" />
            <geometry>
                <mesh scale="1.0 1.0 1.1196913862971734" filename="visual_0_L_Arm1.obj" />
            </geometry>
            <material name="fMoveBotMaterial" />
        </visual>
        <inertial>
            <origin xyz="0.0 0.0 -0.14296947419643402" rpy="0 0 0" />
            <mass value="1.78125" />
            <inertia iyz="0" ixy="0" izz="0.0017812500000000005" ixz="0" ixx="0.0017812500000000005"
                iyy="0.0017812500000000005" />
        </inertial>
    </link>
    <link name="L_Arm2">
        <visual>
            <origin xyz="0.0 0.0 0.0" rpy="0.0 0.0 0.0" />
            <geometry>
                <mesh scale="1.0 1.0 0.9563799537355628" filename="visual_0_L_Arm2.obj" />
            </geometry>
            <material name="fMoveBotMaterial" />
        </visual>
        <inertial>
            <origin xyz="0.0 0.0 -0.12903621792793274" rpy="0 0 0" />
            <mass value="1.78125" />
            <inertia iyz="0" ixy="0" izz="0.0017812500000000005" ixz="0" ixx="0.0017812500000000005"
                iyy="0.0017812500000000005" />
        </inertial>
    </link>
    <link name="L_Wrist1">
        <inertial>
            <origin xyz="0 0 0" rpy="0 0 0" />
            <mass value="0.000001" />
            <inertia iyz="0" ixy="0" izz="0.000001" ixz="0" ixx="0.000001" iyy="0.000001" />
        </inertial>
    </link>
    <link name="L_Wrist2">
        <inertial>
            <origin xyz="0 0 0" rpy="0 0 0" />
            <mass value="0.000001" />
            <inertia iyz="0" ixy="0" izz="0.000001" ixz="0" ixx="0.000001" iyy="0.000001" />
        </inertial>
    </link>
    <link name="L_Wrist3">
        <visual>
            <origin xyz="0.0 0.0 0.0" rpy="0.0 0.0 0.0" />
            <geometry>
                <mesh scale="1.0 1.0 1.0" filename="visual_0_L_Wrist3.obj" />
            </geometry>
            <material name="fMoveBotMaterial" />
        </visual>
        <inertial>
            <origin xyz="0.0 0.0 -0.04" rpy="0 0 0" />
            <mass value="0.0" />
            <inertia iyz="0" ixy="0" izz="0.0" ixz="0" ixx="0.0" iyy="0.0" />
        </inertial>
    </link>

    <link name="L_Leg1">
        <visual>
            <origin xyz="0.0 0.0 0.0" rpy="0.0 0.0 0.0" />
            <geometry>
                <mesh scale="1.0 1.0 0.9313624015428175" filename="visual_0_L_Leg1.obj" />
            </geometry>
            <material name="fMoveBotMaterial" />
        </visual>
        <inertial>
            <origin xyz="0.0 0.0 -0.20733803510665894" rpy="0 0 0" />
            <mass value="8.0625" />
            <inertia iyz="0" ixy="0" izz="0.008062500000000002" ixz="0" ixx="0.008062500000000002"
                iyy="0.008062500000000002" />
        </inertial>
    </link>
    <link name="L_Leg2">
        <visual>
            <origin xyz="0.0 0.0 0.0" rpy="0.0 0.0 0.0" />
            <geometry>
                <mesh scale="1.0 1.0 0.9572832242437154" filename="visual_0_L_Leg2.obj" />
            </geometry>
            <material name="fMoveBotMaterial" />
        </visual>
        <inertial>
            <origin xyz="0.0 0.0 -0.2102634310722351" rpy="0 0 0" />
            <mass value="5.250000000000001" />
            <inertia iyz="0" ixy="0" izz="0.005250000000000002" ixz="0" ixx="0.005250000000000002"
                iyy="0.005250000000000002" />
        </inertial>
    </link>
    <link name="L_Leg3">
        <inertial>
            <origin xyz="0 0 0" rpy="0 0 0" />
            <mass value="0.000001" />
            <inertia iyz="0" ixy="0" izz="0.000001" ixz="0" ixx="0.000001" iyy="0.000001" />
        </inertial>
    </link>
    <link name="L_Leg4">
        <inertial>
            <origin xyz="0 0 0" rpy="0 0 0" />
            <mass value="0.000001" />
            <inertia iyz="0" ixy="0" izz="0.000001" ixz="0" ixx="0.000001" iyy="0.000001" />
        </inertial>
    </link>
    <link name="L_Ankle">
        <visual>
            <origin xyz="0.0 0.0 0.0" rpy="0.0 0.0 0.0" />
            <geometry>
                <mesh scale="1.0 1.381386161395932 0.6904197830456728"
                    filename="visual_0_L_Ankle.obj" />
            </geometry>
            <material name="fMoveBotMaterial" />
        </visual>
        <inertial>
            <origin xyz="0.0 -0.06 -0.050019532442092896" rpy="0 0 0" />
            <mass value="0.0" />
            <inertia iyz="0" ixy="0" izz="0.0" ixz="0" ixx="0.0" iyy="0.0" />
        </inertial>
    </link>
    <link name="L_Foot">
        <visual>
            <origin xyz="0.0 0.0 0.0" rpy="0.0 0.0 0.0" />
            <geometry>
                <mesh scale="1.0 0.7906851368472344 1.0" filename="visual_0_L_Foot.obj" />
            </geometry>
            <material name="fMoveBotMaterial" />
        </visual>
        <inertial>
            <origin xyz="-0.0625 0.0 -0.00625" rpy="0 0 0" />
            <mass value="0.0" />
            <inertia iyz="0" ixy="0" izz="0.0" ixz="0" ixx="0.0" iyy="0.0" />
        </inertial>
    </link>

    <link name="R_sblade">
        <visual>
            <origin xyz="0.0 0.0 0.0" rpy="0.0 0.0 0.0" />
            <geometry>
                <mesh scale="1.0 1.0 1.0" filename="visual_0_R_sblade.obj" />
            </geometry>
            <material name="fMoveBotMaterial" />
        </visual>
        <inertial>
            <origin xyz="0.0 0.0 0.0" rpy="0 0 0" />
            <mass value="0.0" />
            <inertia iyz="0" ixy="0" izz="0.0" ixz="0" ixx="0.0" iyy="0.0" />
        </inertial>
    </link>
    <link name="R_Arm1">
        <visual>
            <origin xyz="0.0 0.0 0.0" rpy="0.0 0.0 0.0" />
            <geometry>
                <mesh scale="1.0 1.0 1.1196913862971734" filename="visual_0_R_Arm1.obj" />
            </geometry>
            <material name="fMoveBotMaterial" />
        </visual>
        <inertial>
            <origin xyz="0.0 0.0 -0.14296947419643402" rpy="0 0 0" />
            <mass value="1.78125" />
            <inertia iyz="0" ixy="0" izz="0.0017812500000000005" ixz="0" ixx="0.0017812500000000005"
                iyy="0.0017812500000000005" />
        </inertial>
    </link>
    <link name="R_Arm2">
        <visual>
            <origin xyz="0.0 0.0 0.0" rpy="0.0 0.0 0.0" />
            <geometry>
                <mesh scale="1.0 1.0 0.9563799537355628" filename="visual_0_R_Arm2.obj" />
            </geometry>
            <material name="fMoveBotMaterial" />
        </visual>
        <inertial>
            <origin xyz="0.0 0.0 -0.12903621792793274" rpy="0 0 0" />
            <mass value="1.78125" />
            <inertia iyz="0" ixy="0" izz="0.0017812500000000005" ixz="0" ixx="0.0017812500000000005"
                iyy="0.0017812500000000005" />
        </inertial>
    </link>
    <link name="R_Wrist1">
        <inertial>
            <origin xyz="0 0 0" rpy="0 0 0" />
            <mass value="0.000001" />
            <inertia iyz="0" ixy="0" izz="0.000001" ixz="0" ixx="0.000001" iyy="0.000001" />
        </inertial>
    </link>
    <link name="R_Wrist2">
        <inertial>
            <origin xyz="0 0 0" rpy="0 0 0" />
            <mass value="0.000001" />
            <inertia iyz="0" ixy="0" izz="0.000001" ixz="0" ixx="0.000001" iyy="0.000001" />
        </inertial>
    </link>
    <link name="R_Wrist3">
        <visual>
            <origin xyz="0.0 0.0 0.0" rpy="0.0 0.0 0.0" />
            <geometry>
                <mesh scale="1.0 1.0 1.0" filename="visual_0_R_Wrist3.obj" />
            </geometry>
            <material name="fMoveBotMaterial" />
        </visual>
        <inertial>
            <origin xyz="0.0 0.0 -0.04" rpy="0 0 0" />
            <mass value="0.0" />
            <inertia iyz="0" ixy="0" izz="0.0" ixz="0" ixx="0.0" iyy="0.0" />
        </inertial>
    </link>

    <link name="R_Leg1">
        <visual>
            <origin xyz="0.0 0.0 0.0" rpy="0.0 0.0 0.0" />
            <geometry>
                <mesh scale="1.0 1.0 0.9313624015428175" filename="visual_0_R_Leg1.obj" />
            </geometry>
            <material name="fMoveBotMaterial" />
        </visual>
        <inertial>
            <origin xyz="0.0 0.0 -0.20733803510665894" rpy="0 0 0" />
            <mass value="8.0625" />
            <inertia iyz="0" ixy="0" izz="0.008062500000000002" ixz="0" ixx="0.008062500000000002"
                iyy="0.008062500000000002" />
        </inertial>
    </link>
    <link name="R_Leg2">
        <visual>
            <origin xyz="0.0 0.0 0.0" rpy="0.0 0.0 0.0" />
            <geometry>
                <mesh scale="1.0 1.0 0.9572832242437154" filename="visual_0_R_Leg2.obj" />
            </geometry>
            <material name="fMoveBotMaterial" />
        </visual>
        <inertial>
            <origin xyz="0.0 0.0 -0.2102634310722351" rpy="0 0 0" />
            <mass value="5.250000000000001" />
            <inertia iyz="0" ixy="0" izz="0.005250000000000002" ixz="0" ixx="0.005250000000000002"
                iyy="0.005250000000000002" />
        </inertial>
    </link>
    <link name="R_Leg3">
        <inertial>
            <origin xyz="0 0 0" rpy="0 0 0" />
            <mass value="0.000001" />
            <inertia iyz="0" ixy="0" izz="0.000001" ixz="0" ixx="0.000001" iyy="0.000001" />
        </inertial>
    </link>
    <link name="R_Leg4">
        <inertial>
            <origin xyz="0 0 0" rpy="0 0 0" />
            <mass value="0.000001" />
            <inertia iyz="0" ixy="0" izz="0.000001" ixz="0" ixx="0.000001" iyy="0.000001" />
        </inertial>
    </link>
    <link name="R_Ankle">
        <visual>
            <origin xyz="0.0 0.0 0.0" rpy="0.0 0.0 0.0" />
            <geometry>
                <mesh scale="1.0 1.381386161395932 0.6904197830456728"
                    filename="visual_0_R_Ankle.obj" />
            </geometry>
            <material name="fMoveBotMaterial" />
        </visual>
        <inertial>
            <origin xyz="0.0 -0.06 -0.050019532442092896" rpy="0 0 0" />
            <mass value="0.0" />
            <inertia iyz="0" ixy="0" izz="0.0" ixz="0" ixx="0.0" iyy="0.0" />
        </inertial>
    </link>
    <link name="R_Foot">
        <visual>
            <origin xyz="0.0 0.0 0.0" rpy="0.0 0.0 0.0" />
            <geometry>
                <mesh scale="1.0 0.7906851368472344 1.0" filename="visual_0_R_Foot.obj" />
            </geometry>
            <material name="fMoveBotMaterial" />
        </visual>
        <inertial>
            <origin xyz="0.0625 0.0 -0.00625" rpy="0 0 0" />
            <mass value="0.0" />
            <inertia iyz="0" ixy="0" izz="0.0" ixz="0" ixx="0.0" iyy="0.0" />
        </inertial>
    </link>

    <joint name="R" type="floating">
        <parent link="BASE" />
        <child link="BODY" />
        <origin xyz="0 0 0" rpy="0 0 0" />
    </joint>
    <joint name="Spine1_P" type="revolute">
        <parent link="BODY" />
        <child link="Spine1_1" />
        <origin xyz="0.0 0.0 0.14785385131835938" rpy="0 0.0 0" />
        <axis xyz="1 0 0" />
        <limit velocity="1000" lower="-0.2" upper="0.6" effort="100" />
    </joint>
    <joint name="Spine1_R" type="revolute">
        <parent link="Spine1_1" />
        <child link="Spine1_2" />
        <origin xyz="0.0 0.0 0.0" rpy="0 0.0 0" />
        <axis xyz="0 1 0" />
        <limit velocity="1000" lower="-0.52" upper="0.52" effort="100" />
    </joint>
    <joint name="Spine1_Y" type="revolute">
        <parent link="Spine1_2" />
        <child link="Spine1_3" />
        <origin xyz="0.0 0.0 0.0" rpy="0 0.0 0" />
        <axis xyz="0 0 1" />
        <limit velocity="1000" lower="-0.26" upper="0.26" effort="100" />
    </joint>
    <joint name="Spine2_P" type="revolute">
        <parent link="Spine1_3" />
        <child link="Spine2_1" />
        <origin xyz="0.0 0.0 0.1876315325498581" rpy="0 0.0 0" />
        <axis xyz="1 0 0" />
        <limit velocity="1000" lower="-0.2" upper="0.34" effort="100" />
    </joint>
    <joint name="Spine2_R" type="revolute">
        <parent link="Spine2_1" />
        <child link="Spine2_2" />
        <origin xyz="0.0 0.0 0.0" rpy="0 0.0 0" />
        <axis xyz="0 1 0" />
        <limit velocity="1000" lower="-0.52" upper="0.52" effort="100" />
    </joint>
    <joint name="Spine2_Y" type="revolute">
        <parent link="Spine2_2" />
        <child link="Spine2_3" />
        <origin xyz="0.0 0.0 0.0" rpy="0 0.0 0" />
        <axis xyz="0 0 1" />
        <limit velocity="1000" lower="-0.82" upper="0.82" effort="100" />
    </joint>
    <joint name="Chest" type="fixed">
        <parent link="Spine2_3" />
        <child link="Torso" />
        <origin xyz="0.0 0.0 0.1876315325498581" rpy="0 0.0 0" />
    </joint>
    <joint name="Neck_Y" type="revolute">
        <parent link="Torso" />
        <child link="Neck1" />
        <origin xyz="0.0 0.0 0.10500428080558777" rpy="0 0.0 0" />
        <axis xyz="0 0 1" />
        <limit velocity="1000" lower="-1.48" upper="1.48" effort="100" />
    </joint>
    <joint name="Neck_P" type="revolute">
        <parent link="Neck1" />
        <child link="Neck2" />
        <origin xyz="0.0 0.0 0.0" rpy="0 0.0 0" />
        <axis xyz="1 0 0" />
        <limit velocity="1000" lower="-1.09" upper="1.11" effort="100" />
    </joint>
    <joint name="Neck_R" type="revolute">
        <parent link="Neck2" />
        <child link="Neck3" />
        <origin xyz="0.0 0.0 0.0" rpy="0 0.0 0" />
        <axis xyz="0 1 0" />
        <limit velocity="1000" lower="-0.85" upper="0.85" effort="100" />
    </joint>

    <joint name="L_Shoulder_Prism" type="prismatic">
        <parent link="Torso" />
        <child link="L_sblade" />
        <origin xyz="0.16465303301811218 0.0 0.0" rpy="0 0.0 0" />
        <axis xyz="0 0 1" />
        <limit velocity="1000" lower="-1" upper="1" effort="1" />
    </joint>
    <joint name="L_Shoulder" type="spherical">
        <parent link="L_sblade" />
        <child link="L_Arm1" />
        <origin xyz="0.0 0.0 0.0" rpy="0 -1.570796327 0" />
    </joint>
    <joint name="L_Elbow" type="revolute">
        <parent link="L_Arm1" />
        <child link="L_Arm2" />
        <origin xyz="0.0 0.0 -0.28593894839286804" rpy="0 0.0 0" />
        <axis xyz="1 0 0" />
        <limit velocity="1000" lower="-3.14" upper="0.01" effort="100" />
    </joint>
    <joint name="L_Wrist_P" type="revolute">
        <parent link="L_Arm2" />
        <child link="L_Wrist1" />
        <origin xyz="0.0 0.0 -0.2580724358558655" rpy="0 0.0 0" />
        <axis xyz="1 0 0" />
        <limit velocity="1000" lower="-1.57" upper="1.57" effort="100" />
    </joint>
    <joint name="L_Wrist_R" type="revolute">
        <parent link="L_Wrist1" />
        <child link="L_Wrist2" />
        <origin xyz="0.0 0.0 0.0" rpy="0 0.0 0" />
        <axis xyz="0 1 0" />
        <limit velocity="1000" lower="-1.57" upper="1.57" effort="100" />
    </joint>
    <joint name="L_Wrist_Y" type="revolute">
        <parent link="L_Wrist2" />
        <child link="L_Wrist3" />
        <origin xyz="0.0 0.0 0.0" rpy="0 0.0 0" />
        <axis xyz="0 0 1" />
        <limit velocity="1000" lower="-0.5" upper="0.5" effort="100" />
    </joint>
    <joint name="R_Shoulder_Prism" type="prismatic">
        <parent link="Torso" />
        <child link="R_sblade" />
        <origin xyz="-0.16465303301811218 0.0 0.0" rpy="0 0.0 0" />
        <axis xyz="0 0 1" />
        <limit velocity="1000" lower="-1" upper="1" effort="1" />
    </joint>
    <joint name="R_Shoulder" type="spherical">
        <parent link="R_sblade" />
        <child link="R_Arm1" />
        <origin xyz="0.0 0.0 0.0" rpy="0 1.570796327 0" />
    </joint>
    <joint name="R_Elbow" type="revolute">
        <parent link="R_Arm1" />
        <child link="R_Arm2" />
        <origin xyz="0.0 0.0 -0.28593894839286804" rpy="0 0.0 0" />
        <axis xyz="1 0 0" />
        <limit velocity="1000" lower="-3.14" upper="0.01" effort="100" />
    </joint>
    <joint name="R_Wrist_P" type="revolute">
        <parent link="R_Arm2" />
        <child link="R_Wrist1" />
        <origin xyz="0.0 0.0 -0.2580724358558655" rpy="0 0.0 0" />
        <axis xyz="1 0 0" />
        <limit velocity="1000" lower="-1.57" upper="1.57" effort="100" />
    </joint>
    <joint name="R_Wrist_R" type="revolute">
        <parent link="R_Wrist1" />
        <child link="R_Wrist2" />
        <origin xyz="0.0 0.0 0.0" rpy="0 0.0 0" />
        <axis xyz="0 1 0" />
        <limit velocity="1000" lower="-1.57" upper="1.57" effort="100" />
    </joint>
    <joint name="R_Wrist_Y" type="revolute">
        <parent link="R_Wrist2" />
        <child link="R_Wrist3" />
        <origin xyz="0.0 0.0 0.0" rpy="0 0.0 0" />
        <axis xyz="0 0 1" />
        <limit velocity="1000" lower="-0.5" upper="0.5" effort="100" />
    </joint>
    <joint name="L_Hip" type="spherical">
        <parent link="BODY" />
        <child link="L_Leg1" />
        <origin xyz="0.104087695479393 0.0 0.0" rpy="0 0.0 0" />
    </joint>
    <joint name="L_Knee" type="revolute">
        <parent link="L_Leg1" />
        <child link="L_Leg2" />
        <origin xyz="0.0 0.0 -0.41467607021331787" rpy="0 0.0 0" />
        <axis xyz="1 0 0" />
        <limit velocity="1000" lower="0.01" upper="3.14" effort="100" />
    </joint>
    <joint name="L_Ankle_Y" type="revolute">
        <parent link="L_Leg2" />
        <child link="L_Leg3" />
        <origin xyz="0.0 0.0 -0.4205268621444702" rpy="0 0.0 0" />
        <axis xyz="0 0 -1" />
        <limit velocity="1000" lower="-1.25" upper="1.25" effort="100" />
    </joint>
    <joint name="L_Ankle_R" type="revolute">
        <parent link="L_Leg3" />
        <child link="L_Leg4" />
        <origin xyz="0.0 0.0 0.0" rpy="0 0.0 0" />
        <axis xyz="0 1 0" />
        <limit velocity="1000" lower="-0.35" upper="0.35" effort="100" />
    </joint>
    <joint name="L_Ankle_P" type="revolute">
        <parent link="L_Leg4" />
        <child link="L_Ankle" />
        <origin xyz="0.0 0.0 0.0" rpy="0 0.0 0" />
        <axis xyz="1 0 0" />
        <limit velocity="1000" lower="-0.35" upper="0.35" effort="100" />
    </joint>
    <joint name="L_Foot_Pinky_P" type="revolute">
        <parent link="L_Ankle" />
        <child link="L_Foot" />
        <origin xyz="0.05502148568630219 -0.1500585973262787 -0.050019532442092896" rpy="0 0.0 0" />
        <axis xyz="1 0 0" />
        <limit velocity="1000" lower="-0.3" upper="0.001" effort="100" />
    </joint>
    <joint name="R_Hip" type="spherical">
        <parent link="BODY" />
        <child link="R_Leg1" />
        <origin xyz="-0.104087695479393 0.0 0.0" rpy="0 0.0 0" />
    </joint>
    <joint name="R_Knee" type="revolute">
        <parent link="R_Leg1" />
        <child link="R_Leg2" />
        <origin xyz="0.0 0.0 -0.41467607021331787" rpy="0 0.0 0" />
        <axis xyz="1 0 0" />
        <limit velocity="1000" lower="0.01" upper="3.14" effort="100" />
    </joint>
    <joint name="R_Ankle_Y" type="revolute">
        <parent link="R_Leg2" />
        <child link="R_Leg3" />
        <origin xyz="0.0 0.0 -0.4205268621444702" rpy="0 0.0 0" />
        <axis xyz="0 0 1" />
        <limit velocity="1000" lower="-1.25" upper="1.25" effort="100" />
    </joint>
    <joint name="R_Ankle_R" type="revolute">
        <parent link="R_Leg3" />
        <child link="R_Leg4" />
        <origin xyz="0.0 0.0 0.0" rpy="0 0.0 0" />
        <axis xyz="0 1 0" />
        <limit velocity="1000" lower="-0.35" upper="0.35" effort="100" />
    </joint>
    <joint name="R_Ankle_P" type="revolute">
        <parent link="R_Leg4" />
        <child link="R_Ankle" />
        <origin xyz="0.0 0.0 0.0" rpy="0 0.0 0" />
        <axis xyz="1 0 0" />
        <limit velocity="1000" lower="-0.35" upper="0.35" effort="100" />
    </joint>
    <joint name="R_Foot_Pinky_P" type="revolute">
        <parent link="R_Ankle" />
        <child link="R_Foot" />
        <origin xyz="-0.05502148568630219 -0.1500585973262787 -0.050019532442092896" rpy="0 0.0 0" />
        <axis xyz="1 0 0" />
        <limit velocity="1000" lower="-0.3" upper="0.001" effort="100" />
    </joint>

</robot>