<?xml version="1.0" encoding="utf-8"?>
<!-- This URDF was automatically created by SolidWorks to URDF Exporter! Originally created by Stephen Brawner (brawner@gmail.com) 
     Commit Version: 1.6.0-4-g7f85cfe  Build Version: 1.6.7995.38578
     For more information, please see http://wiki.ros.org/sw_urdf_exporter -->
<robot
  name="lingyue_urdf_1.0">
   <mujoco>
        <compiler meshdir="../../meshes/Bessica_D_v1_1/SkeletonOnly" balanceinertia="true" discardvisual="false" />
        <contact>
            <exclude body1="base_link" body2="left_arm_base_link" />
            <exclude body1="left_arm_base_link" body2="left_arm_link1" />
            <exclude body1="left_arm_link1" body2="left_arm_link2" />
            <exclude body1="left_arm_link2" body2="left_arm_link3" />
            <exclude body1="left_arm_link3" body2="left_arm_link4" />
            <exclude body1="left_arm_link4" body2="left_arm_link5" />
            <exclude body1="left_arm_link5" body2="left_arm_link6" />
            <exclude body1="left_arm_link6" body2="left_arm_link7" />
            <exclude body1="left_arm_link7" body2="left_arm_gripper_left_finger" />
            <exclude body1="left_arm_link7" body2="left_arm_gripper_right_finger" />
            <exclude body1="base_link" body2="right_arm_base_link" />
            <exclude body1="right_arm_base_link" body2="right_arm_link1" />
            <exclude body1="right_arm_link1" body2="right_arm_link2" />
            <exclude body1="right_arm_link2" body2="right_arm_link3" />
            <exclude body1="right_arm_link3" body2="right_arm_link4" />
            <exclude body1="right_arm_link4" body2="right_arm_link5" />
            <exclude body1="right_arm_link5" body2="right_arm_link6" />
            <exclude body1="right_arm_link6" body2="right_arm_link7" />
            <exclude body1="right_arm_link7" body2="right_arm_gripper_left_finger" />
            <exclude body1="right_arm_link7" body2="right_arm_gripper_right_finger" />
        </contact>
    </mujoco>

  <link
    name="base_link">
    <inertial>
      <origin
        xyz="0.0052255070486186 0.000768313849830157 0.452495549709599"
        rpy="0 0 0" />
      <mass
        value="2.01690048544311" />
      <inertia
        ixx="0.0209705849400507"
        ixy="-8.39123948475962E-06"
        ixz="0.000384543145284923"
        iyy="0.0191389747287245"
        iyz="5.57258601597696E-05"
        izz="0.0172742504549452" />
    </inertial>
    <visual>
      <origin
        xyz="0 0 0"
        rpy="0 0 0" />
      <geometry>
        <mesh
          filename="../../meshes/Bessica_D_v1_1/SkeletonOnly/meshes/base_link.STL" />
      </geometry>
      <material
        name="">
        <color
          rgba="0.807843137254902 0.843137254901961 0.905882352941176 1" />
      </material>
    </visual>
    <collision>
      <origin
        xyz="0 0 0"
        rpy="0 0 0" />
      <geometry>
        <mesh
          filename="../../meshes/Bessica_D_v1_1/SkeletonOnly/meshes/base_link.STL" />
      </geometry>
    </collision>
  </link>
  <link
    name="head">
    <inertial>
      <origin
        xyz="-0.0293125038003454 -0.000187461848933229 -0.0543306023228741"
        rpy="0 0 0" />
      <mass
        value="0.142402684646725" />
      <inertia
        ixx="5.88444095122021E-05"
        ixy="3.20779136005839E-08"
        ixz="-2.3670752535087E-07"
        iyy="8.42831925717196E-05"
        iyz="-3.88469642541035E-08"
        izz="0.000119983891754627" />
    </inertial>
    <visual>
      <origin
        xyz="0 0 0"
        rpy="0 0 0" />
      <geometry>
        <mesh
          filename="../../meshes/Bessica_D_v1_1/SkeletonOnly/meshes/head.STL" />
      </geometry>
      <material
        name="">
        <color
          rgba="0.592156862745098 0.666666666666667 0.682352941176471 1" />
      </material>
    </visual>
    <collision>
      <origin
        xyz="0 0 0"
        rpy="0 0 0" />
      <geometry>
        <mesh
          filename="../../meshes/Bessica_D_v1_1/SkeletonOnly/meshes/head.STL" />
      </geometry>
    </collision>
  </link>
  <joint
    name="head"
    type="fixed">
    <origin
      xyz="0.0608245014818929 0.00175926213288763 0.700041453535697"
      rpy="0 0 0" />
    <parent
      link="base_link" />
    <child
      link="head" />
    <axis
      xyz="0 0 0" />
  </joint>
  <link
    name="right_arm_base_link">
    <inertial>
      <origin
        xyz="1.14229575733371E-05 0.0313122795518412 -0.00207120887226653"
        rpy="0 0 0" />
      <mass
        value="0.708886467492412" />
      <inertia
        ixx="0.00109027347222112"
        ixy="-1.24274485088717E-07"
        ixz="3.30654402003726E-08"
        iyy="0.00175522828645706"
        iyz="1.13920582313823E-05"
        izz="0.0010339233657024" />
    </inertial>
    <visual>
      <origin
        xyz="0 0 0"
        rpy="0 0 0" />
      <geometry>
        <mesh
          filename="../../meshes/Bessica_D_v1_1/SkeletonOnly/meshes/right_arm_base_link.STL" />
      </geometry>
      <material
        name="">
        <color
          rgba="0.807843137254902 0.843137254901961 0.905882352941176 1" />
      </material>
    </visual>
    <collision>
      <origin
        xyz="0 0 0"
        rpy="0 0 0" />
      <geometry>
        <mesh
          filename="../../meshes/Bessica_D_v1_1/SkeletonOnly/meshes/right_arm_base_link.STL" />
      </geometry>
    </collision>
  </link>
  <joint
    name="right_arm_joint1"
    type="fixed">
    <origin
      xyz="-0.0608245014818929 -0.0917592621328876 -0.185541452202364"
      rpy="0 0 -3.14159265358979" />
    <parent
      link="head" />
    <child
      link="right_arm_base_link" />
    <axis
      xyz="0 0 0" />
  </joint>
  <link
    name="right_arm_link1">
    <inertial>
      <origin
        xyz="0.000110936279980989 -0.00312061477497777 0.000177913829121079"
        rpy="0 0 0" />
      <mass
        value="0.208265932404293" />
      <inertia
        ixx="0.00015065297346917"
        ixy="1.035930541789E-06"
        ixz="-4.02294230760938E-07"
        iyy="0.000340012950100841"
        iyz="-3.27493899289596E-07"
        izz="0.000262863346162676" />
    </inertial>
    <visual>
      <origin
        xyz="0 0 0"
        rpy="0 0 0" />
      <geometry>
        <mesh
          filename="../../meshes/Bessica_D_v1_1/SkeletonOnly/meshes/right_arm_link1.STL" />
      </geometry>
      <material
        name="">
        <color
          rgba="0.807843137254902 0.843137254901961 0.905882352941176 1" />
      </material>
    </visual>
    <collision>
      <origin
        xyz="0 0 0"
        rpy="0 0 0" />
      <geometry>
        <mesh
          filename="../../meshes/Bessica_D_v1_1/SkeletonOnly/meshes/right_arm_link1.STL" />
      </geometry>
    </collision>
  </link>
  <joint
    name="right_arm_joint1"
    type="revolute">
    <origin
      xyz="-5.00000000009382E-05 0.1146 0"
      rpy="3.14159265358979 0 0" />
    <parent
      link="right_arm_base_link" />
    <child
      link="right_arm_link1" />
    <axis
      xyz="0 1 0" />
    <limit
      lower="-2.14"
      upper="2.14"
      effort="5"
      velocity="12" />
  </joint>
  <link
    name="right_arm_link2">
    <inertial>
      <origin
        xyz="-0.0297080813049525 0.000293734615861629 0.000469868606601365"
        rpy="0 0 0" />
      <mass
        value="0.0472690683829237" />
      <inertia
        ixx="7.84810743746745E-06"
        ixy="-3.0307332166087E-07"
        ixz="-8.12871142227175E-07"
        iyy="1.61967381497318E-05"
        iyz="-2.66374052480781E-08"
        izz="1.57923111016873E-05" />
    </inertial>
    <visual>
      <origin
        xyz="0 0 0"
        rpy="0 0 0" />
      <geometry>
        <mesh
          filename="../../meshes/Bessica_D_v1_1/SkeletonOnly/meshes/right_arm_link2.STL" />
      </geometry>
      <material
        name="">
        <color
          rgba="0.592156862745098 0.666666666666667 0.682352941176471 1" />
      </material>
    </visual>
    <collision>
      <origin
        xyz="0 0 0"
        rpy="0 0 0" />
      <geometry>
        <mesh
          filename="../../meshes/Bessica_D_v1_1/SkeletonOnly/meshes/right_arm_link2.STL" />
      </geometry>
    </collision>
  </link>
  <joint
    name="right_arm_joint2"
    type="revolute">
    <origin
      xyz="0 -0.0428600000000001 0"
      rpy="3.14159265358979 1.5707963267949 0" />
    <parent
      link="right_arm_link1" />
    <child
      link="right_arm_link2" />
    <axis
      xyz="0 0 -1" />
    <limit
      lower="-2.14"
      upper="2.14"
      effort="5"
      velocity="12" />
  </joint>
  <link
    name="right_arm_link3">
    <inertial>
      <origin
        xyz="-0.0035931321606647 -0.000221914238546617 0.0944689642093965"
        rpy="0 0 0" />
      <mass
        value="0.140451565348764" />
      <inertia
        ixx="7.84851548096081E-05"
        ixy="7.63137766499138E-08"
        ixz="-2.13950350084598E-06"
        iyy="8.80462028482879E-05"
        iyz="-2.08857307228524E-07"
        izz="5.54283683548546E-05" />
    </inertial>
    <visual>
      <origin
        xyz="0 0 0"
        rpy="0 0 0" />
      <geometry>
        <mesh
          filename="../../meshes/Bessica_D_v1_1/SkeletonOnly/meshes/right_arm_link3.STL" />
      </geometry>
      <material
        name="">
        <color
          rgba="0.807843137254902 0.843137254901961 0.905882352941176 1" />
      </material>
    </visual>
    <collision>
      <origin
        xyz="0 0 0"
        rpy="0 0 0" />
      <geometry>
        <mesh
          filename="../../meshes/Bessica_D_v1_1/SkeletonOnly/meshes/right_arm_link3.STL" />
      </geometry>
    </collision>
  </link>
  <joint
    name="right_arm_joint3"
    type="revolute">
    <origin
      xyz="-0.0645499999999983 0 0.00030000000000413"
      rpy="1.5707963267949 0 -1.5707963267949" />
    <parent
      link="right_arm_link2" />
    <child
      link="right_arm_link3" />
    <axis
      xyz="0 0 -1" />
    <limit
      lower="-2.14"
      upper="2.14"
      effort="5"
      velocity="12" />
  </joint>
  <link
    name="right_arm_link4">
    <inertial>
      <origin
        xyz="-2.8021106827647E-05 -0.0241582530067607 -4.84136545567393E-05"
        rpy="0 0 0" />
      <mass
        value="0.0427207248005302" />
      <inertia
        ixx="1.04868448962503E-05"
        ixy="6.74043724082861E-10"
        ixz="2.02593790454178E-12"
        iyy="8.49767824751406E-06"
        iyz="-1.47298483047162E-12"
        izz="8.00564872453032E-06" />
    </inertial>
    <visual>
      <origin
        xyz="0 0 0"
        rpy="0 0 0" />
      <geometry>
        <mesh
          filename="../../meshes/Bessica_D_v1_1/SkeletonOnly/meshes/right_arm_link4.STL" />
      </geometry>
      <material
        name="">
        <color
          rgba="0.592156862745098 0.666666666666667 0.682352941176471 1" />
      </material>
    </visual>
    <collision>
      <origin
        xyz="0 0 0"
        rpy="0 0 0" />
      <geometry>
        <mesh
          filename="../../meshes/Bessica_D_v1_1/SkeletonOnly/meshes/right_arm_link4.STL" />
      </geometry>
    </collision>
  </link>
  <joint
    name="right_arm_joint4"
    type="revolute">
    <origin
      xyz="-1.89941608920163E-05 -5.00000000027701E-05 0.181600000000001"
      rpy="-1.5707963267949 0 0" />
    <parent
      link="right_arm_link3" />
    <child
      link="right_arm_link4" />
    <axis
      xyz="0 0 1" />
    <limit
      lower="-2.14"
      upper="2.14"
      effort="5"
      velocity="12" />
  </joint>
  <link
    name="right_arm_link5">
    <inertial>
      <origin
        xyz="-0.00180910551541141 0.000196787268223975 -0.0430792551205488"
        rpy="0 0 0" />
      <mass
        value="0.110396949311228" />
      <inertia
        ixx="8.50646302378457E-05"
        ixy="-4.1548293291304E-07"
        ixz="9.6766191036647E-06"
        iyy="8.69928948972484E-05"
        iyz="8.81478326050512E-07"
        izz="4.58202376916797E-05" />
    </inertial>
    <visual>
      <origin
        xyz="0 0 0"
        rpy="0 0 0" />
      <geometry>
        <mesh
          filename="../../meshes/Bessica_D_v1_1/SkeletonOnly/meshes/right_arm_link5.STL" />
      </geometry>
      <material
        name="">
        <color
          rgba="0.807843137254902 0.843137254901961 0.905882352941176 1" />
      </material>
    </visual>
    <collision>
      <origin
        xyz="0 0 0"
        rpy="0 0 0" />
      <geometry>
        <mesh
          filename="../../meshes/Bessica_D_v1_1/SkeletonOnly/meshes/right_arm_link5.STL" />
      </geometry>
    </collision>
  </link>
  <joint
    name="right_arm_joint5"
    type="revolute">
    <origin
      xyz="0 -0.0487999999999997 -0.000100000000000044"
      rpy="-1.5707963267949 0 0" />
    <parent
      link="right_arm_link4" />
    <child
      link="right_arm_link5" />
    <axis
      xyz="0 0 1" />
    <limit
      lower="-2.14"
      upper="2.14"
      effort="5"
      velocity="12" />
  </joint>
  <link
    name="right_arm_link6">
    <inertial>
      <origin
        xyz="0.00036589757849087 -0.0257376411060454 -4.10017362013904E-05"
        rpy="0 0 0" />
      <mass
        value="0.0345706786766193" />
      <inertia
        ixx="1.56357560390161E-05"
        ixy="-1.6318363095613E-07"
        ixz="-7.87691904674622E-09"
        iyy="1.27277246486035E-05"
        iyz="2.83300556758754E-08"
        izz="9.20019800174231E-06" />
    </inertial>
    <visual>
      <origin
        xyz="0 0 0"
        rpy="0 0 0" />
      <geometry>
        <mesh
          filename="../../meshes/Bessica_D_v1_1/SkeletonOnly/meshes/right_arm_link6.STL" />
      </geometry>
      <material
        name="">
        <color
          rgba="0.807843137254902 0.843137254901961 0.905882352941176 1" />
      </material>
    </visual>
    <collision>
      <origin
        xyz="0 0 0"
        rpy="0 0 0" />
      <geometry>
        <mesh
          filename="../../meshes/Bessica_D_v1_1/SkeletonOnly/meshes/right_arm_link6.STL" />
      </geometry>
    </collision>
  </link>
  <joint
    name="right_arm_joint6"
    type="revolute">
    <origin
      xyz="0.00288999999999712 0.00207606801469368 -0.10801"
      rpy="1.5707963267949 0 0" />
    <parent
      link="right_arm_link5" />
    <child
      link="right_arm_link6" />
    <axis
      xyz="0 0 1" />
    <limit
      lower="-2.14"
      upper="2.14"
      effort="5"
      velocity="12" />
  </joint>
  <link
    name="right_arm_link7">
    <inertial>
      <origin
        xyz="0.0415075816926784 0.000152834551207959 -0.0262966809284831"
        rpy="0 0 0" />
      <mass
        value="0.134443483288705" />
      <inertia
        ixx="9.47488732001998E-05"
        ixy="-1.46899736216728E-08"
        ixz="-3.66536057147566E-06"
        iyy="4.3145617616874E-05"
        iyz="-1.72469159945908E-08"
        izz="8.45592399895302E-05" />
    </inertial>
    <visual>
      <origin
        xyz="0 0 0"
        rpy="0 0 0" />
      <geometry>
        <mesh
          filename="../../meshes/Bessica_D_v1_1/SkeletonOnly/meshes/right_arm_link7.STL" />
      </geometry>
      <material
        name="">
        <color
          rgba="0.807843137254902 0.843137254901961 0.905882352941176 1" />
      </material>
    </visual>
    <collision>
      <origin
        xyz="0 0 0"
        rpy="0 0 0" />
      <geometry>
        <mesh
          filename="../../meshes/Bessica_D_v1_1/SkeletonOnly/meshes/right_arm_link7.STL" />
      </geometry>
    </collision>
  </link>
  <joint
    name="right_arm_joint7"
    type="revolute">
    <origin
      xyz="-0.00149999999999995 -0.05561 0"
      rpy="-1.57079632065809 0 -1.5707963267949" />
    <parent
      link="right_arm_link6" />
    <child
      link="right_arm_link7" />
    <axis
      xyz="0 0 -1" />
    <limit
      lower="-2.14"
      upper="2.14"
      effort="5"
      velocity="12" />
  </joint>
  <link
    name="right_arm_gripper_left_finger">
    <inertial>
      <origin
        xyz="-0.0434086638076309 -1.55043299865376E-08 -0.0106596340265737"
        rpy="0 0 0" />
      <mass
        value="0.025646269101417" />
      <inertia
        ixx="5.13427082909082E-06"
        ixy="2.45028551060813E-11"
        ixz="-1.26430154389001E-06"
        iyy="6.46826207608316E-06"
        iyz="-4.16227997995568E-13"
        izz="8.0360672473386E-06" />
    </inertial>
    <visual>
      <origin
        xyz="0 0 0"
        rpy="0 0 0" />
      <geometry>
        <mesh
          filename="../../meshes/Bessica_D_v1_1/SkeletonOnly/meshes/right_arm_gripper_left_finger.STL" />
      </geometry>
      <material
        name="">
        <color
          rgba="0.592156862745098 0.666666666666667 0.682352941176471 1" />
      </material>
    </visual>
    <collision>
      <origin
        xyz="0 0 0"
        rpy="0 0 0" />
      <geometry>
        <mesh
          filename="../../meshes/Bessica_D_v1_1/SkeletonOnly/meshes/right_arm_gripper_left_finger.STL" />
      </geometry>
    </collision>
  </link>
  <joint
    name="right_arm_gripper_joint1"
    type="prismatic">
    <origin
      xyz="0.14128 0.0505 -0.00015"
      rpy="1.5708 0 0" />
    <parent
      link="right_arm_link7" />
    <child
      link="right_arm_gripper_left_finger" />
    <axis
      xyz="0 0.054375 -0.99852" />
    <limit
      lower="-0.05"
      upper="0"
      effort="5"
      velocity="12" />
  </joint>
  <link
    name="right_arm_gripper_right_finger">
    <inertial>
      <origin
        xyz="-0.0434086638077172 -1.55043430316582E-08 -0.0106596340265701"
        rpy="0 0 0" />
      <mass
        value="0.0256462691012978" />
      <inertia
        ixx="5.13427082907485E-06"
        ixy="2.45028619613969E-11"
        ixz="-1.2643015438903E-06"
        iyy="6.46826207604504E-06"
        iyz="-4.16226521284073E-13"
        izz="8.03606724728575E-06" />
    </inertial>
    <visual>
      <origin
        xyz="0 0 0"
        rpy="0 0 0" />
      <geometry>
        <mesh
          filename="../../meshes/Bessica_D_v1_1/SkeletonOnly/meshes/right_arm_gripper_right_finger.STL" />
      </geometry>
      <material
        name="">
        <color
          rgba="0.592156862745098 0.666666666666667 0.682352941176471 1" />
      </material>
    </visual>
    <collision>
      <origin
        xyz="0 0 0"
        rpy="0 0 0" />
      <geometry>
        <mesh
          filename="../../meshes/Bessica_D_v1_1/SkeletonOnly/meshes/right_arm_gripper_right_finger.STL" />
      </geometry>
    </collision>
  </link>
  <joint
    name="right_arm_gripper_joint2"
    type="prismatic">
    <origin
      xyz="0.14128 -0.0505 -0.00015"
      rpy="-1.5708 0 0" />
    <parent
      link="right_arm_link7" />
    <child
      link="right_arm_gripper_right_finger" />
    <axis
      xyz="0 -0.054375 0.99852" />
    <limit
      lower="0"
      upper="0.05"
      effort="5"
      velocity="12" />
  </joint>
  <link
    name="right_gripper_center">
   <!-- <inertial>
      <origin
        xyz="-0.567708783489944 -0.00255239950365633 -0.249378733393753"
        rpy="0 0 0" /> -->
    <visual>
      <origin
        xyz="0 0 0"
        rpy="0 0 0" />
      <geometry>
        <sphere radius="0.005" />
      </geometry>
      <material
        name="green_virtual_sphere_material">
        <color
          rgba="0 1 0 1" />
      </material>
    </visual>
  </link>

  <joint
    name="right_arm_gripper_joint"
    type="fixed">
    <origin
      xyz="0.14128 0 -0.00015"
      rpy="-3.1416 0 0" />
    <parent
      link="right_arm_link7" />
    <child
      link="right_gripper_center" />
    <axis
      xyz="0 0 0" />
  </joint>
  <link
    name="left_arm_base_link">
    <inertial>
      <origin
        xyz="-1.14229701028146E-05 -0.00207120886507745 0.0313122795461047"
        rpy="0 0 0" />
      <mass
        value="0.708886467816498" />
      <inertia
        ixx="0.0010902734722558"
        ixy="-3.30653114624663E-08"
        ixz="1.24274418586447E-07"
        iyy="0.00103392336596676"
        iyz="1.13920582784335E-05"
        izz="0.00175522828670161" />
    </inertial>
    <visual>
      <origin
        xyz="0 0 0"
        rpy="0 0 0" />
      <geometry>
        <mesh
          filename="../../meshes/Bessica_D_v1_1/SkeletonOnly/meshes/left_arm_base_link.STL" />
      </geometry>
      <material
        name="">
        <color
          rgba="0.807843137254902 0.843137254901961 0.905882352941176 1" />
      </material>
    </visual>
    <collision>
      <origin
        xyz="0 0 0"
        rpy="0 0 0" />
      <geometry>
        <mesh
          filename="../../meshes/Bessica_D_v1_1/SkeletonOnly/meshes/left_arm_base_link.STL" />
      </geometry>
    </collision>
  </link>
  <joint
    name="left_arm_joint1"
    type="fixed">
    <origin
      xyz="-0.0608244908152269 0.0882407378671124 -0.185541452202364"
      rpy="1.5707963267949 0 -3.14159265358979" />
    <parent
      link="head" />
    <child
      link="left_arm_base_link" />
    <axis
      xyz="0 0 0" />
  </joint>
  <link
    name="left_arm_link1">
    <inertial>
      <origin
        xyz="-0.000114065547778958 -0.000187361749707626 0.00370368574276148"
        rpy="0 0 0" />
      <mass
        value="0.197841064757444" />
      <inertia
        ixx="0.000148040969900171"
        ixy="-4.02156083847359E-07"
        ixz="1.03598334177727E-06"
        iyy="0.000260030642343948"
        iyz="-3.27575058672307E-07"
        izz="0.000335789888401838" />
    </inertial>
    <visual>
      <origin
        xyz="0 0 0"
        rpy="0 0 0" />
      <geometry>
        <mesh
          filename="../../meshes/Bessica_D_v1_1/SkeletonOnly/meshes/left_arm_link1.STL" />
      </geometry>
      <material
        name="">
        <color
          rgba="0.807843137254902 0.843137254901961 0.905882352941176 1" />
      </material>
    </visual>
    <collision>
      <origin
        xyz="0 0 0"
        rpy="0 0 0" />
      <geometry>
        <mesh
          filename="../../meshes/Bessica_D_v1_1/SkeletonOnly/meshes/left_arm_link1.STL" />
      </geometry>
    </collision>
  </link>
  <joint
    name="left_arm_joint1"
    type="revolute">
    <origin
      xyz="5.00000000009382E-05 0 0.1146"
      rpy="0 0 0" />
    <parent
      link="left_arm_base_link" />
    <child
      link="left_arm_link1" />
    <axis
      xyz="0 0 1" />
    <limit
      lower="-2.14"
      upper="2.14"
      effort="5"
      velocity="12" />
  </joint>
  <link
    name="left_arm_link2">
    <inertial>
      <origin
        xyz="-0.0297080813058722 0.000293734620618658 0.000469868617215791"
        rpy="0 0 0" />
      <mass
        value="0.0472690683067017" />
      <inertia
        ixx="7.84810744977831E-06"
        ixy="-3.03073324362694E-07"
        ixz="-8.12871150167469E-07"
        iyy="1.61967381251389E-05"
        iyz="-2.66374100600199E-08"
        izz="1.57923110897148E-05" />
    </inertial>
    <visual>
      <origin
        xyz="0 0 0"
        rpy="0 0 0" />
      <geometry>
        <mesh
          filename="../../meshes/Bessica_D_v1_1/SkeletonOnly/meshes/left_arm_link2.STL" />
      </geometry>
      <material
        name="">
        <color
          rgba="0.592156862745098 0.666666666666667 0.682352941176471 1" />
      </material>
    </visual>
    <collision>
      <origin
        xyz="0 0 0"
        rpy="0 0 0" />
      <geometry>
        <mesh
          filename="../../meshes/Bessica_D_v1_1/SkeletonOnly/meshes/left_arm_link2.STL" />
      </geometry>
    </collision>
  </link>
  <joint
    name="left_arm_joint2"
    type="revolute">
    <origin
      xyz="0 0 0.04286"
      rpy="1.5707963267949 0 1.5707963267949" />
    <parent
      link="left_arm_link1" />
    <child
      link="left_arm_link2" />
    <axis
      xyz="0 0 1" />
    <limit
      lower="-2.14"
      upper="2.14"
      effort="5"
      velocity="12" />
  </joint>
  <link
    name="left_arm_link3">
    <inertial>
      <origin
        xyz="-0.00359313216075538 -0.000221914238669546 0.0944689642085152"
        rpy="0 0 0" />
      <mass
        value="0.14045156535093" />
      <inertia
        ixx="7.84851548099568E-05"
        ixy="7.6313776566735E-08"
        ixz="-2.13950350074402E-06"
        iyy="8.8046202848535E-05"
        iyz="-2.08857307055331E-07"
        izz="5.54283683550603E-05" />
    </inertial>
    <visual>
      <origin
        xyz="0 0 0"
        rpy="0 0 0" />
      <geometry>
        <mesh
          filename="../../meshes/Bessica_D_v1_1/SkeletonOnly/meshes/left_arm_link3.STL" />
      </geometry>
      <material
        name="">
        <color
          rgba="0.807843137254902 0.843137254901961 0.905882352941176 1" />
      </material>
    </visual>
    <collision>
      <origin
        xyz="0 0 0"
        rpy="0 0 0" />
      <geometry>
        <mesh
          filename="../../meshes/Bessica_D_v1_1/SkeletonOnly/meshes/left_arm_link3.STL" />
      </geometry>
    </collision>
  </link>
  <joint
    name="left_arm_joint3"
    type="revolute">
    <origin
      xyz="-0.0645499999999944 0 0.000300000000004297"
      rpy="1.5707963267949 0 -1.5707963267949" />
    <parent
      link="left_arm_link2" />
    <child
      link="left_arm_link3" />
    <axis
      xyz="0 0 -1" />
    <limit
      lower="-2.14"
      upper="2.14"
      effort="5"
      velocity="12" />
  </joint>
  <link
    name="left_arm_link4">
    <inertial>
      <origin
        xyz="-2.80211068357239E-05 -0.0241582530067605 -4.84136545565728E-05"
        rpy="0 0 0" />
      <mass
        value="0.0427207248005301" />
      <inertia
        ixx="1.04868448962502E-05"
        ixy="6.74043723901983E-10"
        ixz="2.02593790702478E-12"
        iyy="8.49767824751404E-06"
        iyz="-1.47298483825813E-12"
        izz="8.00564872453029E-06" />
    </inertial>
    <visual>
      <origin
        xyz="0 0 0"
        rpy="0 0 0" />
      <geometry>
        <mesh
          filename="../../meshes/Bessica_D_v1_1/SkeletonOnly/meshes/left_arm_link4.STL" />
      </geometry>
      <material
        name="">
        <color
          rgba="0.592156862745098 0.666666666666667 0.682352941176471 1" />
      </material>
    </visual>
    <collision>
      <origin
        xyz="0 0 0"
        rpy="0 0 0" />
      <geometry>
        <mesh
          filename="../../meshes/Bessica_D_v1_1/SkeletonOnly/meshes/left_arm_link4.STL" />
      </geometry>
    </collision>
  </link>
  <joint
    name="left_arm_joint4"
    type="revolute">
    <origin
      xyz="-1.89941608861599E-05 -5.00000000028533E-05 0.181600000000001"
      rpy="-1.5707963267949 0 0" />
    <parent
      link="left_arm_link3" />
    <child
      link="left_arm_link4" />
    <axis
      xyz="0 0 -1" />
    <limit
      lower="-2.14"
      upper="2.14"
      effort="5"
      velocity="12" />
  </joint>
  <link
    name="left_arm_link5">
    <inertial>
      <origin
        xyz="-0.00180910545981172 0.000196787091761741 -0.0430792554514196"
        rpy="0 0 0" />
      <mass
        value="0.110396950769399" />
      <inertia
        ixx="8.50646316985132E-05"
        ixy="-4.15482833718214E-07"
        ixz="9.67661929495237E-06"
        iyy="8.69928960918562E-05"
        iyz="8.81477744222685E-07"
        izz="4.58202380057361E-05" />
    </inertial>
    <visual>
      <origin
        xyz="0 0 0"
        rpy="0 0 0" />
      <geometry>
        <mesh
          filename="../../meshes/Bessica_D_v1_1/SkeletonOnly/meshes/left_arm_link5.STL" />
      </geometry>
      <material
        name="">
        <color
          rgba="0.807843137254902 0.843137254901961 0.905882352941176 1" />
      </material>
    </visual>
    <collision>
      <origin
        xyz="0 0 0"
        rpy="0 0 0" />
      <geometry>
        <mesh
          filename="../../meshes/Bessica_D_v1_1/SkeletonOnly/meshes/left_arm_link5.STL" />
      </geometry>
    </collision>
  </link>
  <joint
    name="left_arm_joint5"
    type="revolute">
    <origin
      xyz="0 -0.0487999999999995 -9.99999999999612E-05"
      rpy="-1.5707963267949 0 0" />
    <parent
      link="left_arm_link4" />
    <child
      link="left_arm_link5" />
    <axis
      xyz="0 0 1" />
    <limit
      lower="-2.14"
      upper="2.14"
      effort="5"
      velocity="12" />
  </joint>
  <link
    name="left_arm_link6">
    <inertial>
      <origin
        xyz="0.000365897578239543 -0.0257376411060454 -4.10017384469274E-05"
        rpy="0 0 0" />
      <mass
        value="0.0345706786766195" />
      <inertia
        ixx="1.56357560389195E-05"
        ixy="-1.63183630782294E-07"
        ixz="-7.87695854049935E-09"
        iyy="1.27277246486035E-05"
        iyz="2.83300566773047E-08"
        izz="9.20019800183908E-06" />
    </inertial>
    <visual>
      <origin
        xyz="0 0 0"
        rpy="0 0 0" />
      <geometry>
        <mesh
          filename="../../meshes/Bessica_D_v1_1/SkeletonOnly/meshes/left_arm_link6.STL" />
      </geometry>
      <material
        name="">
        <color
          rgba="0.807843137254902 0.843137254901961 0.905882352941176 1" />
      </material>
    </visual>
    <collision>
      <origin
        xyz="0 0 0"
        rpy="0 0 0" />
      <geometry>
        <mesh
          filename="../../meshes/Bessica_D_v1_1/SkeletonOnly/meshes/left_arm_link6.STL" />
      </geometry>
    </collision>
  </link>
  <joint
    name="left_arm_joint6"
    type="revolute">
    <origin
      xyz="0.00288999999999712 0.00207606801469368 -0.10801"
      rpy="1.5707963267949 0 0" />
    <parent
      link="left_arm_link5" />
    <child
      link="left_arm_link6" />
    <axis
      xyz="0 0 -1" />
    <limit
      lower="-2.14"
      upper="2.14"
      effort="5"
      velocity="12" />
  </joint>
  <link
    name="left_arm_link7">
    <inertial>
      <origin
        xyz="0.0417512298009294 0.00390924649669644 -0.0266716203172186"
        rpy="0 0 0" />
      <mass
        value="0.130827779580124" />
      <inertia
        ixx="9.36649808607767E-05"
        ixy="-1.47345193706856E-08"
        ixz="-3.64715377710155E-06"
        iyy="4.23029425414413E-05"
        iyz="-1.66579516794379E-08"
        izz="8.42341624354086E-05" />
    </inertial>
    <visual>
      <origin
        xyz="0 0 0"
        rpy="0 0 0" />
      <geometry>
        <mesh
          filename="../../meshes/Bessica_D_v1_1/SkeletonOnly/meshes/left_arm_link7.STL" />
      </geometry>
      <material
        name="">
        <color
          rgba="0.807843137254902 0.843137254901961 0.905882352941176 1" />
      </material>
    </visual>
    <collision>
      <origin
        xyz="0 0 0"
        rpy="0 0 0" />
      <geometry>
        <mesh
          filename="../../meshes/Bessica_D_v1_1/SkeletonOnly/meshes/left_arm_link7.STL" />
      </geometry>
    </collision>
  </link>
  <joint
    name="left_arm_joint7"
    type="revolute">
    <origin
      xyz="-0.00150000000000011 -0.0556100008049838 0.00375194992308486"
      rpy="-1.5707963267949 0 -1.5707963267949" />
    <parent
      link="left_arm_link6" />
    <child
      link="left_arm_link7" />
    <axis
      xyz="0 0 -1" />
    <limit
      lower="-2.14"
      upper="2.14"
      effort="5"
      velocity="12" />
  </joint>
  <link
    name="left_arm_gripper_right_finger">
    <inertial>
      <origin
        xyz="-0.0434086638076308 1.5504332706584E-08 0.111659634026574"
        rpy="0 0 0" />
      <mass
        value="0.0256462691014171" />
      <inertia
        ixx="5.13427082909085E-06"
        ixy="-2.45028551173559E-11"
        ixz="1.26430154389003E-06"
        iyy="6.46826207608323E-06"
        iyz="-4.16228003064832E-13"
        izz="8.03606724733866E-06" />
    </inertial>
    <visual>
      <origin
        xyz="0 0 0"
        rpy="0 0 0" />
      <geometry>
        <mesh
          filename="../../meshes/Bessica_D_v1_1/SkeletonOnly/meshes/left_arm_gripper_right_finger.STL" />
      </geometry>
      <material
        name="">
        <color
          rgba="0.592156862745098 0.666666666666667 0.682352941176471 1" />
      </material>
    </visual>
    <collision>
      <origin
        xyz="0 0 0"
        rpy="0 0 0" />
      <geometry>
        <mesh
          filename="../../meshes/Bessica_D_v1_1/SkeletonOnly/meshes/left_arm_gripper_right_finger.STL" />
      </geometry>
    </collision>
  </link>
  <joint
    name="left_arm_gripper_joint1"
    type="prismatic">
    <origin
      xyz="0.14128 -0.046748 -0.00015"
      rpy="-1.5708 0 0" />
    <parent
      link="left_arm_link7" />
    <child
      link="left_arm_gripper_right_finger" />
    <axis
      xyz="0 0 1" />
    <limit
      lower="-0.05"
      upper="0"
      effort="5"
      velocity="12" />
  </joint>
  <link
    name="left_arm_gripper_left_finger">
    <inertial>
      <origin
        xyz="-0.0434086638077171 1.55043462790605E-08 0.11165963402657"
        rpy="0 0 0" />
      <mass
        value="0.0256462691012979" />
      <inertia
        ixx="5.13427082907486E-06"
        ixy="-2.4502861966258E-11"
        ixz="1.26430154389031E-06"
        iyy="6.46826207604508E-06"
        iyz="-4.16226512838934E-13"
        izz="8.03606724728578E-06" />
    </inertial>
    <visual>
      <origin
        xyz="0 0 0"
        rpy="0 0 0" />
      <geometry>
        <mesh
          filename="../../meshes/Bessica_D_v1_1/SkeletonOnly/meshes/left_arm_gripper_left_finger.STL" />
      </geometry>
      <material
        name="">
        <color
          rgba="0.592156862745098 0.666666666666667 0.682352941176471 1" />
      </material>
    </visual>
    <collision>
      <origin
        xyz="0 0 0"
        rpy="0 0 0" />
      <geometry>
        <mesh
          filename="../../meshes/Bessica_D_v1_1/SkeletonOnly/meshes/left_arm_gripper_left_finger.STL" />
      </geometry>
    </collision>
  </link>
  <joint
    name="left_arm_gripper_joint2"
    type="prismatic">
    <origin
      xyz="0.14128 0.054252 -0.00015"
      rpy="1.5708 0 0" />
    <parent
      link="left_arm_link7" />
    <child
      link="left_arm_gripper_left_finger" />
    <axis
      xyz="0 0 -1" />
    <limit
      lower="0"
      upper="0.05"
      effort="5"
      velocity="12" />
  </joint>
  <link
    name="left_gripper_center">
     <!-- <inertial>
      <origin
        xyz="-0.567708783489944 -0.00255239950365633 -0.249378733393753"
        rpy="0 0 0" /> -->
    <visual>
      <origin
        xyz="0 0 0"
        rpy="0 0 0" />
      <geometry>
        <sphere radius="0.005" />
      </geometry>
      <material
        name="green_virtual_sphere_material">
        <color
          rgba="0 1 0 1" />
      </material>
    </visual>
  </link>

  <joint
    name="left_arm_gripper_joint"
    type="fixed">
    <origin
      xyz="0.14128 0.0037519 -0.00015"
      rpy="3.1416 0 0" />
    <parent
      link="left_arm_link7" />
    <child
      link="left_gripper_center" />
    <axis
      xyz="0 0 0" />
  </joint>
</robot>